Workbook
Name PlanYear: Dashboard!$A$5
Name Depts: Departments!$A$6:INDEX(Departments!$A$6:$A$20,MAX(1,COUNTA(Departments!$A$6:$A$20)))
Name BDOCall: 'Duty Crew'!$A$6:$A$55
Name BDODept: 'Duty Crew'!$C$6:$C$55
Name SDOCall: 'Duty Crew'!$E$6:$E$55
Name SDODept: 'Duty Crew'!$G$6:$G$55

Sheet Dashboard
A1: DUTY ROSTER | BDO AND SDO
A2: Kept by the Duty Planner. Base Duty Officer (BDO) and Squadron Duty Orderly (SDO): a person from each duty's crew list on every day. | Z2: LODESTAR roster layout 2
A4: YEAR | G4: FILE
A5: 2026 | G5: Duty Roster
A8: HOW DUTY PLANNING WORKS
A9: 1. Duty crew: on the Duty Crew sheet, list who can do each duty (callsign, name, department). BDO and SDO have separate lists.
A10: 2. Duty Planner: open this file in the planner dashboard (Open my Excel), then Add other departments to see every department's plans read-only.
A11: 3. On the dashboard's Duty Planner tab, pick the department for BDO and for SDO on each day. Save to Excel writes only to this file.
A12: 4. Each department: open your own planner in the dashboard with this Duty Roster alongside. The Duty Planner tab shows what differs; click 'Copy my duty days from the Duty Roster', then Save to Excel.
A13: 5. Then put someone from the crew list on BDO / SDO for each of your duty days on the month tabs. The DUTY DAYS row turns red on a day with nobody on that duty.
A15: You can also plan straight in Excel on the BDO Plan and SDO Plan sheets: pick a department from the dropdown in each day. The table on the right lists each department's dates.
A16: Departments are listed on the Departments sheet. Use the same spelling as the Department name in each department's planner (its Dashboard, cell G5).

Sheet BDO Plan
A1: BDO PLANNING CALENDAR | BASE DUTY OFFICER
A2: Pick the department on BDO duty for each day. The table on the right lists each department's dates. Who can do BDO: the Duty Crew sheet.
A4: HIGHLIGHT DEPT | E4: Pick a department to highlight its days. | Z4: BDO DATES BY DEPARTMENT (filled in automatically)
Z5: Month | AA5: =IF(Departments!$A$6="","",Departments!$A$6) | AB5: =IF(Departments!$A$7="","",Departments!$A$7) | AC5: =IF(Departments!$A$8="","",Departments!$A$8) | AD5: =IF(Departments!$A$9="","",Departments!$A$9) | AE5: =IF(Departments!$A$10="","",Departments!$A$10) | AF5: =IF(Departments!$A$11="","",Departments!$A$11) | AG5: =IF(Departments!$A$12="","",Departments!$A$12) | AH5: =IF(Departments!$A$13="","",Departments!$A$13) | AI5: =IF(Departments!$A$14="","",Departments!$A$14) | AJ5: =IF(Departments!$A$15="","",Departments!$A$15) | AK5: Days not set
A6: =UPPER(TEXT(DATE(PlanYear,1,1),"mmmm yyyy"))&" · BDO" | I6: =UPPER(TEXT(DATE(PlanYear,2,1),"mmmm yyyy"))&" · BDO" | Q6: =UPPER(TEXT(DATE(PlanYear,3,1),"mmmm yyyy"))&" · BDO" | Z6: January | AA6: =IF(AA$5="","",MID(IF(INDEX($A$9:$G$19,2*INT((0+WEEKDAY(DATE(PlanYear,1,1),2)-1)/7)+1,MOD(0+WEEKDAY(DATE(PlanYear,1,1),2)-1,7)+1)=AA$5,", "&1,"")&IF(INDEX($A$9:$G$19,2*INT((1+WEEKDAY(DATE(PlanYear,1,1),2)-1)/7)+1,MOD(1+WEEKDAY(DATE(PlanYear,1,1),2)-1,7)+1)=AA$5,", "&2,"")&IF(INDEX($A$9:$G$19,2*INT((2+WEEKDAY(DATE(PlanYear,1,1),2)-1)/7)+1,MOD(2+WEEKDAY(DATE(PlanYear,1,1),2)-1,7)+1)=AA$5,", "&3,"")&IF(INDEX($A$9:$G$19,2*INT((3+WEEKDAY(DATE(PlanYear,1,1),2)-1)/7)+1,MOD(3+WEEKDAY(DATE(PlanYear,1,1),2)-1,7)+1)=AA$5,", "&4,"")&IF(INDEX($A$9:$G$19,2*INT((4+WEEKDAY(DATE(PlanYear,1,1),2)-1)/7)+1,MOD(4+WEEKDAY(DATE(PlanYear,1,1),2)-1,7)+1)=AA$5,", "&5,"")&IF(INDEX($A$9:$G$19,2*INT((5+WEEKDAY(DATE(PlanYear,1,1),2)-1)/7)+1,MOD(5+WEEKDAY(DATE(PlanYear,1,1),2)-1,7)+1)=AA$5,", "&6,"")&IF(INDEX($A$9:$G$19,2*INT((6+WEEKDAY(DATE(PlanYear,1,1),2)-1)/7)+1,MOD(6+WEEKDAY(DATE(PlanYear,1,1),2)-1,7)+1)=AA$5,", "&7,"")&IF(INDEX($A$9:$G$19,2*INT((7+WEEKDAY(DATE(PlanYear,1,1),2)-1)/7)+1,MOD(7+WEEKDAY(DATE(PlanYear,1,1),2)-1,7)+1)=AA$5,", "&8,"")&IF(INDEX($A$9:$G$19,2*INT((8+WEEKDAY(DATE(PlanYear,1,1),2)-1)/7)+1,MOD(8+WEEKDAY(DATE(PlanYear,1,1),2)-1,7)+1)=AA$5,", "&9,"")&IF(INDEX($A$9:$G$19,2*INT((9+WEEKDAY(DATE(PlanYear,1,1),2)-1)/7)+1,MOD(9+WEEKDAY(DATE(PlanYear,1,1),2)-1,7)+1)=AA$5,", "&10,"")&IF(INDEX($A$9:$G$19,2*INT((10+WEEKDAY(DATE(PlanYear,1,1),2)-1)/7)+1,MOD(10+WEEKDAY(DATE(PlanYear,1,1),2)-1,7)+1)=AA$5,", "&11,"")&IF(INDEX($A$9:$G$19,2*INT((11+WEEKDAY(DATE(PlanYear,1,1),2)-1)/7)+1,MOD(11+WEEKDAY(DATE(PlanYear,1,1),2)-1,7)+1)=AA$5,", "&12,"")&IF(INDEX($A$9:$G$19,2*INT((12+WEEKDAY(DATE(PlanYear,1,1),2)-1)/7)+1,MOD(12+WEEKDAY(DATE(PlanYear,1,1),2)-1,7)+1)=AA$5,", "&13,"")&IF(INDEX($A$9:$G$19,2*INT((13+WEEKDAY(DATE(PlanYear,1,1),2)-1)/7)+1,MOD(13+WEEKDAY(DATE(PlanYear,1,1),2)-1,7)+1)=AA$5,", "&14,"")&IF(INDEX($A$9:$G$19,2*INT((14+WEEKDAY(DATE(PlanYear,1,1),2)-1)/7)+1,MOD(14+WEEKDAY(DATE(PlanYear,1,1),2)-1,7)+1)=AA$5,", "&15,"")&IF(INDEX($A$9:$G$19,2*INT((15+WEEKDAY(DATE(PlanYear,1,1),2)-1)/7)+1,MOD(15+WEEKDAY(DATE(PlanYear,1,1),2)-1,7)+1)=AA$5,", "&16,"")&IF(INDEX($A$9:$G$19,2*INT((16+WEEKDAY(DATE(PlanYear,1,1),2)-1)/7)+1,MOD(16+WEEKDAY(DATE(PlanYear,1,1),2)-1,7)+1)=AA$5,", "&17,"")&IF(INDEX($A$9:$G$19,2*INT((17+WEEKDAY(DATE(PlanYear,1,1),2)-1)/7)+1,MOD(17+WEEKDAY(DATE(PlanYear,1,1),2)-1,7)+1)=AA$5,", "&18,"")&IF(INDEX($A$9:$G$19,2*INT((18+WEEKDAY(DATE(PlanYear,1,1),2)-1)/7)+1,MOD(18+WEEKDAY(DATE(PlanYear,1,1),2)-1,7)+1)=AA$5,", "&19,"")&IF(INDEX($A$9:$G$19,2*INT((19+WEEKDAY(DATE(PlanYear,1,1),2)-1)/7)+1,MOD(19+WEEKDAY(DATE(PlanYear,1,1),2)-1,7)+1)=AA$5,", "&20,"")&IF(INDEX($A$9:$G$19,2*INT((20+WEEKDAY(DATE(PlanYear,1,1),2)-1)/7)+1,MOD(20+WEEKDAY(DATE(PlanYear,1,1),2)-1,7)+1)=AA$5,", "&21,"")&IF(INDEX($A$9:$G$19,2*INT((21+WEEKDAY(DATE(PlanYear,1,1),2)-1)/7)+1,MOD(21+WEEKDAY(DATE(PlanYear,1,1),2)-1,7)+1)=AA$5,", "&22,"")&IF(INDEX($A$9:$G$19,2*INT((22+WEEKDAY(DATE(PlanYear,1,1),2)-1)/7)+1,MOD(22+WEEKDAY(DATE(PlanYear,1,1),2)-1,7)+1)=AA$5,", "&23,"")&IF(INDEX($A$9:$G$19,2*INT((23+WEEKDAY(DATE(PlanYear,1,1),2)-1)/7)+1,MOD(23+WEEKDAY(DATE(PlanYear,1,1),2)-1,7)+1)=AA$5,", "&24,"")&IF(INDEX($A$9:$G$19,2*INT((24+WEEKDAY(DATE(PlanYear,1,1),2)-1)/7)+1,MOD(24+WEEKDAY(DATE(PlanYear,1,1),2)-1,7)+1)=AA$5,", "&25,"")&IF(INDEX($A$9:$G$19,2*INT((25+WEEKDAY(DATE(PlanYear,1,1),2)-1)/7)+1,MOD(25+WEEKDAY(DATE(PlanYear,1,1),2)-1,7)+1)=AA$5,", "&26,"")&IF(INDEX($A$9:$G$19,2*INT((26+WEEKDAY(DATE(PlanYear,1,1),2)-1)/7)+1,MOD(26+WEEKDAY(DATE(PlanYear,1,1),2)-1,7)+1)=AA$5,", "&27,"")&IF(INDEX($A$9:$G$19,2*INT((27+WEEKDAY(DATE(PlanYear,1,1),2)-1)/7)+1,MOD(27+WEEKDAY(DATE(PlanYear,1,1),2)-1,7)+1)=AA$5,", "&28,"")&IF(INDEX($A$9:$G$19,2*INT((28+WEEKDAY(DATE(PlanYear,1,1),2)-1)/7)+1,MOD(28+WEEKDAY(DATE(PlanYear,1,1),2)-1,7)+1)=AA$5,", "&29,"")&IF(INDEX($A$9:$G$19,2*INT((29+WEEKDAY(DATE(PlanYear,1,1),2)-1)/7)+1,MOD(29+WEEKDAY(DATE(PlanYear,1,1),2)-1,7)+1)=AA$5,", "&30,"")&IF(INDEX($A$9:$G$19,2*INT((30+WEEKDAY(DATE(PlanYear,1,1),2)-1)/7)+1,MOD(30+WEEKDAY(DATE(PlanYear,1,1),2)-1,7)+1)=AA$5,", "&31,""),3,200)) | AB6: =IF(AB$5="","",MID(IF(INDEX($A$9:$G$19,2*INT((0+WEEKDAY(DATE(PlanYear,1,1),2)-1)/7)+1,MOD(0+WEEKDAY(DATE(PlanYear,1,1),2)-1,7)+1)=AB$5,", "&1,"")&IF(INDEX($A$9:$G$19,2*INT((1+WEEKDAY(DATE(PlanYear,1,1),2)-1)/7)+1,MOD(1+WEEKDAY(DATE(PlanYear,1,1),2)-1,7)+1)=AB$5,", "&2,"")&IF(INDEX($A$9:$G$19,2*INT((2+WEEKDAY(DATE(PlanYear,1,1),2)-1)/7)+1,MOD(2+WEEKDAY(DATE(PlanYear,1,1),2)-1,7)+1)=AB$5,", "&3,"")&IF(INDEX($A$9:$G$19,2*INT((3+WEEKDAY(DATE(PlanYear,1,1),2)-1)/7)+1,MOD(3+WEEKDAY(DATE(PlanYear,1,1),2)-1,7)+1)=AB$5,", "&4,"")&IF(INDEX($A$9:$G$19,2*INT((4+WEEKDAY(DATE(PlanYear,1,1),2)-1)/7)+1,MOD(4+WEEKDAY(DATE(PlanYear,1,1),2)-1,7)+1)=AB$5,", "&5,"")&IF(INDEX($A$9:$G$19,2*INT((5+WEEKDAY(DATE(PlanYear,1,1),2)-1)/7)+1,MOD(5+WEEKDAY(DATE(PlanYear,1,1),2)-1,7)+1)=AB$5,", "&6,"")&IF(INDEX($A$9:$G$19,2*INT((6+WEEKDAY(DATE(PlanYear,1,1),2)-1)/7)+1,MOD(6+WEEKDAY(DATE(PlanYear,1,1),2)-1,7)+1)=AB$5,", "&7,"")&IF(INDEX($A$9:$G$19,2*INT((7+WEEKDAY(DATE(PlanYear,1,1),2)-1)/7)+1,MOD(7+WEEKDAY(DATE(PlanYear,1,1),2)-1,7)+1)=AB$5,", "&8,"")&IF(INDEX($A$9:$G$19,2*INT((8+WEEKDAY(DATE(PlanYear,1,1),2)-1)/7)+1,MOD(8+WEEKDAY(DATE(PlanYear,1,1),2)-1,7)+1)=AB$5,", "&9,"")&IF(INDEX($A$9:$G$19,2*INT((9+WEEKDAY(DATE(PlanYear,1,1),2)-1)/7)+1,MOD(9+WEEKDAY(DATE(PlanYear,1,1),2)-1,7)+1)=AB$5,", "&10,"")&IF(INDEX($A$9:$G$19,2*INT((10+WEEKDAY(DATE(PlanYear,1,1),2)-1)/7)+1,MOD(10+WEEKDAY(DATE(PlanYear,1,1),2)-1,7)+1)=AB$5,", "&11,"")&IF(INDEX($A$9:$G$19,2*INT((11+WEEKDAY(DATE(PlanYear,1,1),2)-1)/7)+1,MOD(11+WEEKDAY(DATE(PlanYear,1,1),2)-1,7)+1)=AB$5,", "&12,"")&IF(INDEX($A$9:$G$19,2*INT((12+WEEKDAY(DATE(PlanYear,1,1),2)-1)/7)+1,MOD(12+WEEKDAY(DATE(PlanYear,1,1),2)-1,7)+1)=AB$5,", "&13,"")&IF(INDEX($A$9:$G$19,2*INT((13+WEEKDAY(DATE(PlanYear,1,1),2)-1)/7)+1,MOD(13+WEEKDAY(DATE(PlanYear,1,1),2)-1,7)+1)=AB$5,", "&14,"")&IF(INDEX($A$9:$G$19,2*INT((14+WEEKDAY(DATE(PlanYear,1,1),2)-1)/7)+1,MOD(14+WEEKDAY(DATE(PlanYear,1,1),2)-1,7)+1)=AB$5,", "&15,"")&IF(INDEX($A$9:$G$19,2*INT((15+WEEKDAY(DATE(PlanYear,1,1),2)-1)/7)+1,MOD(15+WEEKDAY(DATE(PlanYear,1,1),2)-1,7)+1)=AB$5,", "&16,"")&IF(INDEX($A$9:$G$19,2*INT((16+WEEKDAY(DATE(PlanYear,1,1),2)-1)/7)+1,MOD(16+WEEKDAY(DATE(PlanYear,1,1),2)-1,7)+1)=AB$5,", "&17,"")&IF(INDEX($A$9:$G$19,2*INT((17+WEEKDAY(DATE(PlanYear,1,1),2)-1)/7)+1,MOD(17+WEEKDAY(DATE(PlanYear,1,1),2)-1,7)+1)=AB$5,", "&18,"")&IF(INDEX($A$9:$G$19,2*INT((18+WEEKDAY(DATE(PlanYear,1,1),2)-1)/7)+1,MOD(18+WEEKDAY(DATE(PlanYear,1,1),2)-1,7)+1)=AB$5,", "&19,"")&IF(INDEX($A$9:$G$19,2*INT((19+WEEKDAY(DATE(PlanYear,1,1),2)-1)/7)+1,MOD(19+WEEKDAY(DATE(PlanYear,1,1),2)-1,7)+1)=AB$5,", "&20,"")&IF(INDEX($A$9:$G$19,2*INT((20+WEEKDAY(DATE(PlanYear,1,1),2)-1)/7)+1,MOD(20+WEEKDAY(DATE(PlanYear,1,1),2)-1,7)+1)=AB$5,", "&21,"")&IF(INDEX($A$9:$G$19,2*INT((21+WEEKDAY(DATE(PlanYear,1,1),2)-1)/7)+1,MOD(21+WEEKDAY(DATE(PlanYear,1,1),2)-1,7)+1)=AB$5,", "&22,"")&IF(INDEX($A$9:$G$19,2*INT((22+WEEKDAY(DATE(PlanYear,1,1),2)-1)/7)+1,MOD(22+WEEKDAY(DATE(PlanYear,1,1),2)-1,7)+1)=AB$5,", "&23,"")&IF(INDEX($A$9:$G$19,2*INT((23+WEEKDAY(DATE(PlanYear,1,1),2)-1)/7)+1,MOD(23+WEEKDAY(DATE(PlanYear,1,1),2)-1,7)+1)=AB$5,", "&24,"")&IF(INDEX($A$9:$G$19,2*INT((24+WEEKDAY(DATE(PlanYear,1,1),2)-1)/7)+1,MOD(24+WEEKDAY(DATE(PlanYear,1,1),2)-1,7)+1)=AB$5,", "&25,"")&IF(INDEX($A$9:$G$19,2*INT((25+WEEKDAY(DATE(PlanYear,1,1),2)-1)/7)+1,MOD(25+WEEKDAY(DATE(PlanYear,1,1),2)-1,7)+1)=AB$5,", "&26,"")&IF(INDEX($A$9:$G$19,2*INT((26+WEEKDAY(DATE(PlanYear,1,1),2)-1)/7)+1,MOD(26+WEEKDAY(DATE(PlanYear,1,1),2)-1,7)+1)=AB$5,", "&27,"")&IF(INDEX($A$9:$G$19,2*INT((27+WEEKDAY(DATE(PlanYear,1,1),2)-1)/7)+1,MOD(27+WEEKDAY(DATE(PlanYear,1,1),2)-1,7)+1)=AB$5,", "&28,"")&IF(INDEX($A$9:$G$19,2*INT((28+WEEKDAY(DATE(PlanYear,1,1),2)-1)/7)+1,MOD(28+WEEKDAY(DATE(PlanYear,1,1),2)-1,7)+1)=AB$5,", "&29,"")&IF(INDEX($A$9:$G$19,2*INT((29+WEEKDAY(DATE(PlanYear,1,1),2)-1)/7)+1,MOD(29+WEEKDAY(DATE(PlanYear,1,1),2)-1,7)+1)=AB$5,", "&30,"")&IF(INDEX($A$9:$G$19,2*INT((30+WEEKDAY(DATE(PlanYear,1,1),2)-1)/7)+1,MOD(30+WEEKDAY(DATE(PlanYear,1,1),2)-1,7)+1)=AB$5,", "&31,""),3,200)) | AC6: =IF(AC$5="","",MID(IF(INDEX($A$9:$G$19,2*INT((0+WEEKDAY(DATE(PlanYear,1,1),2)-1)/7)+1,MOD(0+WEEKDAY(DATE(PlanYear,1,1),2)-1,7)+1)=AC$5,", "&1,"")&IF(INDEX($A$9:$G$19,2*INT((1+WEEKDAY(DATE(PlanYear,1,1),2)-1)/7)+1,MOD(1+WEEKDAY(DATE(PlanYear,1,1),2)-1,7)+1)=AC$5,", "&2,"")&IF(INDEX($A$9:$G$19,2*INT((2+WEEKDAY(DATE(PlanYear,1,1),2)-1)/7)+1,MOD(2+WEEKDAY(DATE(PlanYear,1,1),2)-1,7)+1)=AC$5,", "&3,"")&IF(INDEX($A$9:$G$19,2*INT((3+WEEKDAY(DATE(PlanYear,1,1),2)-1)/7)+1,MOD(3+WEEKDAY(DATE(PlanYear,1,1),2)-1,7)+1)=AC$5,", "&4,"")&IF(INDEX($A$9:$G$19,2*INT((4+WEEKDAY(DATE(PlanYear,1,1),2)-1)/7)+1,MOD(4+WEEKDAY(DATE(PlanYear,1,1),2)-1,7)+1)=AC$5,", "&5,"")&IF(INDEX($A$9:$G$19,2*INT((5+WEEKDAY(DATE(PlanYear,1,1),2)-1)/7)+1,MOD(5+WEEKDAY(DATE(PlanYear,1,1),2)-1,7)+1)=AC$5,", "&6,"")&IF(INDEX($A$9:$G$19,2*INT((6+WEEKDAY(DATE(PlanYear,1,1),2)-1)/7)+1,MOD(6+WEEKDAY(DATE(PlanYear,1,1),2)-1,7)+1)=AC$5,", "&7,"")&IF(INDEX($A$9:$G$19,2*INT((7+WEEKDAY(DATE(PlanYear,1,1),2)-1)/7)+1,MOD(7+WEEKDAY(DATE(PlanYear,1,1),2)-1,7)+1)=AC$5,", "&8,"")&IF(INDEX($A$9:$G$19,2*INT((8+WEEKDAY(DATE(PlanYear,1,1),2)-1)/7)+1,MOD(8+WEEKDAY(DATE(PlanYear,1,1),2)-1,7)+1)=AC$5,", "&9,"")&IF(INDEX($A$9:$G$19,2*INT((9+WEEKDAY(DATE(PlanYear,1,1),2)-1)/7)+1,MOD(9+WEEKDAY(DATE(PlanYear,1,1),2)-1,7)+1)=AC$5,", "&10,"")&IF(INDEX($A$9:$G$19,2*INT((10+WEEKDAY(DATE(PlanYear,1,1),2)-1)/7)+1,MOD(10+WEEKDAY(DATE(PlanYear,1,1),2)-1,7)+1)=AC$5,", "&11,"")&IF(INDEX($A$9:$G$19,2*INT((11+WEEKDAY(DATE(PlanYear,1,1),2)-1)/7)+1,MOD(11+WEEKDAY(DATE(PlanYear,1,1),2)-1,7)+1)=AC$5,", "&12,"")&IF(INDEX($A$9:$G$19,2*INT((12+WEEKDAY(DATE(PlanYear,1,1),2)-1)/7)+1,MOD(12+WEEKDAY(DATE(PlanYear,1,1),2)-1,7)+1)=AC$5,", "&13,"")&IF(INDEX($A$9:$G$19,2*INT((13+WEEKDAY(DATE(PlanYear,1,1),2)-1)/7)+1,MOD(13+WEEKDAY(DATE(PlanYear,1,1),2)-1,7)+1)=AC$5,", "&14,"")&IF(INDEX($A$9:$G$19,2*INT((14+WEEKDAY(DATE(PlanYear,1,1),2)-1)/7)+1,MOD(14+WEEKDAY(DATE(PlanYear,1,1),2)-1,7)+1)=AC$5,", "&15,"")&IF(INDEX($A$9:$G$19,2*INT((15+WEEKDAY(DATE(PlanYear,1,1),2)-1)/7)+1,MOD(15+WEEKDAY(DATE(PlanYear,1,1),2)-1,7)+1)=AC$5,", "&16,"")&IF(INDEX($A$9:$G$19,2*INT((16+WEEKDAY(DATE(PlanYear,1,1),2)-1)/7)+1,MOD(16+WEEKDAY(DATE(PlanYear,1,1),2)-1,7)+1)=AC$5,", "&17,"")&IF(INDEX($A$9:$G$19,2*INT((17+WEEKDAY(DATE(PlanYear,1,1),2)-1)/7)+1,MOD(17+WEEKDAY(DATE(PlanYear,1,1),2)-1,7)+1)=AC$5,", "&18,"")&IF(INDEX($A$9:$G$19,2*INT((18+WEEKDAY(DATE(PlanYear,1,1),2)-1)/7)+1,MOD(18+WEEKDAY(DATE(PlanYear,1,1),2)-1,7)+1)=AC$5,", "&19,"")&IF(INDEX($A$9:$G$19,2*INT((19+WEEKDAY(DATE(PlanYear,1,1),2)-1)/7)+1,MOD(19+WEEKDAY(DATE(PlanYear,1,1),2)-1,7)+1)=AC$5,", "&20,"")&IF(INDEX($A$9:$G$19,2*INT((20+WEEKDAY(DATE(PlanYear,1,1),2)-1)/7)+1,MOD(20+WEEKDAY(DATE(PlanYear,1,1),2)-1,7)+1)=AC$5,", "&21,"")&IF(INDEX($A$9:$G$19,2*INT((21+WEEKDAY(DATE(PlanYear,1,1),2)-1)/7)+1,MOD(21+WEEKDAY(DATE(PlanYear,1,1),2)-1,7)+1)=AC$5,", "&22,"")&IF(INDEX($A$9:$G$19,2*INT((22+WEEKDAY(DATE(PlanYear,1,1),2)-1)/7)+1,MOD(22+WEEKDAY(DATE(PlanYear,1,1),2)-1,7)+1)=AC$5,", "&23,"")&IF(INDEX($A$9:$G$19,2*INT((23+WEEKDAY(DATE(PlanYear,1,1),2)-1)/7)+1,MOD(23+WEEKDAY(DATE(PlanYear,1,1),2)-1,7)+1)=AC$5,", "&24,"")&IF(INDEX($A$9:$G$19,2*INT((24+WEEKDAY(DATE(PlanYear,1,1),2)-1)/7)+1,MOD(24+WEEKDAY(DATE(PlanYear,1,1),2)-1,7)+1)=AC$5,", "&25,"")&IF(INDEX($A$9:$G$19,2*INT((25+WEEKDAY(DATE(PlanYear,1,1),2)-1)/7)+1,MOD(25+WEEKDAY(DATE(PlanYear,1,1),2)-1,7)+1)=AC$5,", "&26,"")&IF(INDEX($A$9:$G$19,2*INT((26+WEEKDAY(DATE(PlanYear,1,1),2)-1)/7)+1,MOD(26+WEEKDAY(DATE(PlanYear,1,1),2)-1,7)+1)=AC$5,", "&27,"")&IF(INDEX($A$9:$G$19,2*INT((27+WEEKDAY(DATE(PlanYear,1,1),2)-1)/7)+1,MOD(27+WEEKDAY(DATE(PlanYear,1,1),2)-1,7)+1)=AC$5,", "&28,"")&IF(INDEX($A$9:$G$19,2*INT((28+WEEKDAY(DATE(PlanYear,1,1),2)-1)/7)+1,MOD(28+WEEKDAY(DATE(PlanYear,1,1),2)-1,7)+1)=AC$5,", "&29,"")&IF(INDEX($A$9:$G$19,2*INT((29+WEEKDAY(DATE(PlanYear,1,1),2)-1)/7)+1,MOD(29+WEEKDAY(DATE(PlanYear,1,1),2)-1,7)+1)=AC$5,", "&30,"")&IF(INDEX($A$9:$G$19,2*INT((30+WEEKDAY(DATE(PlanYear,1,1),2)-1)/7)+1,MOD(30+WEEKDAY(DATE(PlanYear,1,1),2)-1,7)+1)=AC$5,", "&31,""),3,200)) | AD6: =IF(AD$5="","",MID(IF(INDEX($A$9:$G$19,2*INT((0+WEEKDAY(DATE(PlanYear,1,1),2)-1)/7)+1,MOD(0+WEEKDAY(DATE(PlanYear,1,1),2)-1,7)+1)=AD$5,", "&1,"")&IF(INDEX($A$9:$G$19,2*INT((1+WEEKDAY(DATE(PlanYear,1,1),2)-1)/7)+1,MOD(1+WEEKDAY(DATE(PlanYear,1,1),2)-1,7)+1)=AD$5,", "&2,"")&IF(INDEX($A$9:$G$19,2*INT((2+WEEKDAY(DATE(PlanYear,1,1),2)-1)/7)+1,MOD(2+WEEKDAY(DATE(PlanYear,1,1),2)-1,7)+1)=AD$5,", "&3,"")&IF(INDEX($A$9:$G$19,2*INT((3+WEEKDAY(DATE(PlanYear,1,1),2)-1)/7)+1,MOD(3+WEEKDAY(DATE(PlanYear,1,1),2)-1,7)+1)=AD$5,", "&4,"")&IF(INDEX($A$9:$G$19,2*INT((4+WEEKDAY(DATE(PlanYear,1,1),2)-1)/7)+1,MOD(4+WEEKDAY(DATE(PlanYear,1,1),2)-1,7)+1)=AD$5,", "&5,"")&IF(INDEX($A$9:$G$19,2*INT((5+WEEKDAY(DATE(PlanYear,1,1),2)-1)/7)+1,MOD(5+WEEKDAY(DATE(PlanYear,1,1),2)-1,7)+1)=AD$5,", "&6,"")&IF(INDEX($A$9:$G$19,2*INT((6+WEEKDAY(DATE(PlanYear,1,1),2)-1)/7)+1,MOD(6+WEEKDAY(DATE(PlanYear,1,1),2)-1,7)+1)=AD$5,", "&7,"")&IF(INDEX($A$9:$G$19,2*INT((7+WEEKDAY(DATE(PlanYear,1,1),2)-1)/7)+1,MOD(7+WEEKDAY(DATE(PlanYear,1,1),2)-1,7)+1)=AD$5,", "&8,"")&IF(INDEX($A$9:$G$19,2*INT((8+WEEKDAY(DATE(PlanYear,1,1),2)-1)/7)+1,MOD(8+WEEKDAY(DATE(PlanYear,1,1),2)-1,7)+1)=AD$5,", "&9,"")&IF(INDEX($A$9:$G$19,2*INT((9+WEEKDAY(DATE(PlanYear,1,1),2)-1)/7)+1,MOD(9+WEEKDAY(DATE(PlanYear,1,1),2)-1,7)+1)=AD$5,", "&10,"")&IF(INDEX($A$9:$G$19,2*INT((10+WEEKDAY(DATE(PlanYear,1,1),2)-1)/7)+1,MOD(10+WEEKDAY(DATE(PlanYear,1,1),2)-1,7)+1)=AD$5,", "&11,"")&IF(INDEX($A$9:$G$19,2*INT((11+WEEKDAY(DATE(PlanYear,1,1),2)-1)/7)+1,MOD(11+WEEKDAY(DATE(PlanYear,1,1),2)-1,7)+1)=AD$5,", "&12,"")&IF(INDEX($A$9:$G$19,2*INT((12+WEEKDAY(DATE(PlanYear,1,1),2)-1)/7)+1,MOD(12+WEEKDAY(DATE(PlanYear,1,1),2)-1,7)+1)=AD$5,", "&13,"")&IF(INDEX($A$9:$G$19,2*INT((13+WEEKDAY(DATE(PlanYear,1,1),2)-1)/7)+1,MOD(13+WEEKDAY(DATE(PlanYear,1,1),2)-1,7)+1)=AD$5,", "&14,"")&IF(INDEX($A$9:$G$19,2*INT((14+WEEKDAY(DATE(PlanYear,1,1),2)-1)/7)+1,MOD(14+WEEKDAY(DATE(PlanYear,1,1),2)-1,7)+1)=AD$5,", "&15,"")&IF(INDEX($A$9:$G$19,2*INT((15+WEEKDAY(DATE(PlanYear,1,1),2)-1)/7)+1,MOD(15+WEEKDAY(DATE(PlanYear,1,1),2)-1,7)+1)=AD$5,", "&16,"")&IF(INDEX($A$9:$G$19,2*INT((16+WEEKDAY(DATE(PlanYear,1,1),2)-1)/7)+1,MOD(16+WEEKDAY(DATE(PlanYear,1,1),2)-1,7)+1)=AD$5,", "&17,"")&IF(INDEX($A$9:$G$19,2*INT((17+WEEKDAY(DATE(PlanYear,1,1),2)-1)/7)+1,MOD(17+WEEKDAY(DATE(PlanYear,1,1),2)-1,7)+1)=AD$5,", "&18,"")&IF(INDEX($A$9:$G$19,2*INT((18+WEEKDAY(DATE(PlanYear,1,1),2)-1)/7)+1,MOD(18+WEEKDAY(DATE(PlanYear,1,1),2)-1,7)+1)=AD$5,", "&19,"")&IF(INDEX($A$9:$G$19,2*INT((19+WEEKDAY(DATE(PlanYear,1,1),2)-1)/7)+1,MOD(19+WEEKDAY(DATE(PlanYear,1,1),2)-1,7)+1)=AD$5,", "&20,"")&IF(INDEX($A$9:$G$19,2*INT((20+WEEKDAY(DATE(PlanYear,1,1),2)-1)/7)+1,MOD(20+WEEKDAY(DATE(PlanYear,1,1),2)-1,7)+1)=AD$5,", "&21,"")&IF(INDEX($A$9:$G$19,2*INT((21+WEEKDAY(DATE(PlanYear,1,1),2)-1)/7)+1,MOD(21+WEEKDAY(DATE(PlanYear,1,1),2)-1,7)+1)=AD$5,", "&22,"")&IF(INDEX($A$9:$G$19,2*INT((22+WEEKDAY(DATE(PlanYear,1,1),2)-1)/7)+1,MOD(22+WEEKDAY(DATE(PlanYear,1,1),2)-1,7)+1)=AD$5,", "&23,"")&IF(INDEX($A$9:$G$19,2*INT((23+WEEKDAY(DATE(PlanYear,1,1),2)-1)/7)+1,MOD(23+WEEKDAY(DATE(PlanYear,1,1),2)-1,7)+1)=AD$5,", "&24,"")&IF(INDEX($A$9:$G$19,2*INT((24+WEEKDAY(DATE(PlanYear,1,1),2)-1)/7)+1,MOD(24+WEEKDAY(DATE(PlanYear,1,1),2)-1,7)+1)=AD$5,", "&25,"")&IF(INDEX($A$9:$G$19,2*INT((25+WEEKDAY(DATE(PlanYear,1,1),2)-1)/7)+1,MOD(25+WEEKDAY(DATE(PlanYear,1,1),2)-1,7)+1)=AD$5,", "&26,"")&IF(INDEX($A$9:$G$19,2*INT((26+WEEKDAY(DATE(PlanYear,1,1),2)-1)/7)+1,MOD(26+WEEKDAY(DATE(PlanYear,1,1),2)-1,7)+1)=AD$5,", "&27,"")&IF(INDEX($A$9:$G$19,2*INT((27+WEEKDAY(DATE(PlanYear,1,1),2)-1)/7)+1,MOD(27+WEEKDAY(DATE(PlanYear,1,1),2)-1,7)+1)=AD$5,", "&28,"")&IF(INDEX($A$9:$G$19,2*INT((28+WEEKDAY(DATE(PlanYear,1,1),2)-1)/7)+1,MOD(28+WEEKDAY(DATE(PlanYear,1,1),2)-1,7)+1)=AD$5,", "&29,"")&IF(INDEX($A$9:$G$19,2*INT((29+WEEKDAY(DATE(PlanYear,1,1),2)-1)/7)+1,MOD(29+WEEKDAY(DATE(PlanYear,1,1),2)-1,7)+1)=AD$5,", "&30,"")&IF(INDEX($A$9:$G$19,2*INT((30+WEEKDAY(DATE(PlanYear,1,1),2)-1)/7)+1,MOD(30+WEEKDAY(DATE(PlanYear,1,1),2)-1,7)+1)=AD$5,", "&31,""),3,200)) | AE6: =IF(AE$5="","",MID(IF(INDEX($A$9:$G$19,2*INT((0+WEEKDAY(DATE(PlanYear,1,1),2)-1)/7)+1,MOD(0+WEEKDAY(DATE(PlanYear,1,1),2)-1,7)+1)=AE$5,", "&1,"")&IF(INDEX($A$9:$G$19,2*INT((1+WEEKDAY(DATE(PlanYear,1,1),2)-1)/7)+1,MOD(1+WEEKDAY(DATE(PlanYear,1,1),2)-1,7)+1)=AE$5,", "&2,"")&IF(INDEX($A$9:$G$19,2*INT((2+WEEKDAY(DATE(PlanYear,1,1),2)-1)/7)+1,MOD(2+WEEKDAY(DATE(PlanYear,1,1),2)-1,7)+1)=AE$5,", "&3,"")&IF(INDEX($A$9:$G$19,2*INT((3+WEEKDAY(DATE(PlanYear,1,1),2)-1)/7)+1,MOD(3+WEEKDAY(DATE(PlanYear,1,1),2)-1,7)+1)=AE$5,", "&4,"")&IF(INDEX($A$9:$G$19,2*INT((4+WEEKDAY(DATE(PlanYear,1,1),2)-1)/7)+1,MOD(4+WEEKDAY(DATE(PlanYear,1,1),2)-1,7)+1)=AE$5,", "&5,"")&IF(INDEX($A$9:$G$19,2*INT((5+WEEKDAY(DATE(PlanYear,1,1),2)-1)/7)+1,MOD(5+WEEKDAY(DATE(PlanYear,1,1),2)-1,7)+1)=AE$5,", "&6,"")&IF(INDEX($A$9:$G$19,2*INT((6+WEEKDAY(DATE(PlanYear,1,1),2)-1)/7)+1,MOD(6+WEEKDAY(DATE(PlanYear,1,1),2)-1,7)+1)=AE$5,", "&7,"")&IF(INDEX($A$9:$G$19,2*INT((7+WEEKDAY(DATE(PlanYear,1,1),2)-1)/7)+1,MOD(7+WEEKDAY(DATE(PlanYear,1,1),2)-1,7)+1)=AE$5,", "&8,"")&IF(INDEX($A$9:$G$19,2*INT((8+WEEKDAY(DATE(PlanYear,1,1),2)-1)/7)+1,MOD(8+WEEKDAY(DATE(PlanYear,1,1),2)-1,7)+1)=AE$5,", "&9,"")&IF(INDEX($A$9:$G$19,2*INT((9+WEEKDAY(DATE(PlanYear,1,1),2)-1)/7)+1,MOD(9+WEEKDAY(DATE(PlanYear,1,1),2)-1,7)+1)=AE$5,", "&10,"")&IF(INDEX($A$9:$G$19,2*INT((10+WEEKDAY(DATE(PlanYear,1,1),2)-1)/7)+1,MOD(10+WEEKDAY(DATE(PlanYear,1,1),2)-1,7)+1)=AE$5,", "&11,"")&IF(INDEX($A$9:$G$19,2*INT((11+WEEKDAY(DATE(PlanYear,1,1),2)-1)/7)+1,MOD(11+WEEKDAY(DATE(PlanYear,1,1),2)-1,7)+1)=AE$5,", "&12,"")&IF(INDEX($A$9:$G$19,2*INT((12+WEEKDAY(DATE(PlanYear,1,1),2)-1)/7)+1,MOD(12+WEEKDAY(DATE(PlanYear,1,1),2)-1,7)+1)=AE$5,", "&13,"")&IF(INDEX($A$9:$G$19,2*INT((13+WEEKDAY(DATE(PlanYear,1,1),2)-1)/7)+1,MOD(13+WEEKDAY(DATE(PlanYear,1,1),2)-1,7)+1)=AE$5,", "&14,"")&IF(INDEX($A$9:$G$19,2*INT((14+WEEKDAY(DATE(PlanYear,1,1),2)-1)/7)+1,MOD(14+WEEKDAY(DATE(PlanYear,1,1),2)-1,7)+1)=AE$5,", "&15,"")&IF(INDEX($A$9:$G$19,2*INT((15+WEEKDAY(DATE(PlanYear,1,1),2)-1)/7)+1,MOD(15+WEEKDAY(DATE(PlanYear,1,1),2)-1,7)+1)=AE$5,", "&16,"")&IF(INDEX($A$9:$G$19,2*INT((16+WEEKDAY(DATE(PlanYear,1,1),2)-1)/7)+1,MOD(16+WEEKDAY(DATE(PlanYear,1,1),2)-1,7)+1)=AE$5,", "&17,"")&IF(INDEX($A$9:$G$19,2*INT((17+WEEKDAY(DATE(PlanYear,1,1),2)-1)/7)+1,MOD(17+WEEKDAY(DATE(PlanYear,1,1),2)-1,7)+1)=AE$5,", "&18,"")&IF(INDEX($A$9:$G$19,2*INT((18+WEEKDAY(DATE(PlanYear,1,1),2)-1)/7)+1,MOD(18+WEEKDAY(DATE(PlanYear,1,1),2)-1,7)+1)=AE$5,", "&19,"")&IF(INDEX($A$9:$G$19,2*INT((19+WEEKDAY(DATE(PlanYear,1,1),2)-1)/7)+1,MOD(19+WEEKDAY(DATE(PlanYear,1,1),2)-1,7)+1)=AE$5,", "&20,"")&IF(INDEX($A$9:$G$19,2*INT((20+WEEKDAY(DATE(PlanYear,1,1),2)-1)/7)+1,MOD(20+WEEKDAY(DATE(PlanYear,1,1),2)-1,7)+1)=AE$5,", "&21,"")&IF(INDEX($A$9:$G$19,2*INT((21+WEEKDAY(DATE(PlanYear,1,1),2)-1)/7)+1,MOD(21+WEEKDAY(DATE(PlanYear,1,1),2)-1,7)+1)=AE$5,", "&22,"")&IF(INDEX($A$9:$G$19,2*INT((22+WEEKDAY(DATE(PlanYear,1,1),2)-1)/7)+1,MOD(22+WEEKDAY(DATE(PlanYear,1,1),2)-1,7)+1)=AE$5,", "&23,"")&IF(INDEX($A$9:$G$19,2*INT((23+WEEKDAY(DATE(PlanYear,1,1),2)-1)/7)+1,MOD(23+WEEKDAY(DATE(PlanYear,1,1),2)-1,7)+1)=AE$5,", "&24,"")&IF(INDEX($A$9:$G$19,2*INT((24+WEEKDAY(DATE(PlanYear,1,1),2)-1)/7)+1,MOD(24+WEEKDAY(DATE(PlanYear,1,1),2)-1,7)+1)=AE$5,", "&25,"")&IF(INDEX($A$9:$G$19,2*INT((25+WEEKDAY(DATE(PlanYear,1,1),2)-1)/7)+1,MOD(25+WEEKDAY(DATE(PlanYear,1,1),2)-1,7)+1)=AE$5,", "&26,"")&IF(INDEX($A$9:$G$19,2*INT((26+WEEKDAY(DATE(PlanYear,1,1),2)-1)/7)+1,MOD(26+WEEKDAY(DATE(PlanYear,1,1),2)-1,7)+1)=AE$5,", "&27,"")&IF(INDEX($A$9:$G$19,2*INT((27+WEEKDAY(DATE(PlanYear,1,1),2)-1)/7)+1,MOD(27+WEEKDAY(DATE(PlanYear,1,1),2)-1,7)+1)=AE$5,", "&28,"")&IF(INDEX($A$9:$G$19,2*INT((28+WEEKDAY(DATE(PlanYear,1,1),2)-1)/7)+1,MOD(28+WEEKDAY(DATE(PlanYear,1,1),2)-1,7)+1)=AE$5,", "&29,"")&IF(INDEX($A$9:$G$19,2*INT((29+WEEKDAY(DATE(PlanYear,1,1),2)-1)/7)+1,MOD(29+WEEKDAY(DATE(PlanYear,1,1),2)-1,7)+1)=AE$5,", "&30,"")&IF(INDEX($A$9:$G$19,2*INT((30+WEEKDAY(DATE(PlanYear,1,1),2)-1)/7)+1,MOD(30+WEEKDAY(DATE(PlanYear,1,1),2)-1,7)+1)=AE$5,", "&31,""),3,200)) | AF6: =IF(AF$5="","",MID(IF(INDEX($A$9:$G$19,2*INT((0+WEEKDAY(DATE(PlanYear,1,1),2)-1)/7)+1,MOD(0+WEEKDAY(DATE(PlanYear,1,1),2)-1,7)+1)=AF$5,", "&1,"")&IF(INDEX($A$9:$G$19,2*INT((1+WEEKDAY(DATE(PlanYear,1,1),2)-1)/7)+1,MOD(1+WEEKDAY(DATE(PlanYear,1,1),2)-1,7)+1)=AF$5,", "&2,"")&IF(INDEX($A$9:$G$19,2*INT((2+WEEKDAY(DATE(PlanYear,1,1),2)-1)/7)+1,MOD(2+WEEKDAY(DATE(PlanYear,1,1),2)-1,7)+1)=AF$5,", "&3,"")&IF(INDEX($A$9:$G$19,2*INT((3+WEEKDAY(DATE(PlanYear,1,1),2)-1)/7)+1,MOD(3+WEEKDAY(DATE(PlanYear,1,1),2)-1,7)+1)=AF$5,", "&4,"")&IF(INDEX($A$9:$G$19,2*INT((4+WEEKDAY(DATE(PlanYear,1,1),2)-1)/7)+1,MOD(4+WEEKDAY(DATE(PlanYear,1,1),2)-1,7)+1)=AF$5,", "&5,"")&IF(INDEX($A$9:$G$19,2*INT((5+WEEKDAY(DATE(PlanYear,1,1),2)-1)/7)+1,MOD(5+WEEKDAY(DATE(PlanYear,1,1),2)-1,7)+1)=AF$5,", "&6,"")&IF(INDEX($A$9:$G$19,2*INT((6+WEEKDAY(DATE(PlanYear,1,1),2)-1)/7)+1,MOD(6+WEEKDAY(DATE(PlanYear,1,1),2)-1,7)+1)=AF$5,", "&7,"")&IF(INDEX($A$9:$G$19,2*INT((7+WEEKDAY(DATE(PlanYear,1,1),2)-1)/7)+1,MOD(7+WEEKDAY(DATE(PlanYear,1,1),2)-1,7)+1)=AF$5,", "&8,"")&IF(INDEX($A$9:$G$19,2*INT((8+WEEKDAY(DATE(PlanYear,1,1),2)-1)/7)+1,MOD(8+WEEKDAY(DATE(PlanYear,1,1),2)-1,7)+1)=AF$5,", "&9,"")&IF(INDEX($A$9:$G$19,2*INT((9+WEEKDAY(DATE(PlanYear,1,1),2)-1)/7)+1,MOD(9+WEEKDAY(DATE(PlanYear,1,1),2)-1,7)+1)=AF$5,", "&10,"")&IF(INDEX($A$9:$G$19,2*INT((10+WEEKDAY(DATE(PlanYear,1,1),2)-1)/7)+1,MOD(10+WEEKDAY(DATE(PlanYear,1,1),2)-1,7)+1)=AF$5,", "&11,"")&IF(INDEX($A$9:$G$19,2*INT((11+WEEKDAY(DATE(PlanYear,1,1),2)-1)/7)+1,MOD(11+WEEKDAY(DATE(PlanYear,1,1),2)-1,7)+1)=AF$5,", "&12,"")&IF(INDEX($A$9:$G$19,2*INT((12+WEEKDAY(DATE(PlanYear,1,1),2)-1)/7)+1,MOD(12+WEEKDAY(DATE(PlanYear,1,1),2)-1,7)+1)=AF$5,", "&13,"")&IF(INDEX($A$9:$G$19,2*INT((13+WEEKDAY(DATE(PlanYear,1,1),2)-1)/7)+1,MOD(13+WEEKDAY(DATE(PlanYear,1,1),2)-1,7)+1)=AF$5,", "&14,"")&IF(INDEX($A$9:$G$19,2*INT((14+WEEKDAY(DATE(PlanYear,1,1),2)-1)/7)+1,MOD(14+WEEKDAY(DATE(PlanYear,1,1),2)-1,7)+1)=AF$5,", "&15,"")&IF(INDEX($A$9:$G$19,2*INT((15+WEEKDAY(DATE(PlanYear,1,1),2)-1)/7)+1,MOD(15+WEEKDAY(DATE(PlanYear,1,1),2)-1,7)+1)=AF$5,", "&16,"")&IF(INDEX($A$9:$G$19,2*INT((16+WEEKDAY(DATE(PlanYear,1,1),2)-1)/7)+1,MOD(16+WEEKDAY(DATE(PlanYear,1,1),2)-1,7)+1)=AF$5,", "&17,"")&IF(INDEX($A$9:$G$19,2*INT((17+WEEKDAY(DATE(PlanYear,1,1),2)-1)/7)+1,MOD(17+WEEKDAY(DATE(PlanYear,1,1),2)-1,7)+1)=AF$5,", "&18,"")&IF(INDEX($A$9:$G$19,2*INT((18+WEEKDAY(DATE(PlanYear,1,1),2)-1)/7)+1,MOD(18+WEEKDAY(DATE(PlanYear,1,1),2)-1,7)+1)=AF$5,", "&19,"")&IF(INDEX($A$9:$G$19,2*INT((19+WEEKDAY(DATE(PlanYear,1,1),2)-1)/7)+1,MOD(19+WEEKDAY(DATE(PlanYear,1,1),2)-1,7)+1)=AF$5,", "&20,"")&IF(INDEX($A$9:$G$19,2*INT((20+WEEKDAY(DATE(PlanYear,1,1),2)-1)/7)+1,MOD(20+WEEKDAY(DATE(PlanYear,1,1),2)-1,7)+1)=AF$5,", "&21,"")&IF(INDEX($A$9:$G$19,2*INT((21+WEEKDAY(DATE(PlanYear,1,1),2)-1)/7)+1,MOD(21+WEEKDAY(DATE(PlanYear,1,1),2)-1,7)+1)=AF$5,", "&22,"")&IF(INDEX($A$9:$G$19,2*INT((22+WEEKDAY(DATE(PlanYear,1,1),2)-1)/7)+1,MOD(22+WEEKDAY(DATE(PlanYear,1,1),2)-1,7)+1)=AF$5,", "&23,"")&IF(INDEX($A$9:$G$19,2*INT((23+WEEKDAY(DATE(PlanYear,1,1),2)-1)/7)+1,MOD(23+WEEKDAY(DATE(PlanYear,1,1),2)-1,7)+1)=AF$5,", "&24,"")&IF(INDEX($A$9:$G$19,2*INT((24+WEEKDAY(DATE(PlanYear,1,1),2)-1)/7)+1,MOD(24+WEEKDAY(DATE(PlanYear,1,1),2)-1,7)+1)=AF$5,", "&25,"")&IF(INDEX($A$9:$G$19,2*INT((25+WEEKDAY(DATE(PlanYear,1,1),2)-1)/7)+1,MOD(25+WEEKDAY(DATE(PlanYear,1,1),2)-1,7)+1)=AF$5,", "&26,"")&IF(INDEX($A$9:$G$19,2*INT((26+WEEKDAY(DATE(PlanYear,1,1),2)-1)/7)+1,MOD(26+WEEKDAY(DATE(PlanYear,1,1),2)-1,7)+1)=AF$5,", "&27,"")&IF(INDEX($A$9:$G$19,2*INT((27+WEEKDAY(DATE(PlanYear,1,1),2)-1)/7)+1,MOD(27+WEEKDAY(DATE(PlanYear,1,1),2)-1,7)+1)=AF$5,", "&28,"")&IF(INDEX($A$9:$G$19,2*INT((28+WEEKDAY(DATE(PlanYear,1,1),2)-1)/7)+1,MOD(28+WEEKDAY(DATE(PlanYear,1,1),2)-1,7)+1)=AF$5,", "&29,"")&IF(INDEX($A$9:$G$19,2*INT((29+WEEKDAY(DATE(PlanYear,1,1),2)-1)/7)+1,MOD(29+WEEKDAY(DATE(PlanYear,1,1),2)-1,7)+1)=AF$5,", "&30,"")&IF(INDEX($A$9:$G$19,2*INT((30+WEEKDAY(DATE(PlanYear,1,1),2)-1)/7)+1,MOD(30+WEEKDAY(DATE(PlanYear,1,1),2)-1,7)+1)=AF$5,", "&31,""),3,200)) | AG6: =IF(AG$5="","",MID(IF(INDEX($A$9:$G$19,2*INT((0+WEEKDAY(DATE(PlanYear,1,1),2)-1)/7)+1,MOD(0+WEEKDAY(DATE(PlanYear,1,1),2)-1,7)+1)=AG$5,", "&1,"")&IF(INDEX($A$9:$G$19,2*INT((1+WEEKDAY(DATE(PlanYear,1,1),2)-1)/7)+1,MOD(1+WEEKDAY(DATE(PlanYear,1,1),2)-1,7)+1)=AG$5,", "&2,"")&IF(INDEX($A$9:$G$19,2*INT((2+WEEKDAY(DATE(PlanYear,1,1),2)-1)/7)+1,MOD(2+WEEKDAY(DATE(PlanYear,1,1),2)-1,7)+1)=AG$5,", "&3,"")&IF(INDEX($A$9:$G$19,2*INT((3+WEEKDAY(DATE(PlanYear,1,1),2)-1)/7)+1,MOD(3+WEEKDAY(DATE(PlanYear,1,1),2)-1,7)+1)=AG$5,", "&4,"")&IF(INDEX($A$9:$G$19,2*INT((4+WEEKDAY(DATE(PlanYear,1,1),2)-1)/7)+1,MOD(4+WEEKDAY(DATE(PlanYear,1,1),2)-1,7)+1)=AG$5,", "&5,"")&IF(INDEX($A$9:$G$19,2*INT((5+WEEKDAY(DATE(PlanYear,1,1),2)-1)/7)+1,MOD(5+WEEKDAY(DATE(PlanYear,1,1),2)-1,7)+1)=AG$5,", "&6,"")&IF(INDEX($A$9:$G$19,2*INT((6+WEEKDAY(DATE(PlanYear,1,1),2)-1)/7)+1,MOD(6+WEEKDAY(DATE(PlanYear,1,1),2)-1,7)+1)=AG$5,", "&7,"")&IF(INDEX($A$9:$G$19,2*INT((7+WEEKDAY(DATE(PlanYear,1,1),2)-1)/7)+1,MOD(7+WEEKDAY(DATE(PlanYear,1,1),2)-1,7)+1)=AG$5,", "&8,"")&IF(INDEX($A$9:$G$19,2*INT((8+WEEKDAY(DATE(PlanYear,1,1),2)-1)/7)+1,MOD(8+WEEKDAY(DATE(PlanYear,1,1),2)-1,7)+1)=AG$5,", "&9,"")&IF(INDEX($A$9:$G$19,2*INT((9+WEEKDAY(DATE(PlanYear,1,1),2)-1)/7)+1,MOD(9+WEEKDAY(DATE(PlanYear,1,1),2)-1,7)+1)=AG$5,", "&10,"")&IF(INDEX($A$9:$G$19,2*INT((10+WEEKDAY(DATE(PlanYear,1,1),2)-1)/7)+1,MOD(10+WEEKDAY(DATE(PlanYear,1,1),2)-1,7)+1)=AG$5,", "&11,"")&IF(INDEX($A$9:$G$19,2*INT((11+WEEKDAY(DATE(PlanYear,1,1),2)-1)/7)+1,MOD(11+WEEKDAY(DATE(PlanYear,1,1),2)-1,7)+1)=AG$5,", "&12,"")&IF(INDEX($A$9:$G$19,2*INT((12+WEEKDAY(DATE(PlanYear,1,1),2)-1)/7)+1,MOD(12+WEEKDAY(DATE(PlanYear,1,1),2)-1,7)+1)=AG$5,", "&13,"")&IF(INDEX($A$9:$G$19,2*INT((13+WEEKDAY(DATE(PlanYear,1,1),2)-1)/7)+1,MOD(13+WEEKDAY(DATE(PlanYear,1,1),2)-1,7)+1)=AG$5,", "&14,"")&IF(INDEX($A$9:$G$19,2*INT((14+WEEKDAY(DATE(PlanYear,1,1),2)-1)/7)+1,MOD(14+WEEKDAY(DATE(PlanYear,1,1),2)-1,7)+1)=AG$5,", "&15,"")&IF(INDEX($A$9:$G$19,2*INT((15+WEEKDAY(DATE(PlanYear,1,1),2)-1)/7)+1,MOD(15+WEEKDAY(DATE(PlanYear,1,1),2)-1,7)+1)=AG$5,", "&16,"")&IF(INDEX($A$9:$G$19,2*INT((16+WEEKDAY(DATE(PlanYear,1,1),2)-1)/7)+1,MOD(16+WEEKDAY(DATE(PlanYear,1,1),2)-1,7)+1)=AG$5,", "&17,"")&IF(INDEX($A$9:$G$19,2*INT((17+WEEKDAY(DATE(PlanYear,1,1),2)-1)/7)+1,MOD(17+WEEKDAY(DATE(PlanYear,1,1),2)-1,7)+1)=AG$5,", "&18,"")&IF(INDEX($A$9:$G$19,2*INT((18+WEEKDAY(DATE(PlanYear,1,1),2)-1)/7)+1,MOD(18+WEEKDAY(DATE(PlanYear,1,1),2)-1,7)+1)=AG$5,", "&19,"")&IF(INDEX($A$9:$G$19,2*INT((19+WEEKDAY(DATE(PlanYear,1,1),2)-1)/7)+1,MOD(19+WEEKDAY(DATE(PlanYear,1,1),2)-1,7)+1)=AG$5,", "&20,"")&IF(INDEX($A$9:$G$19,2*INT((20+WEEKDAY(DATE(PlanYear,1,1),2)-1)/7)+1,MOD(20+WEEKDAY(DATE(PlanYear,1,1),2)-1,7)+1)=AG$5,", "&21,"")&IF(INDEX($A$9:$G$19,2*INT((21+WEEKDAY(DATE(PlanYear,1,1),2)-1)/7)+1,MOD(21+WEEKDAY(DATE(PlanYear,1,1),2)-1,7)+1)=AG$5,", "&22,"")&IF(INDEX($A$9:$G$19,2*INT((22+WEEKDAY(DATE(PlanYear,1,1),2)-1)/7)+1,MOD(22+WEEKDAY(DATE(PlanYear,1,1),2)-1,7)+1)=AG$5,", "&23,"")&IF(INDEX($A$9:$G$19,2*INT((23+WEEKDAY(DATE(PlanYear,1,1),2)-1)/7)+1,MOD(23+WEEKDAY(DATE(PlanYear,1,1),2)-1,7)+1)=AG$5,", "&24,"")&IF(INDEX($A$9:$G$19,2*INT((24+WEEKDAY(DATE(PlanYear,1,1),2)-1)/7)+1,MOD(24+WEEKDAY(DATE(PlanYear,1,1),2)-1,7)+1)=AG$5,", "&25,"")&IF(INDEX($A$9:$G$19,2*INT((25+WEEKDAY(DATE(PlanYear,1,1),2)-1)/7)+1,MOD(25+WEEKDAY(DATE(PlanYear,1,1),2)-1,7)+1)=AG$5,", "&26,"")&IF(INDEX($A$9:$G$19,2*INT((26+WEEKDAY(DATE(PlanYear,1,1),2)-1)/7)+1,MOD(26+WEEKDAY(DATE(PlanYear,1,1),2)-1,7)+1)=AG$5,", "&27,"")&IF(INDEX($A$9:$G$19,2*INT((27+WEEKDAY(DATE(PlanYear,1,1),2)-1)/7)+1,MOD(27+WEEKDAY(DATE(PlanYear,1,1),2)-1,7)+1)=AG$5,", "&28,"")&IF(INDEX($A$9:$G$19,2*INT((28+WEEKDAY(DATE(PlanYear,1,1),2)-1)/7)+1,MOD(28+WEEKDAY(DATE(PlanYear,1,1),2)-1,7)+1)=AG$5,", "&29,"")&IF(INDEX($A$9:$G$19,2*INT((29+WEEKDAY(DATE(PlanYear,1,1),2)-1)/7)+1,MOD(29+WEEKDAY(DATE(PlanYear,1,1),2)-1,7)+1)=AG$5,", "&30,"")&IF(INDEX($A$9:$G$19,2*INT((30+WEEKDAY(DATE(PlanYear,1,1),2)-1)/7)+1,MOD(30+WEEKDAY(DATE(PlanYear,1,1),2)-1,7)+1)=AG$5,", "&31,""),3,200)) | AH6: =IF(AH$5="","",MID(IF(INDEX($A$9:$G$19,2*INT((0+WEEKDAY(DATE(PlanYear,1,1),2)-1)/7)+1,MOD(0+WEEKDAY(DATE(PlanYear,1,1),2)-1,7)+1)=AH$5,", "&1,"")&IF(INDEX($A$9:$G$19,2*INT((1+WEEKDAY(DATE(PlanYear,1,1),2)-1)/7)+1,MOD(1+WEEKDAY(DATE(PlanYear,1,1),2)-1,7)+1)=AH$5,", "&2,"")&IF(INDEX($A$9:$G$19,2*INT((2+WEEKDAY(DATE(PlanYear,1,1),2)-1)/7)+1,MOD(2+WEEKDAY(DATE(PlanYear,1,1),2)-1,7)+1)=AH$5,", "&3,"")&IF(INDEX($A$9:$G$19,2*INT((3+WEEKDAY(DATE(PlanYear,1,1),2)-1)/7)+1,MOD(3+WEEKDAY(DATE(PlanYear,1,1),2)-1,7)+1)=AH$5,", "&4,"")&IF(INDEX($A$9:$G$19,2*INT((4+WEEKDAY(DATE(PlanYear,1,1),2)-1)/7)+1,MOD(4+WEEKDAY(DATE(PlanYear,1,1),2)-1,7)+1)=AH$5,", "&5,"")&IF(INDEX($A$9:$G$19,2*INT((5+WEEKDAY(DATE(PlanYear,1,1),2)-1)/7)+1,MOD(5+WEEKDAY(DATE(PlanYear,1,1),2)-1,7)+1)=AH$5,", "&6,"")&IF(INDEX($A$9:$G$19,2*INT((6+WEEKDAY(DATE(PlanYear,1,1),2)-1)/7)+1,MOD(6+WEEKDAY(DATE(PlanYear,1,1),2)-1,7)+1)=AH$5,", "&7,"")&IF(INDEX($A$9:$G$19,2*INT((7+WEEKDAY(DATE(PlanYear,1,1),2)-1)/7)+1,MOD(7+WEEKDAY(DATE(PlanYear,1,1),2)-1,7)+1)=AH$5,", "&8,"")&IF(INDEX($A$9:$G$19,2*INT((8+WEEKDAY(DATE(PlanYear,1,1),2)-1)/7)+1,MOD(8+WEEKDAY(DATE(PlanYear,1,1),2)-1,7)+1)=AH$5,", "&9,"")&IF(INDEX($A$9:$G$19,2*INT((9+WEEKDAY(DATE(PlanYear,1,1),2)-1)/7)+1,MOD(9+WEEKDAY(DATE(PlanYear,1,1),2)-1,7)+1)=AH$5,", "&10,"")&IF(INDEX($A$9:$G$19,2*INT((10+WEEKDAY(DATE(PlanYear,1,1),2)-1)/7)+1,MOD(10+WEEKDAY(DATE(PlanYear,1,1),2)-1,7)+1)=AH$5,", "&11,"")&IF(INDEX($A$9:$G$19,2*INT((11+WEEKDAY(DATE(PlanYear,1,1),2)-1)/7)+1,MOD(11+WEEKDAY(DATE(PlanYear,1,1),2)-1,7)+1)=AH$5,", "&12,"")&IF(INDEX($A$9:$G$19,2*INT((12+WEEKDAY(DATE(PlanYear,1,1),2)-1)/7)+1,MOD(12+WEEKDAY(DATE(PlanYear,1,1),2)-1,7)+1)=AH$5,", "&13,"")&IF(INDEX($A$9:$G$19,2*INT((13+WEEKDAY(DATE(PlanYear,1,1),2)-1)/7)+1,MOD(13+WEEKDAY(DATE(PlanYear,1,1),2)-1,7)+1)=AH$5,", "&14,"")&IF(INDEX($A$9:$G$19,2*INT((14+WEEKDAY(DATE(PlanYear,1,1),2)-1)/7)+1,MOD(14+WEEKDAY(DATE(PlanYear,1,1),2)-1,7)+1)=AH$5,", "&15,"")&IF(INDEX($A$9:$G$19,2*INT((15+WEEKDAY(DATE(PlanYear,1,1),2)-1)/7)+1,MOD(15+WEEKDAY(DATE(PlanYear,1,1),2)-1,7)+1)=AH$5,", "&16,"")&IF(INDEX($A$9:$G$19,2*INT((16+WEEKDAY(DATE(PlanYear,1,1),2)-1)/7)+1,MOD(16+WEEKDAY(DATE(PlanYear,1,1),2)-1,7)+1)=AH$5,", "&17,"")&IF(INDEX($A$9:$G$19,2*INT((17+WEEKDAY(DATE(PlanYear,1,1),2)-1)/7)+1,MOD(17+WEEKDAY(DATE(PlanYear,1,1),2)-1,7)+1)=AH$5,", "&18,"")&IF(INDEX($A$9:$G$19,2*INT((18+WEEKDAY(DATE(PlanYear,1,1),2)-1)/7)+1,MOD(18+WEEKDAY(DATE(PlanYear,1,1),2)-1,7)+1)=AH$5,", "&19,"")&IF(INDEX($A$9:$G$19,2*INT((19+WEEKDAY(DATE(PlanYear,1,1),2)-1)/7)+1,MOD(19+WEEKDAY(DATE(PlanYear,1,1),2)-1,7)+1)=AH$5,", "&20,"")&IF(INDEX($A$9:$G$19,2*INT((20+WEEKDAY(DATE(PlanYear,1,1),2)-1)/7)+1,MOD(20+WEEKDAY(DATE(PlanYear,1,1),2)-1,7)+1)=AH$5,", "&21,"")&IF(INDEX($A$9:$G$19,2*INT((21+WEEKDAY(DATE(PlanYear,1,1),2)-1)/7)+1,MOD(21+WEEKDAY(DATE(PlanYear,1,1),2)-1,7)+1)=AH$5,", "&22,"")&IF(INDEX($A$9:$G$19,2*INT((22+WEEKDAY(DATE(PlanYear,1,1),2)-1)/7)+1,MOD(22+WEEKDAY(DATE(PlanYear,1,1),2)-1,7)+1)=AH$5,", "&23,"")&IF(INDEX($A$9:$G$19,2*INT((23+WEEKDAY(DATE(PlanYear,1,1),2)-1)/7)+1,MOD(23+WEEKDAY(DATE(PlanYear,1,1),2)-1,7)+1)=AH$5,", "&24,"")&IF(INDEX($A$9:$G$19,2*INT((24+WEEKDAY(DATE(PlanYear,1,1),2)-1)/7)+1,MOD(24+WEEKDAY(DATE(PlanYear,1,1),2)-1,7)+1)=AH$5,", "&25,"")&IF(INDEX($A$9:$G$19,2*INT((25+WEEKDAY(DATE(PlanYear,1,1),2)-1)/7)+1,MOD(25+WEEKDAY(DATE(PlanYear,1,1),2)-1,7)+1)=AH$5,", "&26,"")&IF(INDEX($A$9:$G$19,2*INT((26+WEEKDAY(DATE(PlanYear,1,1),2)-1)/7)+1,MOD(26+WEEKDAY(DATE(PlanYear,1,1),2)-1,7)+1)=AH$5,", "&27,"")&IF(INDEX($A$9:$G$19,2*INT((27+WEEKDAY(DATE(PlanYear,1,1),2)-1)/7)+1,MOD(27+WEEKDAY(DATE(PlanYear,1,1),2)-1,7)+1)=AH$5,", "&28,"")&IF(INDEX($A$9:$G$19,2*INT((28+WEEKDAY(DATE(PlanYear,1,1),2)-1)/7)+1,MOD(28+WEEKDAY(DATE(PlanYear,1,1),2)-1,7)+1)=AH$5,", "&29,"")&IF(INDEX($A$9:$G$19,2*INT((29+WEEKDAY(DATE(PlanYear,1,1),2)-1)/7)+1,MOD(29+WEEKDAY(DATE(PlanYear,1,1),2)-1,7)+1)=AH$5,", "&30,"")&IF(INDEX($A$9:$G$19,2*INT((30+WEEKDAY(DATE(PlanYear,1,1),2)-1)/7)+1,MOD(30+WEEKDAY(DATE(PlanYear,1,1),2)-1,7)+1)=AH$5,", "&31,""),3,200)) | ... AJ6: =IF(AJ$5="","",MID(IF(INDEX($A$9:$G$19,2*INT((0+WEEKDAY(DATE(PlanYear,1,1),2)-1)/7)+1,MOD(0+WEEKDAY(DATE(PlanYear,1,1),2)-1,7)+1)=AJ$5,", "&1,"")&IF(INDEX($A$9:$G$19,2*INT((1+WEEKDAY(DATE(PlanYear,1,1),2)-1)/7)+1,MOD(1+WEEKDAY(DATE(PlanYear,1,1),2)-1,7)+1)=AJ$5,", "&2,"")&IF(INDEX($A$9:$G$19,2*INT((2+WEEKDAY(DATE(PlanYear,1,1),2)-1)/7)+1,MOD(2+WEEKDAY(DATE(PlanYear,1,1),2)-1,7)+1)=AJ$5,", "&3,"")&IF(INDEX($A$9:$G$19,2*INT((3+WEEKDAY(DATE(PlanYear,1,1),2)-1)/7)+1,MOD(3+WEEKDAY(DATE(PlanYear,1,1),2)-1,7)+1)=AJ$5,", "&4,"")&IF(INDEX($A$9:$G$19,2*INT((4+WEEKDAY(DATE(PlanYear,1,1),2)-1)/7)+1,MOD(4+WEEKDAY(DATE(PlanYear,1,1),2)-1,7)+1)=AJ$5,", "&5,"")&IF(INDEX($A$9:$G$19,2*INT((5+WEEKDAY(DATE(PlanYear,1,1),2)-1)/7)+1,MOD(5+WEEKDAY(DATE(PlanYear,1,1),2)-1,7)+1)=AJ$5,", "&6,"")&IF(INDEX($A$9:$G$19,2*INT((6+WEEKDAY(DATE(PlanYear,1,1),2)-1)/7)+1,MOD(6+WEEKDAY(DATE(PlanYear,1,1),2)-1,7)+1)=AJ$5,", "&7,"")&IF(INDEX($A$9:$G$19,2*INT((7+WEEKDAY(DATE(PlanYear,1,1),2)-1)/7)+1,MOD(7+WEEKDAY(DATE(PlanYear,1,1),2)-1,7)+1)=AJ$5,", "&8,"")&IF(INDEX($A$9:$G$19,2*INT((8+WEEKDAY(DATE(PlanYear,1,1),2)-1)/7)+1,MOD(8+WEEKDAY(DATE(PlanYear,1,1),2)-1,7)+1)=AJ$5,", "&9,"")&IF(INDEX($A$9:$G$19,2*INT((9+WEEKDAY(DATE(PlanYear,1,1),2)-1)/7)+1,MOD(9+WEEKDAY(DATE(PlanYear,1,1),2)-1,7)+1)=AJ$5,", "&10,"")&IF(INDEX($A$9:$G$19,2*INT((10+WEEKDAY(DATE(PlanYear,1,1),2)-1)/7)+1,MOD(10+WEEKDAY(DATE(PlanYear,1,1),2)-1,7)+1)=AJ$5,", "&11,"")&IF(INDEX($A$9:$G$19,2*INT((11+WEEKDAY(DATE(PlanYear,1,1),2)-1)/7)+1,MOD(11+WEEKDAY(DATE(PlanYear,1,1),2)-1,7)+1)=AJ$5,", "&12,"")&IF(INDEX($A$9:$G$19,2*INT((12+WEEKDAY(DATE(PlanYear,1,1),2)-1)/7)+1,MOD(12+WEEKDAY(DATE(PlanYear,1,1),2)-1,7)+1)=AJ$5,", "&13,"")&IF(INDEX($A$9:$G$19,2*INT((13+WEEKDAY(DATE(PlanYear,1,1),2)-1)/7)+1,MOD(13+WEEKDAY(DATE(PlanYear,1,1),2)-1,7)+1)=AJ$5,", "&14,"")&IF(INDEX($A$9:$G$19,2*INT((14+WEEKDAY(DATE(PlanYear,1,1),2)-1)/7)+1,MOD(14+WEEKDAY(DATE(PlanYear,1,1),2)-1,7)+1)=AJ$5,", "&15,"")&IF(INDEX($A$9:$G$19,2*INT((15+WEEKDAY(DATE(PlanYear,1,1),2)-1)/7)+1,MOD(15+WEEKDAY(DATE(PlanYear,1,1),2)-1,7)+1)=AJ$5,", "&16,"")&IF(INDEX($A$9:$G$19,2*INT((16+WEEKDAY(DATE(PlanYear,1,1),2)-1)/7)+1,MOD(16+WEEKDAY(DATE(PlanYear,1,1),2)-1,7)+1)=AJ$5,", "&17,"")&IF(INDEX($A$9:$G$19,2*INT((17+WEEKDAY(DATE(PlanYear,1,1),2)-1)/7)+1,MOD(17+WEEKDAY(DATE(PlanYear,1,1),2)-1,7)+1)=AJ$5,", "&18,"")&IF(INDEX($A$9:$G$19,2*INT((18+WEEKDAY(DATE(PlanYear,1,1),2)-1)/7)+1,MOD(18+WEEKDAY(DATE(PlanYear,1,1),2)-1,7)+1)=AJ$5,", "&19,"")&IF(INDEX($A$9:$G$19,2*INT((19+WEEKDAY(DATE(PlanYear,1,1),2)-1)/7)+1,MOD(19+WEEKDAY(DATE(PlanYear,1,1),2)-1,7)+1)=AJ$5,", "&20,"")&IF(INDEX($A$9:$G$19,2*INT((20+WEEKDAY(DATE(PlanYear,1,1),2)-1)/7)+1,MOD(20+WEEKDAY(DATE(PlanYear,1,1),2)-1,7)+1)=AJ$5,", "&21,"")&IF(INDEX($A$9:$G$19,2*INT((21+WEEKDAY(DATE(PlanYear,1,1),2)-1)/7)+1,MOD(21+WEEKDAY(DATE(PlanYear,1,1),2)-1,7)+1)=AJ$5,", "&22,"")&IF(INDEX($A$9:$G$19,2*INT((22+WEEKDAY(DATE(PlanYear,1,1),2)-1)/7)+1,MOD(22+WEEKDAY(DATE(PlanYear,1,1),2)-1,7)+1)=AJ$5,", "&23,"")&IF(INDEX($A$9:$G$19,2*INT((23+WEEKDAY(DATE(PlanYear,1,1),2)-1)/7)+1,MOD(23+WEEKDAY(DATE(PlanYear,1,1),2)-1,7)+1)=AJ$5,", "&24,"")&IF(INDEX($A$9:$G$19,2*INT((24+WEEKDAY(DATE(PlanYear,1,1),2)-1)/7)+1,MOD(24+WEEKDAY(DATE(PlanYear,1,1),2)-1,7)+1)=AJ$5,", "&25,"")&IF(INDEX($A$9:$G$19,2*INT((25+WEEKDAY(DATE(PlanYear,1,1),2)-1)/7)+1,MOD(25+WEEKDAY(DATE(PlanYear,1,1),2)-1,7)+1)=AJ$5,", "&26,"")&IF(INDEX($A$9:$G$19,2*INT((26+WEEKDAY(DATE(PlanYear,1,1),2)-1)/7)+1,MOD(26+WEEKDAY(DATE(PlanYear,1,1),2)-1,7)+1)=AJ$5,", "&27,"")&IF(INDEX($A$9:$G$19,2*INT((27+WEEKDAY(DATE(PlanYear,1,1),2)-1)/7)+1,MOD(27+WEEKDAY(DATE(PlanYear,1,1),2)-1,7)+1)=AJ$5,", "&28,"")&IF(INDEX($A$9:$G$19,2*INT((28+WEEKDAY(DATE(PlanYear,1,1),2)-1)/7)+1,MOD(28+WEEKDAY(DATE(PlanYear,1,1),2)-1,7)+1)=AJ$5,", "&29,"")&IF(INDEX($A$9:$G$19,2*INT((29+WEEKDAY(DATE(PlanYear,1,1),2)-1)/7)+1,MOD(29+WEEKDAY(DATE(PlanYear,1,1),2)-1,7)+1)=AJ$5,", "&30,"")&IF(INDEX($A$9:$G$19,2*INT((30+WEEKDAY(DATE(PlanYear,1,1),2)-1)/7)+1,MOD(30+WEEKDAY(DATE(PlanYear,1,1),2)-1,7)+1)=AJ$5,", "&31,""),3,200)) | AK6: =DAY(EOMONTH(DATE(PlanYear,1,1),0))-COUNTIF($A$9:$G$19,"?*")
