Workbook
Name CrewName: Roster!$C$6:$C$65
Name CrewCat: Roster!$E$6:$E$65
Name CrewStatus: Roster!$G$6:$G$65
Name NoteKey: 'Cell Notes'!$G$6:$G$1505
Name SylStageList: 'Syllabus Stages'!$A$6:INDEX('Syllabus Stages'!$A$6:$A$25,MAX(1,COUNTA('Syllabus Stages'!$A$6:$A$25)))
Name ActSort: Activities!$L$6:$L$65
Name FlightCodes: Activities!$N$6:INDEX(Activities!$N$6:$N$65,MAX(1,COUNTIF(Activities!$C$6:$C$65,Activities!$G$6)))
Name WdCodes: Activities!$P$6:INDEX(Activities!$P$6:$P$65,MAX(1,COUNTIF(Activities!$C$6:$C$65,Activities!$G$8)+COUNTIF(Activities!$C$6:$C$65,Activities!$G$12)))
Name ActCodesAll: Activities!$A$6:$A$65
Name ActCat: Activities!$C$6:$C$65
Name ActHrs: Activities!$D$6:$D$65
Name ActCodes: Activities!$A$6:INDEX(Activities!$A$6:$A$65,MAX(1,COUNTA(Activities!$A$6:$A$65)))
Name Categories: Activities!$G$6:$G$14
Name Holidays: Activities!$I$6:$I$35
Name ThisDept: Dashboard!$G$5
Name PlanYear: Dashboard!$A$5
Name MonthIdx: Dashboard!$Z$1

Sheet Dashboard
A1: LODESTAR | SUP 2 | FLIGHT & OPS PLANNING DASHBOARD | Z1: =MATCH($B$5,{"January","February","March","April","May","June","July","August","September","October","November","December"},0)
A2: Pick a year and month to see its totals. Planning is done on the month tabs: click Open planner. | Z2: LODESTAR dept layout 3
A4: YEAR | B4: MONTH | G4: DEPARTMENT (this file)
A5: 2026 | B5: October | C5: =HYPERLINK("#'"&LEFT($B$5,3)&"'!D27","Open "&$B$5&" planner >") | E5: =HYPERLINK("#'SDO Plan'!A1","SDO Plan >") | G5: SUP 2
A7: TOTAL FLIGHTS | B7: TOTAL FLYING HRS | C7: GROUND DUTIES | D7: SDO PLANNED | F7: ACTIVE CREW | H7: SDO DAYS UNCOVERED | K7: UNCREWED SHIFTS
A8: =CHOOSE(MonthIdx,'Jan'!D3,'Feb'!D3,'Mar'!D3,'Apr'!D3,'May'!D3,'Jun'!D3,'Jul'!D3,'Aug'!D3,'Sep'!D3,'Oct'!D3,'Nov'!D3,'Dec'!D3) | B8: =CHOOSE(MonthIdx,'Jan'!E3,'Feb'!E3,'Mar'!E3,'Apr'!E3,'May'!E3,'Jun'!E3,'Jul'!E3,'Aug'!E3,'Sep'!E3,'Oct'!E3,'Nov'!E3,'Dec'!E3) | C8: =CHOOSE(MonthIdx,'Jan'!F3,'Feb'!F3,'Mar'!F3,'Apr'!F3,'May'!F3,'Jun'!F3,'Jul'!F3,'Aug'!F3,'Sep'!F3,'Oct'!F3,'Nov'!F3,'Dec'!F3) | D8: =CHOOSE(MonthIdx,'Jan'!G3,'Feb'!G3,'Mar'!G3,'Apr'!G3,'May'!G3,'Jun'!G3,'Jul'!G3,'Aug'!G3,'Sep'!G3,'Oct'!G3,'Nov'!G3,'Dec'!G3) | F8: =(COUNTIFS(CrewName,"<>")-COUNTIFS(CrewName,"<>",CrewStatus,"Inactive")) | H8: =CHOOSE(MonthIdx,'Jan'!I3,'Feb'!I3,'Mar'!I3,'Apr'!I3,'May'!I3,'Jun'!I3,'Jul'!I3,'Aug'!I3,'Sep'!I3,'Oct'!I3,'Nov'!I3,'Dec'!I3) | K8: =CHOOSE(MonthIdx,'Jan'!J3,'Feb'!J3,'Mar'!J3,'Apr'!J3,'May'!J3,'Jun'!J3,'Jul'!J3,'Aug'!J3,'Sep'!J3,'Oct'!J3,'Nov'!J3,'Dec'!J3)
A10: ="CREW TOTALS | "&UPPER($B$5)&" "&$A$5 | D10: Empty slots are hidden: Data > Reapply shows new crew | K10: ACTIVITY LEGEND
A11: Callsign | B11: Crew Member | C11: Role | D11: Status | E11: Flights | F11: Fly Hrs | G11: Gnd Duty | H11: Sqn Duty | I11: Leave | K11: Code | L11: Description | N11: Hrs
A12: =IF(Roster!$B$6="","",Roster!$B$6) | B12: =IF(Roster!$C$6="","",Roster!$C$6) | C12: =IF(Roster!$C$6="","",Roster!$F$6&"") | D12: =IF(Roster!$C$6="","",Roster!$G$6&"") | E12: =IF($B12="","",CHOOSE(MonthIdx,'Jan'!AI27,'Feb'!AI27,'Mar'!AI27,'Apr'!AI27,'May'!AI27,'Jun'!AI27,'Jul'!AI27,'Aug'!AI27,'Sep'!AI27,'Oct'!AI27,'Nov'!AI27,'Dec'!AI27)) | F12: =IF($B12="","",CHOOSE(MonthIdx,'Jan'!AJ27,'Feb'!AJ27,'Mar'!AJ27,'Apr'!AJ27,'May'!AJ27,'Jun'!AJ27,'Jul'!AJ27,'Aug'!AJ27,'Sep'!AJ27,'Oct'!AJ27,'Nov'!AJ27,'Dec'!AJ27)) | G12: =IF($B12="","",CHOOSE(MonthIdx,'Jan'!AK27,'Feb'!AK27,'Mar'!AK27,'Apr'!AK27,'May'!AK27,'Jun'!AK27,'Jul'!AK27,'Aug'!AK27,'Sep'!AK27,'Oct'!AK27,'Nov'!AK27,'Dec'!AK27)) | H12: =IF($B12="","",CHOOSE(MonthIdx,'Jan'!AL27,'Feb'!AL27,'Mar'!AL27,'Apr'!AL27,'May'!AL27,'Jun'!AL27,'Jul'!AL27,'Aug'!AL27,'Sep'!AL27,'Oct'!AL27,'Nov'!AL27,'Dec'!AL27)) | I12: =IF($B12="","",CHOOSE(MonthIdx,'Jan'!AM27,'Feb'!AM27,'Mar'!AM27,'Apr'!AM27,'May'!AM27,'Jun'!AM27,'Jul'!AM27,'Aug'!AM27,'Sep'!AM27,'Oct'!AM27,'Nov'!AM27,'Dec'!AM27)) | K12: =IF(Activities!$A$6="","",Activities!$A$6) | L12: =IF(Activities!$A$6="","",Activities!$B$6&"") | N12: =IF(Activities!$A$6="","",Activities!$D$6)
A13: =IF(Roster!$B$7="","",Roster!$B$7) | B13: =IF(Roster!$C$7="","",Roster!$C$7) | C13: =IF(Roster!$C$7="","",Roster!$F$7&"") | D13: =IF(Roster!$C$7="","",Roster!$G$7&"") | E13: =IF($B13="","",CHOOSE(MonthIdx,'Jan'!AI31,'Feb'!AI31,'Mar'!AI31,'Apr'!AI31,'May'!AI31,'Jun'!AI31,'Jul'!AI31,'Aug'!AI31,'Sep'!AI31,'Oct'!AI31,'Nov'!AI31,'Dec'!AI31)) | F13: =IF($B13="","",CHOOSE(MonthIdx,'Jan'!AJ31,'Feb'!AJ31,'Mar'!AJ31,'Apr'!AJ31,'May'!AJ31,'Jun'!AJ31,'Jul'!AJ31,'Aug'!AJ31,'Sep'!AJ31,'Oct'!AJ31,'Nov'!AJ31,'Dec'!AJ31)) | G13: =IF($B13="","",CHOOSE(MonthIdx,'Jan'!AK31,'Feb'!AK31,'Mar'!AK31,'Apr'!AK31,'May'!AK31,'Jun'!AK31,'Jul'!AK31,'Aug'!AK31,'Sep'!AK31,'Oct'!AK31,'Nov'!AK31,'Dec'!AK31)) | H13: =IF($B13="","",CHOOSE(MonthIdx,'Jan'!AL31,'Feb'!AL31,'Mar'!AL31,'Apr'!AL31,'May'!AL31,'Jun'!AL31,'Jul'!AL31,'Aug'!AL31,'Sep'!AL31,'Oct'!AL31,'Nov'!AL31,'Dec'!AL31)) | I13: =IF($B13="","",CHOOSE(MonthIdx,'Jan'!AM31,'Feb'!AM31,'Mar'!AM31,'Apr'!AM31,'May'!AM31,'Jun'!AM31,'Jul'!AM31,'Aug'!AM31,'Sep'!AM31,'Oct'!AM31,'Nov'!AM31,'Dec'!AM31)) | K13: =IF(Activities!$A$7="","",Activities!$A$7) | L13: =IF(Activities!$A$7="","",Activities!$B$7&"") | N13: =IF(Activities!$A$7="","",Activities!$D$7)
A14: =IF(Roster!$B$8="","",Roster!$B$8) | B14: =IF(Roster!$C$8="","",Roster!$C$8) | C14: =IF(Roster!$C$8="","",Roster!$F$8&"") | D14: =IF(Roster!$C$8="","",Roster!$G$8&"") | E14: =IF($B14="","",CHOOSE(MonthIdx,'Jan'!AI35,'Feb'!AI35,'Mar'!AI35,'Apr'!AI35,'May'!AI35,'Jun'!AI35,'Jul'!AI35,'Aug'!AI35,'Sep'!AI35,'Oct'!AI35,'Nov'!AI35,'Dec'!AI35)) | F14: =IF($B14="","",CHOOSE(MonthIdx,'Jan'!AJ35,'Feb'!AJ35,'Mar'!AJ35,'Apr'!AJ35,'May'!AJ35,'Jun'!AJ35,'Jul'!AJ35,'Aug'!AJ35,'Sep'!AJ35,'Oct'!AJ35,'Nov'!AJ35,'Dec'!AJ35)) | G14: =IF($B14="","",CHOOSE(MonthIdx,'Jan'!AK35,'Feb'!AK35,'Mar'!AK35,'Apr'!AK35,'May'!AK35,'Jun'!AK35,'Jul'!AK35,'Aug'!AK35,'Sep'!AK35,'Oct'!AK35,'Nov'!AK35,'Dec'!AK35)) | H14: =IF($B14="","",CHOOSE(MonthIdx,'Jan'!AL35,'Feb'!AL35,'Mar'!AL35,'Apr'!AL35,'May'!AL35,'Jun'!AL35,'Jul'!AL35,'Aug'!AL35,'Sep'!AL35,'Oct'!AL35,'Nov'!AL35,'Dec'!AL35)) | I14: =IF($B14="","",CHOOSE(MonthIdx,'Jan'!AM35,'Feb'!AM35,'Mar'!AM35,'Apr'!AM35,'May'!AM35,'Jun'!AM35,'Jul'!AM35,'Aug'!AM35,'Sep'!AM35,'Oct'!AM35,'Nov'!AM35,'Dec'!AM35)) | K14: =IF(Activities!$A$8="","",Activities!$A$8) | L14: =IF(Activities!$A$8="","",Activities!$B$8&"") | N14: =IF(Activities!$A$8="","",Activities!$D$8)
A15: =IF(Roster!$B$9="","",Roster!$B$9) | B15: =IF(Roster!$C$9="","",Roster!$C$9) | C15: =IF(Roster!$C$9="","",Roster!$F$9&"") | D15: =IF(Roster!$C$9="","",Roster!$G$9&"") | E15: =IF($B15="","",CHOOSE(MonthIdx,'Jan'!AI39,'Feb'!AI39,'Mar'!AI39,'Apr'!AI39,'May'!AI39,'Jun'!AI39,'Jul'!AI39,'Aug'!AI39,'Sep'!AI39,'Oct'!AI39,'Nov'!AI39,'Dec'!AI39)) | F15: =IF($B15="","",CHOOSE(MonthIdx,'Jan'!AJ39,'Feb'!AJ39,'Mar'!AJ39,'Apr'!AJ39,'May'!AJ39,'Jun'!AJ39,'Jul'!AJ39,'Aug'!AJ39,'Sep'!AJ39,'Oct'!AJ39,'Nov'!AJ39,'Dec'!AJ39)) | G15: =IF($B15="","",CHOOSE(MonthIdx,'Jan'!AK39,'Feb'!AK39,'Mar'!AK39,'Apr'!AK39,'May'!AK39,'Jun'!AK39,'Jul'!AK39,'Aug'!AK39,'Sep'!AK39,'Oct'!AK39,'Nov'!AK39,'Dec'!AK39)) | H15: =IF($B15="","",CHOOSE(MonthIdx,'Jan'!AL39,'Feb'!AL39,'Mar'!AL39,'Apr'!AL39,'May'!AL39,'Jun'!AL39,'Jul'!AL39,'Aug'!AL39,'Sep'!AL39,'Oct'!AL39,'Nov'!AL39,'Dec'!AL39)) | I15: =IF($B15="","",CHOOSE(MonthIdx,'Jan'!AM39,'Feb'!AM39,'Mar'!AM39,'Apr'!AM39,'May'!AM39,'Jun'!AM39,'Jul'!AM39,'Aug'!AM39,'Sep'!AM39,'Oct'!AM39,'Nov'!AM39,'Dec'!AM39)) | K15: =IF(Activities!$A$9="","",Activities!$A$9) | L15: =IF(Activities!$A$9="","",Activities!$B$9&"") | N15: =IF(Activities!$A$9="","",Activities!$D$9)
A16: =IF(Roster!$B$10="","",Roster!$B$10) | B16: =IF(Roster!$C$10="","",Roster!$C$10) | C16: =IF(Roster!$C$10="","",Roster!$F$10&"") | D16: =IF(Roster!$C$10="","",Roster!$G$10&"") | E16: =IF($B16="","",CHOOSE(MonthIdx,'Jan'!AI43,'Feb'!AI43,'Mar'!AI43,'Apr'!AI43,'May'!AI43,'Jun'!AI43,'Jul'!AI43,'Aug'!AI43,'Sep'!AI43,'Oct'!AI43,'Nov'!AI43,'Dec'!AI43)) | F16: =IF($B16="","",CHOOSE(MonthIdx,'Jan'!AJ43,'Feb'!AJ43,'Mar'!AJ43,'Apr'!AJ43,'May'!AJ43,'Jun'!AJ43,'Jul'!AJ43,'Aug'!AJ43,'Sep'!AJ43,'Oct'!AJ43,'Nov'!AJ43,'Dec'!AJ43)) | G16: =IF($B16="","",CHOOSE(MonthIdx,'Jan'!AK43,'Feb'!AK43,'Mar'!AK43,'Apr'!AK43,'May'!AK43,'Jun'!AK43,'Jul'!AK43,'Aug'!AK43,'Sep'!AK43,'Oct'!AK43,'Nov'!AK43,'Dec'!AK43)) | H16: =IF($B16="","",CHOOSE(MonthIdx,'Jan'!AL43,'Feb'!AL43,'Mar'!AL43,'Apr'!AL43,'May'!AL43,'Jun'!AL43,'Jul'!AL43,'Aug'!AL43,'Sep'!AL43,'Oct'!AL43,'Nov'!AL43,'Dec'!AL43)) | I16: =IF($B16="","",CHOOSE(MonthIdx,'Jan'!AM43,'Feb'!AM43,'Mar'!AM43,'Apr'!AM43,'May'!AM43,'Jun'!AM43,'Jul'!AM43,'Aug'!AM43,'Sep'!AM43,'Oct'!AM43,'Nov'!AM43,'Dec'!AM43)) | K16: =IF(Activities!$A$10="","",Activities!$A$10) | L16: =IF(Activities!$A$10="","",Activities!$B$10&"") | N16: =IF(Activities!$A$10="","",Activities!$D$10)
A17: =IF(Roster!$B$11="","",Roster!$B$11) | B17: =IF(Roster!$C$11="","",Roster!$C$11) | C17: =IF(Roster!$C$11="","",Roster!$F$11&"") | D17: =IF(Roster!$C$11="","",Roster!$G$11&"") | E17: =IF($B17="","",CHOOSE(MonthIdx,'Jan'!AI47,'Feb'!AI47,'Mar'!AI47,'Apr'!AI47,'May'!AI47,'Jun'!AI47,'Jul'!AI47,'Aug'!AI47,'Sep'!AI47,'Oct'!AI47,'Nov'!AI47,'Dec'!AI47)) | F17: =IF($B17="","",CHOOSE(MonthIdx,'Jan'!AJ47,'Feb'!AJ47,'Mar'!AJ47,'Apr'!AJ47,'May'!AJ47,'Jun'!AJ47,'Jul'!AJ47,'Aug'!AJ47,'Sep'!AJ47,'Oct'!AJ47,'Nov'!AJ47,'Dec'!AJ47)) | G17: =IF($B17="","",CHOOSE(MonthIdx,'Jan'!AK47,'Feb'!AK47,'Mar'!AK47,'Apr'!AK47,'May'!AK47,'Jun'!AK47,'Jul'!AK47,'Aug'!AK47,'Sep'!AK47,'Oct'!AK47,'Nov'!AK47,'Dec'!AK47)) | H17: =IF($B17="","",CHOOSE(MonthIdx,'Jan'!AL47,'Feb'!AL47,'Mar'!AL47,'Apr'!AL47,'May'!AL47,'Jun'!AL47,'Jul'!AL47,'Aug'!AL47,'Sep'!AL47,'Oct'!AL47,'Nov'!AL47,'Dec'!AL47)) | I17: =IF($B17="","",CHOOSE(MonthIdx,'Jan'!AM47,'Feb'!AM47,'Mar'!AM47,'Apr'!AM47,'May'!AM47,'Jun'!AM47,'Jul'!AM47,'Aug'!AM47,'Sep'!AM47,'Oct'!AM47,'Nov'!AM47,'Dec'!AM47)) | K17: =IF(Activities!$A$11="","",Activities!$A$11) | L17: =IF(Activities!$A$11="","",Activities!$B$11&"") | N17: =IF(Activities!$A$11="","",Activities!$D$11)
A18: =IF(Roster!$B$12="","",Roster!$B$12) | B18: =IF(Roster!$C$12="","",Roster!$C$12) | C18: =IF(Roster!$C$12="","",Roster!$F$12&"") | D18: =IF(Roster!$C$12="","",Roster!$G$12&"") | E18: =IF($B18="","",CHOOSE(MonthIdx,'Jan'!AI51,'Feb'!AI51,'Mar'!AI51,'Apr'!AI51,'May'!AI51,'Jun'!AI51,'Jul'!AI51,'Aug'!AI51,'Sep'!AI51,'Oct'!AI51,'Nov'!AI51,'Dec'!AI51)) | F18: =IF($B18="","",CHOOSE(MonthIdx,'Jan'!AJ51,'Feb'!AJ51,'Mar'!AJ51,'Apr'!AJ51,'May'!AJ51,'Jun'!AJ51,'Jul'!AJ51,'Aug'!AJ51,'Sep'!AJ51,'Oct'!AJ51,'Nov'!AJ51,'Dec'!AJ51)) | G18: =IF($B18="","",CHOOSE(MonthIdx,'Jan'!AK51,'Feb'!AK51,'Mar'!AK51,'Apr'!AK51,'May'!AK51,'Jun'!AK51,'Jul'!AK51,'Aug'!AK51,'Sep'!AK51,'Oct'!AK51,'Nov'!AK51,'Dec'!AK51)) | H18: =IF($B18="","",CHOOSE(MonthIdx,'Jan'!AL51,'Feb'!AL51,'Mar'!AL51,'Apr'!AL51,'May'!AL51,'Jun'!AL51,'Jul'!AL51,'Aug'!AL51,'Sep'!AL51,'Oct'!AL51,'Nov'!AL51,'Dec'!AL51)) | I18: =IF($B18="","",CHOOSE(MonthIdx,'Jan'!AM51,'Feb'!AM51,'Mar'!AM51,'Apr'!AM51,'May'!AM51,'Jun'!AM51,'Jul'!AM51,'Aug'!AM51,'Sep'!AM51,'Oct'!AM51,'Nov'!AM51,'Dec'!AM51)) | K18: =IF(Activities!$A$12="","",Activities!$A$12) | L18: =IF(Activities!$A$12="","",Activities!$B$12&"") | N18: =IF(Activities!$A$12="","",Activities!$D$12)
A19: =IF(Roster!$B$13="","",Roster!$B$13) | B19: =IF(Roster!$C$13="","",Roster!$C$13) | C19: =IF(Roster!$C$13="","",Roster!$F$13&"") | D19: =IF(Roster!$C$13="","",Roster!$G$13&"") | E19: =IF($B19="","",CHOOSE(MonthIdx,'Jan'!AI55,'Feb'!AI55,'Mar'!AI55,'Apr'!AI55,'May'!AI55,'Jun'!AI55,'Jul'!AI55,'Aug'!AI55,'Sep'!AI55,'Oct'!AI55,'Nov'!AI55,'Dec'!AI55)) | F19: =IF($B19="","",CHOOSE(MonthIdx,'Jan'!AJ55,'Feb'!AJ55,'Mar'!AJ55,'Apr'!AJ55,'May'!AJ55,'Jun'!AJ55,'Jul'!AJ55,'Aug'!AJ55,'Sep'!AJ55,'Oct'!AJ55,'Nov'!AJ55,'Dec'!AJ55)) | G19: =IF($B19="","",CHOOSE(MonthIdx,'Jan'!AK55,'Feb'!AK55,'Mar'!AK55,'Apr'!AK55,'May'!AK55,'Jun'!AK55,'Jul'!AK55,'Aug'!AK55,'Sep'!AK55,'Oct'!AK55,'Nov'!AK55,'Dec'!AK55)) | H19: =IF($B19="","",CHOOSE(MonthIdx,'Jan'!AL55,'Feb'!AL55,'Mar'!AL55,'Apr'!AL55,'May'!AL55,'Jun'!AL55,'Jul'!AL55,'Aug'!AL55,'Sep'!AL55,'Oct'!AL55,'Nov'!AL55,'Dec'!AL55)) | I19: =IF($B19="","",CHOOSE(MonthIdx,'Jan'!AM55,'Feb'!AM55,'Mar'!AM55,'Apr'!AM55,'May'!AM55,'Jun'!AM55,'Jul'!AM55,'Aug'!AM55,'Sep'!AM55,'Oct'!AM55,'Nov'!AM55,'Dec'!AM55)) | K19: =IF(Activities!$A$13="","",Activities!$A$13) | L19: =IF(Activities!$A$13="","",Activities!$B$13&"") | N19: =IF(Activities!$A$13="","",Activities!$D$13)
A20: =IF(Roster!$B$14="","",Roster!$B$14) | B20: =IF(Roster!$C$14="","",Roster!$C$14) | C20: =IF(Roster!$C$14="","",Roster!$F$14&"") | D20: =IF(Roster!$C$14="","",Roster!$G$14&"") | E20: =IF($B20="","",CHOOSE(MonthIdx,'Jan'!AI59,'Feb'!AI59,'Mar'!AI59,'Apr'!AI59,'May'!AI59,'Jun'!AI59,'Jul'!AI59,'Aug'!AI59,'Sep'!AI59,'Oct'!AI59,'Nov'!AI59,'Dec'!AI59)) | F20: =IF($B20="","",CHOOSE(MonthIdx,'Jan'!AJ59,'Feb'!AJ59,'Mar'!AJ59,'Apr'!AJ59,'May'!AJ59,'Jun'!AJ59,'Jul'!AJ59,'Aug'!AJ59,'Sep'!AJ59,'Oct'!AJ59,'Nov'!AJ59,'Dec'!AJ59)) | G20: =IF($B20="","",CHOOSE(MonthIdx,'Jan'!AK59,'Feb'!AK59,'Mar'!AK59,'Apr'!AK59,'May'!AK59,'Jun'!AK59,'Jul'!AK59,'Aug'!AK59,'Sep'!AK59,'Oct'!AK59,'Nov'!AK59,'Dec'!AK59)) | H20: =IF($B20="","",CHOOSE(MonthIdx,'Jan'!AL59,'Feb'!AL59,'Mar'!AL59,'Apr'!AL59,'May'!AL59,'Jun'!AL59,'Jul'!AL59,'Aug'!AL59,'Sep'!AL59,'Oct'!AL59,'Nov'!AL59,'Dec'!AL59)) | I20: =IF($B20="","",CHOOSE(MonthIdx,'Jan'!AM59,'Feb'!AM59,'Mar'!AM59,'Apr'!AM59,'May'!AM59,'Jun'!AM59,'Jul'!AM59,'Aug'!AM59,'Sep'!AM59,'Oct'!AM59,'Nov'!AM59,'Dec'!AM59)) | K20: =IF(Activities!$A$14="","",Activities!$A$14) | L20: =IF(Activities!$A$14="","",Activities!$B$14&"") | N20: =IF(Activities!$A$14="","",Activities!$D$14)
A21: =IF(Roster!$B$15="","",Roster!$B$15) | B21: =IF(Roster!$C$15="","",Roster!$C$15) | C21: =IF(Roster!$C$15="","",Roster!$F$15&"") | D21: =IF(Roster!$C$15="","",Roster!$G$15&"") | E21: =IF($B21="","",CHOOSE(MonthIdx,'Jan'!AI63,'Feb'!AI63,'Mar'!AI63,'Apr'!AI63,'May'!AI63,'Jun'!AI63,'Jul'!AI63,'Aug'!AI63,'Sep'!AI63,'Oct'!AI63,'Nov'!AI63,'Dec'!AI63)) | F21: =IF($B21="","",CHOOSE(MonthIdx,'Jan'!AJ63,'Feb'!AJ63,'Mar'!AJ63,'Apr'!AJ63,'May'!AJ63,'Jun'!AJ63,'Jul'!AJ63,'Aug'!AJ63,'Sep'!AJ63,'Oct'!AJ63,'Nov'!AJ63,'Dec'!AJ63)) | G21: =IF($B21="","",CHOOSE(MonthIdx,'Jan'!AK63,'Feb'!AK63,'Mar'!AK63,'Apr'!AK63,'May'!AK63,'Jun'!AK63,'Jul'!AK63,'Aug'!AK63,'Sep'!AK63,'Oct'!AK63,'Nov'!AK63,'Dec'!AK63)) | H21: =IF($B21="","",CHOOSE(MonthIdx,'Jan'!AL63,'Feb'!AL63,'Mar'!AL63,'Apr'!AL63,'May'!AL63,'Jun'!AL63,'Jul'!AL63,'Aug'!AL63,'Sep'!AL63,'Oct'!AL63,'Nov'!AL63,'Dec'!AL63)) | I21: =IF($B21="","",CHOOSE(MonthIdx,'Jan'!AM63,'Feb'!AM63,'Mar'!AM63,'Apr'!AM63,'May'!AM63,'Jun'!AM63,'Jul'!AM63,'Aug'!AM63,'Sep'!AM63,'Oct'!AM63,'Nov'!AM63,'Dec'!AM63)) | K21: =IF(Activities!$A$15="","",Activities!$A$15) | L21: =IF(Activities!$A$15="","",Activities!$B$15&"") | N21: =IF(Activities!$A$15="","",Activities!$D$15)
A22: =IF(Roster!$B$16="","",Roster!$B$16) | B22: =IF(Roster!$C$16="","",Roster!$C$16) | C22: =IF(Roster!$C$16="","",Roster!$F$16&"") | D22: =IF(Roster!$C$16="","",Roster!$G$16&"") | E22: =IF($B22="","",CHOOSE(MonthIdx,'Jan'!AI67,'Feb'!AI67,'Mar'!AI67,'Apr'!AI67,'May'!AI67,'Jun'!AI67,'Jul'!AI67,'Aug'!AI67,'Sep'!AI67,'Oct'!AI67,'Nov'!AI67,'Dec'!AI67)) | F22: =IF($B22="","",CHOOSE(MonthIdx,'Jan'!AJ67,'Feb'!AJ67,'Mar'!AJ67,'Apr'!AJ67,'May'!AJ67,'Jun'!AJ67,'Jul'!AJ67,'Aug'!AJ67,'Sep'!AJ67,'Oct'!AJ67,'Nov'!AJ67,'Dec'!AJ67)) | G22: =IF($B22="","",CHOOSE(MonthIdx,'Jan'!AK67,'Feb'!AK67,'Mar'!AK67,'Apr'!AK67,'May'!AK67,'Jun'!AK67,'Jul'!AK67,'Aug'!AK67,'Sep'!AK67,'Oct'!AK67,'Nov'!AK67,'Dec'!AK67)) | H22: =IF($B22="","",CHOOSE(MonthIdx,'Jan'!AL67,'Feb'!AL67,'Mar'!AL67,'Apr'!AL67,'May'!AL67,'Jun'!AL67,'Jul'!AL67,'Aug'!AL67,'Sep'!AL67,'Oct'!AL67,'Nov'!AL67,'Dec'!AL67)) | I22: =IF($B22="","",CHOOSE(MonthIdx,'Jan'!AM67,'Feb'!AM67,'Mar'!AM67,'Apr'!AM67,'May'!AM67,'Jun'!AM67,'Jul'!AM67,'Aug'!AM67,'Sep'!AM67,'Oct'!AM67,'Nov'!AM67,'Dec'!AM67)) | K22: =IF(Activities!$A$16="","",Activities!$A$16) | L22: =IF(Activities!$A$16="","",Activities!$B$16&"") | N22: =IF(Activities!$A$16="","",Activities!$D$16)
A23: =IF(Roster!$B$17="","",Roster!$B$17) | B23: =IF(Roster!$C$17="","",Roster!$C$17) | C23: =IF(Roster!$C$17="","",Roster!$F$17&"") | D23: =IF(Roster!$C$17="","",Roster!$G$17&"") | E23: =IF($B23="","",CHOOSE(MonthIdx,'Jan'!AI71,'Feb'!AI71,'Mar'!AI71,'Apr'!AI71,'May'!AI71,'Jun'!AI71,'Jul'!AI71,'Aug'!AI71,'Sep'!AI71,'Oct'!AI71,'Nov'!AI71,'Dec'!AI71)) | F23: =IF($B23="","",CHOOSE(MonthIdx,'Jan'!AJ71,'Feb'!AJ71,'Mar'!AJ71,'Apr'!AJ71,'May'!AJ71,'Jun'!AJ71,'Jul'!AJ71,'Aug'!AJ71,'Sep'!AJ71,'Oct'!AJ71,'Nov'!AJ71,'Dec'!AJ71)) | G23: =IF($B23="","",CHOOSE(MonthIdx,'Jan'!AK71,'Feb'!AK71,'Mar'!AK71,'Apr'!AK71,'May'!AK71,'Jun'!AK71,'Jul'!AK71,'Aug'!AK71,'Sep'!AK71,'Oct'!AK71,'Nov'!AK71,'Dec'!AK71)) | H23: =IF($B23="","",CHOOSE(MonthIdx,'Jan'!AL71,'Feb'!AL71,'Mar'!AL71,'Apr'!AL71,'May'!AL71,'Jun'!AL71,'Jul'!AL71,'Aug'!AL71,'Sep'!AL71,'Oct'!AL71,'Nov'!AL71,'Dec'!AL71)) | I23: =IF($B23="","",CHOOSE(MonthIdx,'Jan'!AM71,'Feb'!AM71,'Mar'!AM71,'Apr'!AM71,'May'!AM71,'Jun'!AM71,'Jul'!AM71,'Aug'!AM71,'Sep'!AM71,'Oct'!AM71,'Nov'!AM71,'Dec'!AM71)) | K23: =IF(Activities!$A$17="","",Activities!$A$17) | L23: =IF(Activities!$A$17="","",Activities!$B$17&"") | N23: =IF(Activities!$A$17="","",Activities!$D$17)
A24: =IF(Roster!$B$18="","",Roster!$B$18) | B24: =IF(Roster!$C$18="","",Roster!$C$18) | C24: =IF(Roster!$C$18="","",Roster!$F$18&"") | D24: =IF(Roster!$C$18="","",Roster!$G$18&"") | E24: =IF($B24="","",CHOOSE(MonthIdx,'Jan'!AI75,'Feb'!AI75,'Mar'!AI75,'Apr'!AI75,'May'!AI75,'Jun'!AI75,'Jul'!AI75,'Aug'!AI75,'Sep'!AI75,'Oct'!AI75,'Nov'!AI75,'Dec'!AI75)) | F24: =IF($B24="","",CHOOSE(MonthIdx,'Jan'!AJ75,'Feb'!AJ75,'Mar'!AJ75,'Apr'!AJ75,'May'!AJ75,'Jun'!AJ75,'Jul'!AJ75,'Aug'!AJ75,'Sep'!AJ75,'Oct'!AJ75,'Nov'!AJ75,'Dec'!AJ75)) | G24: =IF($B24="","",CHOOSE(MonthIdx,'Jan'!AK75,'Feb'!AK75,'Mar'!AK75,'Apr'!AK75,'May'!AK75,'Jun'!AK75,'Jul'!AK75,'Aug'!AK75,'Sep'!AK75,'Oct'!AK75,'Nov'!AK75,'Dec'!AK75)) | H24: =IF($B24="","",CHOOSE(MonthIdx,'Jan'!AL75,'Feb'!AL75,'Mar'!AL75,'Apr'!AL75,'May'!AL75,'Jun'!AL75,'Jul'!AL75,'Aug'!AL75,'Sep'!AL75,'Oct'!AL75,'Nov'!AL75,'Dec'!AL75)) | I24: =IF($B24="","",CHOOSE(MonthIdx,'Jan'!AM75,'Feb'!AM75,'Mar'!AM75,'Apr'!AM75,'May'!AM75,'Jun'!AM75,'Jul'!AM75,'Aug'!AM75,'Sep'!AM75,'Oct'!AM75,'Nov'!AM75,'Dec'!AM75)) | K24: =IF(Activities!$A$18="","",Activities!$A$18) | L24: =IF(Activities!$A$18="","",Activities!$B$18&"") | N24: =IF(Activities!$A$18="","",Activities!$D$18)
A25: =IF(Roster!$B$19="","",Roster!$B$19) | B25: =IF(Roster!$C$19="","",Roster!$C$19) | C25: =IF(Roster!$C$19="","",Roster!$F$19&"") | D25: =IF(Roster!$C$19="","",Roster!$G$19&"") | E25: =IF($B25="","",CHOOSE(MonthIdx,'Jan'!AI79,'Feb'!AI79,'Mar'!AI79,'Apr'!AI79,'May'!AI79,'Jun'!AI79,'Jul'!AI79,'Aug'!AI79,'Sep'!AI79,'Oct'!AI79,'Nov'!AI79,'Dec'!AI79)) | F25: =IF($B25="","",CHOOSE(MonthIdx,'Jan'!AJ79,'Feb'!AJ79,'Mar'!AJ79,'Apr'!AJ79,'May'!AJ79,'Jun'!AJ79,'Jul'!AJ79,'Aug'!AJ79,'Sep'!AJ79,'Oct'!AJ79,'Nov'!AJ79,'Dec'!AJ79)) | G25: =IF($B25="","",CHOOSE(MonthIdx,'Jan'!AK79,'Feb'!AK79,'Mar'!AK79,'Apr'!AK79,'May'!AK79,'Jun'!AK79,'Jul'!AK79,'Aug'!AK79,'Sep'!AK79,'Oct'!AK79,'Nov'!AK79,'Dec'!AK79)) | H25: =IF($B25="","",CHOOSE(MonthIdx,'Jan'!AL79,'Feb'!AL79,'Mar'!AL79,'Apr'!AL79,'May'!AL79,'Jun'!AL79,'Jul'!AL79,'Aug'!AL79,'Sep'!AL79,'Oct'!AL79,'Nov'!AL79,'Dec'!AL79)) | I25: =IF($B25="","",CHOOSE(MonthIdx,'Jan'!AM79,'Feb'!AM79,'Mar'!AM79,'Apr'!AM79,'May'!AM79,'Jun'!AM79,'Jul'!AM79,'Aug'!AM79,'Sep'!AM79,'Oct'!AM79,'Nov'!AM79,'Dec'!AM79)) | K25: =IF(Activities!$A$19="","",Activities!$A$19) | L25: =IF(Activities!$A$19="","",Activities!$B$19&"") | N25: =IF(Activities!$A$19="","",Activities!$D$19)
A26: =IF(Roster!$B$20="","",Roster!$B$20) | B26: =IF(Roster!$C$20="","",Roster!$C$20) | C26: =IF(Roster!$C$20="","",Roster!$F$20&"") | D26: =IF(Roster!$C$20="","",Roster!$G$20&"") | E26: =IF($B26="","",CHOOSE(MonthIdx,'Jan'!AI83,'Feb'!AI83,'Mar'!AI83,'Apr'!AI83,'May'!AI83,'Jun'!AI83,'Jul'!AI83,'Aug'!AI83,'Sep'!AI83,'Oct'!AI83,'Nov'!AI83,'Dec'!AI83)) | F26: =IF($B26="","",CHOOSE(MonthIdx,'Jan'!AJ83,'Feb'!AJ83,'Mar'!AJ83,'Apr'!AJ83,'May'!AJ83,'Jun'!AJ83,'Jul'!AJ83,'Aug'!AJ83,'Sep'!AJ83,'Oct'!AJ83,'Nov'!AJ83,'Dec'!AJ83)) | G26: =IF($B26="","",CHOOSE(MonthIdx,'Jan'!AK83,'Feb'!AK83,'Mar'!AK83,'Apr'!AK83,'May'!AK83,'Jun'!AK83,'Jul'!AK83,'Aug'!AK83,'Sep'!AK83,'Oct'!AK83,'Nov'!AK83,'Dec'!AK83)) | H26: =IF($B26="","",CHOOSE(MonthIdx,'Jan'!AL83,'Feb'!AL83,'Mar'!AL83,'Apr'!AL83,'May'!AL83,'Jun'!AL83,'Jul'!AL83,'Aug'!AL83,'Sep'!AL83,'Oct'!AL83,'Nov'!AL83,'Dec'!AL83)) | I26: =IF($B26="","",CHOOSE(MonthIdx,'Jan'!AM83,'Feb'!AM83,'Mar'!AM83,'Apr'!AM83,'May'!AM83,'Jun'!AM83,'Jul'!AM83,'Aug'!AM83,'Sep'!AM83,'Oct'!AM83,'Nov'!AM83,'Dec'!AM83)) | K26: =IF(Activities!$A$20="","",Activities!$A$20) | L26: =IF(Activities!$A$20="","",Activities!$B$20&"") | N26: =IF(Activities!$A$20="","",Activities!$D$20)
A27: =IF(Roster!$B$21="","",Roster!$B$21) | B27: =IF(Roster!$C$21="","",Roster!$C$21) | C27: =IF(Roster!$C$21="","",Roster!$F$21&"") | D27: =IF(Roster!$C$21="","",Roster!$G$21&"") | E27: =IF($B27="","",CHOOSE(MonthIdx,'Jan'!AI87,'Feb'!AI87,'Mar'!AI87,'Apr'!AI87,'May'!AI87,'Jun'!AI87,'Jul'!AI87,'Aug'!AI87,'Sep'!AI87,'Oct'!AI87,'Nov'!AI87,'Dec'!AI87)) | F27: =IF($B27="","",CHOOSE(MonthIdx,'Jan'!AJ87,'Feb'!AJ87,'Mar'!AJ87,'Apr'!AJ87,'May'!AJ87,'Jun'!AJ87,'Jul'!AJ87,'Aug'!AJ87,'Sep'!AJ87,'Oct'!AJ87,'Nov'!AJ87,'Dec'!AJ87)) | G27: =IF($B27="","",CHOOSE(MonthIdx,'Jan'!AK87,'Feb'!AK87,'Mar'!AK87,'Apr'!AK87,'May'!AK87,'Jun'!AK87,'Jul'!AK87,'Aug'!AK87,'Sep'!AK87,'Oct'!AK87,'Nov'!AK87,'Dec'!AK87)) | H27: =IF($B27="","",CHOOSE(MonthIdx,'Jan'!AL87,'Feb'!AL87,'Mar'!AL87,'Apr'!AL87,'May'!AL87,'Jun'!AL87,'Jul'!AL87,'Aug'!AL87,'Sep'!AL87,'Oct'!AL87,'Nov'!AL87,'Dec'!AL87)) | I27: =IF($B27="","",CHOOSE(MonthIdx,'Jan'!AM87,'Feb'!AM87,'Mar'!AM87,'Apr'!AM87,'May'!AM87,'Jun'!AM87,'Jul'!AM87,'Aug'!AM87,'Sep'!AM87,'Oct'!AM87,'Nov'!AM87,'Dec'!AM87)) | K27: =IF(Activities!$A$21="","",Activities!$A$21) | L27: =IF(Activities!$A$21="","",Activities!$B$21&"") | N27: =IF(Activities!$A$21="","",Activities!$D$21)
A28: =IF(Roster!$B$22="","",Roster!$B$22) | B28: =IF(Roster!$C$22="","",Roster!$C$22) | C28: =IF(Roster!$C$22="","",Roster!$F$22&"") | D28: =IF(Roster!$C$22="","",Roster!$G$22&"") | E28: =IF($B28="","",CHOOSE(MonthIdx,'Jan'!AI91,'Feb'!AI91,'Mar'!AI91,'Apr'!AI91,'May'!AI91,'Jun'!AI91,'Jul'!AI91,'Aug'!AI91,'Sep'!AI91,'Oct'!AI91,'Nov'!AI91,'Dec'!AI91)) | F28: =IF($B28="","",CHOOSE(MonthIdx,'Jan'!AJ91,'Feb'!AJ91,'Mar'!AJ91,'Apr'!AJ91,'May'!AJ91,'Jun'!AJ91,'Jul'!AJ91,'Aug'!AJ91,'Sep'!AJ91,'Oct'!AJ91,'Nov'!AJ91,'Dec'!AJ91)) | G28: =IF($B28="","",CHOOSE(MonthIdx,'Jan'!AK91,'Feb'!AK91,'Mar'!AK91,'Apr'!AK91,'May'!AK91,'Jun'!AK91,'Jul'!AK91,'Aug'!AK91,'Sep'!AK91,'Oct'!AK91,'Nov'!AK91,'Dec'!AK91)) | H28: =IF($B28="","",CHOOSE(MonthIdx,'Jan'!AL91,'Feb'!AL91,'Mar'!AL91,'Apr'!AL91,'May'!AL91,'Jun'!AL91,'Jul'!AL91,'Aug'!AL91,'Sep'!AL91,'Oct'!AL91,'Nov'!AL91,'Dec'!AL91)) | I28: =IF($B28="","",CHOOSE(MonthIdx,'Jan'!AM91,'Feb'!AM91,'Mar'!AM91,'Apr'!AM91,'May'!AM91,'Jun'!AM91,'Jul'!AM91,'Aug'!AM91,'Sep'!AM91,'Oct'!AM91,'Nov'!AM91,'Dec'!AM91)) | K28: =IF(Activities!$A$22="","",Activities!$A$22) | L28: =IF(Activities!$A$22="","",Activities!$B$22&"") | N28: =IF(Activities!$A$22="","",Activities!$D$22)
A29: =IF(Roster!$B$23="","",Roster!$B$23) | B29: =IF(Roster!$C$23="","",Roster!$C$23) | C29: =IF(Roster!$C$23="","",Roster!$F$23&"") | D29: =IF(Roster!$C$23="","",Roster!$G$23&"") | E29: =IF($B29="","",CHOOSE(MonthIdx,'Jan'!AI95,'Feb'!AI95,'Mar'!AI95,'Apr'!AI95,'May'!AI95,'Jun'!AI95,'Jul'!AI95,'Aug'!AI95,'Sep'!AI95,'Oct'!AI95,'Nov'!AI95,'Dec'!AI95)) | F29: =IF($B29="","",CHOOSE(MonthIdx,'Jan'!AJ95,'Feb'!AJ95,'Mar'!AJ95,'Apr'!AJ95,'May'!AJ95,'Jun'!AJ95,'Jul'!AJ95,'Aug'!AJ95,'Sep'!AJ95,'Oct'!AJ95,'Nov'!AJ95,'Dec'!AJ95)) | G29: =IF($B29="","",CHOOSE(MonthIdx,'Jan'!AK95,'Feb'!AK95,'Mar'!AK95,'Apr'!AK95,'May'!AK95,'Jun'!AK95,'Jul'!AK95,'Aug'!AK95,'Sep'!AK95,'Oct'!AK95,'Nov'!AK95,'Dec'!AK95)) | H29: =IF($B29="","",CHOOSE(MonthIdx,'Jan'!AL95,'Feb'!AL95,'Mar'!AL95,'Apr'!AL95,'May'!AL95,'Jun'!AL95,'Jul'!AL95,'Aug'!AL95,'Sep'!AL95,'Oct'!AL95,'Nov'!AL95,'Dec'!AL95)) | I29: =IF($B29="","",CHOOSE(MonthIdx,'Jan'!AM95,'Feb'!AM95,'Mar'!AM95,'Apr'!AM95,'May'!AM95,'Jun'!AM95,'Jul'!AM95,'Aug'!AM95,'Sep'!AM95,'Oct'!AM95,'Nov'!AM95,'Dec'!AM95)) | K29: =IF(Activities!$A$23="","",Activities!$A$23) | L29: =IF(Activities!$A$23="","",Activities!$B$23&"") | N29: =IF(Activities!$A$23="","",Activities!$D$23)
A30: =IF(Roster!$B$24="","",Roster!$B$24) | B30: =IF(Roster!$C$24="","",Roster!$C$24) | C30: =IF(Roster!$C$24="","",Roster!$F$24&"") | D30: =IF(Roster!$C$24="","",Roster!$G$24&"") | E30: =IF($B30="","",CHOOSE(MonthIdx,'Jan'!AI99,'Feb'!AI99,'Mar'!AI99,'Apr'!AI99,'May'!AI99,'Jun'!AI99,'Jul'!AI99,'Aug'!AI99,'Sep'!AI99,'Oct'!AI99,'Nov'!AI99,'Dec'!AI99)) | F30: =IF($B30="","",CHOOSE(MonthIdx,'Jan'!AJ99,'Feb'!AJ99,'Mar'!AJ99,'Apr'!AJ99,'May'!AJ99,'Jun'!AJ99,'Jul'!AJ99,'Aug'!AJ99,'Sep'!AJ99,'Oct'!AJ99,'Nov'!AJ99,'Dec'!AJ99)) | G30: =IF($B30="","",CHOOSE(MonthIdx,'Jan'!AK99,'Feb'!AK99,'Mar'!AK99,'Apr'!AK99,'May'!AK99,'Jun'!AK99,'Jul'!AK99,'Aug'!AK99,'Sep'!AK99,'Oct'!AK99,'Nov'!AK99,'Dec'!AK99)) | H30: =IF($B30="","",CHOOSE(MonthIdx,'Jan'!AL99,'Feb'!AL99,'Mar'!AL99,'Apr'!AL99,'May'!AL99,'Jun'!AL99,'Jul'!AL99,'Aug'!AL99,'Sep'!AL99,'Oct'!AL99,'Nov'!AL99,'Dec'!AL99)) | I30: =IF($B30="","",CHOOSE(MonthIdx,'Jan'!AM99,'Feb'!AM99,'Mar'!AM99,'Apr'!AM99,'May'!AM99,'Jun'!AM99,'Jul'!AM99,'Aug'!AM99,'Sep'!AM99,'Oct'!AM99,'Nov'!AM99,'Dec'!AM99)) | K30: =IF(Activities!$A$24="","",Activities!$A$24) | L30: =IF(Activities!$A$24="","",Activities!$B$24&"") | N30: =IF(Activities!$A$24="","",Activities!$D$24)
A31: =IF(Roster!$B$25="","",Roster!$B$25) | B31: =IF(Roster!$C$25="","",Roster!$C$25) | C31: =IF(Roster!$C$25="","",Roster!$F$25&"") | D31: =IF(Roster!$C$25="","",Roster!$G$25&"") | E31: =IF($B31="","",CHOOSE(MonthIdx,'Jan'!AI103,'Feb'!AI103,'Mar'!AI103,'Apr'!AI103,'May'!AI103,'Jun'!AI103,'Jul'!AI103,'Aug'!AI103,'Sep'!AI103,'Oct'!AI103,'Nov'!AI103,'Dec'!AI103)) | F31: =IF($B31="","",CHOOSE(MonthIdx,'Jan'!AJ103,'Feb'!AJ103,'Mar'!AJ103,'Apr'!AJ103,'May'!AJ103,'Jun'!AJ103,'Jul'!AJ103,'Aug'!AJ103,'Sep'!AJ103,'Oct'!AJ103,'Nov'!AJ103,'Dec'!AJ103)) | G31: =IF($B31="","",CHOOSE(MonthIdx,'Jan'!AK103,'Feb'!AK103,'Mar'!AK103,'Apr'!AK103,'May'!AK103,'Jun'!AK103,'Jul'!AK103,'Aug'!AK103,'Sep'!AK103,'Oct'!AK103,'Nov'!AK103,'Dec'!AK103)) | H31: =IF($B31="","",CHOOSE(MonthIdx,'Jan'!AL103,'Feb'!AL103,'Mar'!AL103,'Apr'!AL103,'May'!AL103,'Jun'!AL103,'Jul'!AL103,'Aug'!AL103,'Sep'!AL103,'Oct'!AL103,'Nov'!AL103,'Dec'!AL103)) | I31: =IF($B31="","",CHOOSE(MonthIdx,'Jan'!AM103,'Feb'!AM103,'Mar'!AM103,'Apr'!AM103,'May'!AM103,'Jun'!AM103,'Jul'!AM103,'Aug'!AM103,'Sep'!AM103,'Oct'!AM103,'Nov'!AM103,'Dec'!AM103)) | K31: =IF(Activities!$A$25="","",Activities!$A$25) | L31: =IF(Activities!$A$25="","",Activities!$B$25&"") | N31: =IF(Activities!$A$25="","",Activities!$D$25)
A32: =IF(Roster!$B$26="","",Roster!$B$26) | B32: =IF(Roster!$C$26="","",Roster!$C$26) | C32: =IF(Roster!$C$26="","",Roster!$F$26&"") | D32: =IF(Roster!$C$26="","",Roster!$G$26&"") | E32: =IF($B32="","",CHOOSE(MonthIdx,'Jan'!AI107,'Feb'!AI107,'Mar'!AI107,'Apr'!AI107,'May'!AI107,'Jun'!AI107,'Jul'!AI107,'Aug'!AI107,'Sep'!AI107,'Oct'!AI107,'Nov'!AI107,'Dec'!AI107)) | F32: =IF($B32="","",CHOOSE(MonthIdx,'Jan'!AJ107,'Feb'!AJ107,'Mar'!AJ107,'Apr'!AJ107,'May'!AJ107,'Jun'!AJ107,'Jul'!AJ107,'Aug'!AJ107,'Sep'!AJ107,'Oct'!AJ107,'Nov'!AJ107,'Dec'!AJ107)) | G32: =IF($B32="","",CHOOSE(MonthIdx,'Jan'!AK107,'Feb'!AK107,'Mar'!AK107,'Apr'!AK107,'May'!AK107,'Jun'!AK107,'Jul'!AK107,'Aug'!AK107,'Sep'!AK107,'Oct'!AK107,'Nov'!AK107,'Dec'!AK107)) | H32: =IF($B32="","",CHOOSE(MonthIdx,'Jan'!AL107,'Feb'!AL107,'Mar'!AL107,'Apr'!AL107,'May'!AL107,'Jun'!AL107,'Jul'!AL107,'Aug'!AL107,'Sep'!AL107,'Oct'!AL107,'Nov'!AL107,'Dec'!AL107)) | I32: =IF($B32="","",CHOOSE(MonthIdx,'Jan'!AM107,'Feb'!AM107,'Mar'!AM107,'Apr'!AM107,'May'!AM107,'Jun'!AM107,'Jul'!AM107,'Aug'!AM107,'Sep'!AM107,'Oct'!AM107,'Nov'!AM107,'Dec'!AM107))
A33: =IF(Roster!$B$27="","",Roster!$B$27) | B33: =IF(Roster!$C$27="","",Roster!$C$27) | C33: =IF(Roster!$C$27="","",Roster!$F$27&"") | D33: =IF(Roster!$C$27="","",Roster!$G$27&"") | E33: =IF($B33="","",CHOOSE(MonthIdx,'Jan'!AI111,'Feb'!AI111,'Mar'!AI111,'Apr'!AI111,'May'!AI111,'Jun'!AI111,'Jul'!AI111,'Aug'!AI111,'Sep'!AI111,'Oct'!AI111,'Nov'!AI111,'Dec'!AI111)) | F33: =IF($B33="","",CHOOSE(MonthIdx,'Jan'!AJ111,'Feb'!AJ111,'Mar'!AJ111,'Apr'!AJ111,'May'!AJ111,'Jun'!AJ111,'Jul'!AJ111,'Aug'!AJ111,'Sep'!AJ111,'Oct'!AJ111,'Nov'!AJ111,'Dec'!AJ111)) | G33: =IF($B33="","",CHOOSE(MonthIdx,'Jan'!AK111,'Feb'!AK111,'Mar'!AK111,'Apr'!AK111,'May'!AK111,'Jun'!AK111,'Jul'!AK111,'Aug'!AK111,'Sep'!AK111,'Oct'!AK111,'Nov'!AK111,'Dec'!AK111)) | H33: =IF($B33="","",CHOOSE(MonthIdx,'Jan'!AL111,'Feb'!AL111,'Mar'!AL111,'Apr'!AL111,'May'!AL111,'Jun'!AL111,'Jul'!AL111,'Aug'!AL111,'Sep'!AL111,'Oct'!AL111,'Nov'!AL111,'Dec'!AL111)) | I33: =IF($B33="","",CHOOSE(MonthIdx,'Jan'!AM111,'Feb'!AM111,'Mar'!AM111,'Apr'!AM111,'May'!AM111,'Jun'!AM111,'Jul'!AM111,'Aug'!AM111,'Sep'!AM111,'Oct'!AM111,'Nov'!AM111,'Dec'!AM111))
A34: =IF(Roster!$B$28="","",Roster!$B$28) | B34: =IF(Roster!$C$28="","",Roster!$C$28) | C34: =IF(Roster!$C$28="","",Roster!$F$28&"") | D34: =IF(Roster!$C$28="","",Roster!$G$28&"") | E34: =IF($B34="","",CHOOSE(MonthIdx,'Jan'!AI115,'Feb'!AI115,'Mar'!AI115,'Apr'!AI115,'May'!AI115,'Jun'!AI115,'Jul'!AI115,'Aug'!AI115,'Sep'!AI115,'Oct'!AI115,'Nov'!AI115,'Dec'!AI115)) | F34: =IF($B34="","",CHOOSE(MonthIdx,'Jan'!AJ115,'Feb'!AJ115,'Mar'!AJ115,'Apr'!AJ115,'May'!AJ115,'Jun'!AJ115,'Jul'!AJ115,'Aug'!AJ115,'Sep'!AJ115,'Oct'!AJ115,'Nov'!AJ115,'Dec'!AJ115)) | G34: =IF($B34="","",CHOOSE(MonthIdx,'Jan'!AK115,'Feb'!AK115,'Mar'!AK115,'Apr'!AK115,'May'!AK115,'Jun'!AK115,'Jul'!AK115,'Aug'!AK115,'Sep'!AK115,'Oct'!AK115,'Nov'!AK115,'Dec'!AK115)) | H34: =IF($B34="","",CHOOSE(MonthIdx,'Jan'!AL115,'Feb'!AL115,'Mar'!AL115,'Apr'!AL115,'May'!AL115,'Jun'!AL115,'Jul'!AL115,'Aug'!AL115,'Sep'!AL115,'Oct'!AL115,'Nov'!AL115,'Dec'!AL115)) | I34: =IF($B34="","",CHOOSE(MonthIdx,'Jan'!AM115,'Feb'!AM115,'Mar'!AM115,'Apr'!AM115,'May'!AM115,'Jun'!AM115,'Jul'!AM115,'Aug'!AM115,'Sep'!AM115,'Oct'!AM115,'Nov'!AM115,'Dec'!AM115))
A35: =IF(Roster!$B$29="","",Roster!$B$29) | B35: =IF(Roster!$C$29="","",Roster!$C$29) | C35: =IF(Roster!$C$29="","",Roster!$F$29&"") | D35: =IF(Roster!$C$29="","",Roster!$G$29&"") | E35: =IF($B35="","",CHOOSE(MonthIdx,'Jan'!AI119,'Feb'!AI119,'Mar'!AI119,'Apr'!AI119,'May'!AI119,'Jun'!AI119,'Jul'!AI119,'Aug'!AI119,'Sep'!AI119,'Oct'!AI119,'Nov'!AI119,'Dec'!AI119)) | F35: =IF($B35="","",CHOOSE(MonthIdx,'Jan'!AJ119,'Feb'!AJ119,'Mar'!AJ119,'Apr'!AJ119,'May'!AJ119,'Jun'!AJ119,'Jul'!AJ119,'Aug'!AJ119,'Sep'!AJ119,'Oct'!AJ119,'Nov'!AJ119,'Dec'!AJ119)) | G35: =IF($B35="","",CHOOSE(MonthIdx,'Jan'!AK119,'Feb'!AK119,'Mar'!AK119,'Apr'!AK119,'May'!AK119,'Jun'!AK119,'Jul'!AK119,'Aug'!AK119,'Sep'!AK119,'Oct'!AK119,'Nov'!AK119,'Dec'!AK119)) | H35: =IF($B35="","",CHOOSE(MonthIdx,'Jan'!AL119,'Feb'!AL119,'Mar'!AL119,'Apr'!AL119,'May'!AL119,'Jun'!AL119,'Jul'!AL119,'Aug'!AL119,'Sep'!AL119,'Oct'!AL119,'Nov'!AL119,'Dec'!AL119)) | I35: =IF($B35="","",CHOOSE(MonthIdx,'Jan'!AM119,'Feb'!AM119,'Mar'!AM119,'Apr'!AM119,'May'!AM119,'Jun'!AM119,'Jul'!AM119,'Aug'!AM119,'Sep'!AM119,'Oct'!AM119,'Nov'!AM119,'Dec'!AM119))
A36: =IF(Roster!$B$30="","",Roster!$B$30) | B36: =IF(Roster!$C$30="","",Roster!$C$30) | C36: =IF(Roster!$C$30="","",Roster!$F$30&"") | D36: =IF(Roster!$C$30="","",Roster!$G$30&"") | E36: =IF($B36="","",CHOOSE(MonthIdx,'Jan'!AI123,'Feb'!AI123,'Mar'!AI123,'Apr'!AI123,'May'!AI123,'Jun'!AI123,'Jul'!AI123,'Aug'!AI123,'Sep'!AI123,'Oct'!AI123,'Nov'!AI123,'Dec'!AI123)) | F36: =IF($B36="","",CHOOSE(MonthIdx,'Jan'!AJ123,'Feb'!AJ123,'Mar'!AJ123,'Apr'!AJ123,'May'!AJ123,'Jun'!AJ123,'Jul'!AJ123,'Aug'!AJ123,'Sep'!AJ123,'Oct'!AJ123,'Nov'!AJ123,'Dec'!AJ123)) | G36: =IF($B36="","",CHOOSE(MonthIdx,'Jan'!AK123,'Feb'!AK123,'Mar'!AK123,'Apr'!AK123,'May'!AK123,'Jun'!AK123,'Jul'!AK123,'Aug'!AK123,'Sep'!AK123,'Oct'!AK123,'Nov'!AK123,'Dec'!AK123)) | H36: =IF($B36="","",CHOOSE(MonthIdx,'Jan'!AL123,'Feb'!AL123,'Mar'!AL123,'Apr'!AL123,'May'!AL123,'Jun'!AL123,'Jul'!AL123,'Aug'!AL123,'Sep'!AL123,'Oct'!AL123,'Nov'!AL123,'Dec'!AL123)) | I36: =IF($B36="","",CHOOSE(MonthIdx,'Jan'!AM123,'Feb'!AM123,'Mar'!AM123,'Apr'!AM123,'May'!AM123,'Jun'!AM123,'Jul'!AM123,'Aug'!AM123,'Sep'!AM123,'Oct'!AM123,'Nov'!AM123,'Dec'!AM123))
A37: =IF(Roster!$B$31="","",Roster!$B$31) | B37: =IF(Roster!$C$31="","",Roster!$C$31) | C37: =IF(Roster!$C$31="","",Roster!$F$31&"") | D37: =IF(Roster!$C$31="","",Roster!$G$31&"") | E37: =IF($B37="","",CHOOSE(MonthIdx,'Jan'!AI127,'Feb'!AI127,'Mar'!AI127,'Apr'!AI127,'May'!AI127,'Jun'!AI127,'Jul'!AI127,'Aug'!AI127,'Sep'!AI127,'Oct'!AI127,'Nov'!AI127,'Dec'!AI127)) | F37: =IF($B37="","",CHOOSE(MonthIdx,'Jan'!AJ127,'Feb'!AJ127,'Mar'!AJ127,'Apr'!AJ127,'May'!AJ127,'Jun'!AJ127,'Jul'!AJ127,'Aug'!AJ127,'Sep'!AJ127,'Oct'!AJ127,'Nov'!AJ127,'Dec'!AJ127)) | G37: =IF($B37="","",CHOOSE(MonthIdx,'Jan'!AK127,'Feb'!AK127,'Mar'!AK127,'Apr'!AK127,'May'!AK127,'Jun'!AK127,'Jul'!AK127,'Aug'!AK127,'Sep'!AK127,'Oct'!AK127,'Nov'!AK127,'Dec'!AK127)) | H37: =IF($B37="","",CHOOSE(MonthIdx,'Jan'!AL127,'Feb'!AL127,'Mar'!AL127,'Apr'!AL127,'May'!AL127,'Jun'!AL127,'Jul'!AL127,'Aug'!AL127,'Sep'!AL127,'Oct'!AL127,'Nov'!AL127,'Dec'!AL127)) | I37: =IF($B37="","",CHOOSE(MonthIdx,'Jan'!AM127,'Feb'!AM127,'Mar'!AM127,'Apr'!AM127,'May'!AM127,'Jun'!AM127,'Jul'!AM127,'Aug'!AM127,'Sep'!AM127,'Oct'!AM127,'Nov'!AM127,'Dec'!AM127))
A38: =IF(Roster!$B$32="","",Roster!$B$32) | B38: =IF(Roster!$C$32="","",Roster!$C$32) | C38: =IF(Roster!$C$32="","",Roster!$F$32&"") | D38: =IF(Roster!$C$32="","",Roster!$G$32&"") | E38: =IF($B38="","",CHOOSE(MonthIdx,'Jan'!AI131,'Feb'!AI131,'Mar'!AI131,'Apr'!AI131,'May'!AI131,'Jun'!AI131,'Jul'!AI131,'Aug'!AI131,'Sep'!AI131,'Oct'!AI131,'Nov'!AI131,'Dec'!AI131)) | F38: =IF($B38="","",CHOOSE(MonthIdx,'Jan'!AJ131,'Feb'!AJ131,'Mar'!AJ131,'Apr'!AJ131,'May'!AJ131,'Jun'!AJ131,'Jul'!AJ131,'Aug'!AJ131,'Sep'!AJ131,'Oct'!AJ131,'Nov'!AJ131,'Dec'!AJ131)) | G38: =IF($B38="","",CHOOSE(MonthIdx,'Jan'!AK131,'Feb'!AK131,'Mar'!AK131,'Apr'!AK131,'May'!AK131,'Jun'!AK131,'Jul'!AK131,'Aug'!AK131,'Sep'!AK131,'Oct'!AK131,'Nov'!AK131,'Dec'!AK131)) | H38: =IF($B38="","",CHOOSE(MonthIdx,'Jan'!AL131,'Feb'!AL131,'Mar'!AL131,'Apr'!AL131,'May'!AL131,'Jun'!AL131,'Jul'!AL131,'Aug'!AL131,'Sep'!AL131,'Oct'!AL131,'Nov'!AL131,'Dec'!AL131)) | I38: =IF($B38="","",CHOOSE(MonthIdx,'Jan'!AM131,'Feb'!AM131,'Mar'!AM131,'Apr'!AM131,'May'!AM131,'Jun'!AM131,'Jul'!AM131,'Aug'!AM131,'Sep'!AM131,'Oct'!AM131,'Nov'!AM131,'Dec'!AM131))
A39: =IF(Roster!$B$33="","",Roster!$B$33) | B39: =IF(Roster!$C$33="","",Roster!$C$33) | C39: =IF(Roster!$C$33="","",Roster!$F$33&"") | D39: =IF(Roster!$C$33="","",Roster!$G$33&"") | E39: =IF($B39="","",CHOOSE(MonthIdx,'Jan'!AI135,'Feb'!AI135,'Mar'!AI135,'Apr'!AI135,'May'!AI135,'Jun'!AI135,'Jul'!AI135,'Aug'!AI135,'Sep'!AI135,'Oct'!AI135,'Nov'!AI135,'Dec'!AI135)) | F39: =IF($B39="","",CHOOSE(MonthIdx,'Jan'!AJ135,'Feb'!AJ135,'Mar'!AJ135,'Apr'!AJ135,'May'!AJ135,'Jun'!AJ135,'Jul'!AJ135,'Aug'!AJ135,'Sep'!AJ135,'Oct'!AJ135,'Nov'!AJ135,'Dec'!AJ135)) | G39: =IF($B39="","",CHOOSE(MonthIdx,'Jan'!AK135,'Feb'!AK135,'Mar'!AK135,'Apr'!AK135,'May'!AK135,'Jun'!AK135,'Jul'!AK135,'Aug'!AK135,'Sep'!AK135,'Oct'!AK135,'Nov'!AK135,'Dec'!AK135)) | H39: =IF($B39="","",CHOOSE(MonthIdx,'Jan'!AL135,'Feb'!AL135,'Mar'!AL135,'Apr'!AL135,'May'!AL135,'Jun'!AL135,'Jul'!AL135,'Aug'!AL135,'Sep'!AL135,'Oct'!AL135,'Nov'!AL135,'Dec'!AL135)) | I39: =IF($B39="","",CHOOSE(MonthIdx,'Jan'!AM135,'Feb'!AM135,'Mar'!AM135,'Apr'!AM135,'May'!AM135,'Jun'!AM135,'Jul'!AM135,'Aug'!AM135,'Sep'!AM135,'Oct'!AM135,'Nov'!AM135,'Dec'!AM135))
A40: =IF(Roster!$B$34="","",Roster!$B$34) | B40: =IF(Roster!$C$34="","",Roster!$C$34) | C40: =IF(Roster!$C$34="","",Roster!$F$34&"") | D40: =IF(Roster!$C$34="","",Roster!$G$34&"") | E40: =IF($B40="","",CHOOSE(MonthIdx,'Jan'!AI139,'Feb'!AI139,'Mar'!AI139,'Apr'!AI139,'May'!AI139,'Jun'!AI139,'Jul'!AI139,'Aug'!AI139,'Sep'!AI139,'Oct'!AI139,'Nov'!AI139,'Dec'!AI139)) | F40: =IF($B40="","",CHOOSE(MonthIdx,'Jan'!AJ139,'Feb'!AJ139,'Mar'!AJ139,'Apr'!AJ139,'May'!AJ139,'Jun'!AJ139,'Jul'!AJ139,'Aug'!AJ139,'Sep'!AJ139,'Oct'!AJ139,'Nov'!AJ139,'Dec'!AJ139)) | G40: =IF($B40="","",CHOOSE(MonthIdx,'Jan'!AK139,'Feb'!AK139,'Mar'!AK139,'Apr'!AK139,'May'!AK139,'Jun'!AK139,'Jul'!AK139,'Aug'!AK139,'Sep'!AK139,'Oct'!AK139,'Nov'!AK139,'Dec'!AK139)) | H40: =IF($B40="","",CHOOSE(MonthIdx,'Jan'!AL139,'Feb'!AL139,'Mar'!AL139,'Apr'!AL139,'May'!AL139,'Jun'!AL139,'Jul'!AL139,'Aug'!AL139,'Sep'!AL139,'Oct'!AL139,'Nov'!AL139,'Dec'!AL139)) | I40: =IF($B40="","",CHOOSE(MonthIdx,'Jan'!AM139,'Feb'!AM139,'Mar'!AM139,'Apr'!AM139,'May'!AM139,'Jun'!AM139,'Jul'!AM139,'Aug'!AM139,'Sep'!AM139,'Oct'!AM139,'Nov'!AM139,'Dec'!AM139))
A41: =IF(Roster!$B$35="","",Roster!$B$35) | B41: =IF(Roster!$C$35="","",Roster!$C$35) | C41: =IF(Roster!$C$35="","",Roster!$F$35&"") | D41: =IF(Roster!$C$35="","",Roster!$G$35&"") | E41: =IF($B41="","",CHOOSE(MonthIdx,'Jan'!AI143,'Feb'!AI143,'Mar'!AI143,'Apr'!AI143,'May'!AI143,'Jun'!AI143,'Jul'!AI143,'Aug'!AI143,'Sep'!AI143,'Oct'!AI143,'Nov'!AI143,'Dec'!AI143)) | F41: =IF($B41="","",CHOOSE(MonthIdx,'Jan'!AJ143,'Feb'!AJ143,'Mar'!AJ143,'Apr'!AJ143,'May'!AJ143,'Jun'!AJ143,'Jul'!AJ143,'Aug'!AJ143,'Sep'!AJ143,'Oct'!AJ143,'Nov'!AJ143,'Dec'!AJ143)) | G41: =IF($B41="","",CHOOSE(MonthIdx,'Jan'!AK143,'Feb'!AK143,'Mar'!AK143,'Apr'!AK143,'May'!AK143,'Jun'!AK143,'Jul'!AK143,'Aug'!AK143,'Sep'!AK143,'Oct'!AK143,'Nov'!AK143,'Dec'!AK143)) | H41: =IF($B41="","",CHOOSE(MonthIdx,'Jan'!AL143,'Feb'!AL143,'Mar'!AL143,'Apr'!AL143,'May'!AL143,'Jun'!AL143,'Jul'!AL143,'Aug'!AL143,'Sep'!AL143,'Oct'!AL143,'Nov'!AL143,'Dec'!AL143)) | I41: =IF($B41="","",CHOOSE(MonthIdx,'Jan'!AM143,'Feb'!AM143,'Mar'!AM143,'Apr'!AM143,'May'!AM143,'Jun'!AM143,'Jul'!AM143,'Aug'!AM143,'Sep'!AM143,'Oct'!AM143,'Nov'!AM143,'Dec'!AM143))
A42: =IF(Roster!$B$36="","",Roster!$B$36) | B42: =IF(Roster!$C$36="","",Roster!$C$36) | C42: =IF(Roster!$C$36="","",Roster!$F$36&"") | D42: =IF(Roster!$C$36="","",Roster!$G$36&"") | E42: =IF($B42="","",CHOOSE(MonthIdx,'Jan'!AI147,'Feb'!AI147,'Mar'!AI147,'Apr'!AI147,'May'!AI147,'Jun'!AI147,'Jul'!AI147,'Aug'!AI147,'Sep'!AI147,'Oct'!AI147,'Nov'!AI147,'Dec'!AI147)) | F42: =IF($B42="","",CHOOSE(MonthIdx,'Jan'!AJ147,'Feb'!AJ147,'Mar'!AJ147,'Apr'!AJ147,'May'!AJ147,'Jun'!AJ147,'Jul'!AJ147,'Aug'!AJ147,'Sep'!AJ147,'Oct'!AJ147,'Nov'!AJ147,'Dec'!AJ147)) | G42: =IF($B42="","",CHOOSE(MonthIdx,'Jan'!AK147,'Feb'!AK147,'Mar'!AK147,'Apr'!AK147,'May'!AK147,'Jun'!AK147,'Jul'!AK147,'Aug'!AK147,'Sep'!AK147,'Oct'!AK147,'Nov'!AK147,'Dec'!AK147)) | H42: =IF($B42="","",CHOOSE(MonthIdx,'Jan'!AL147,'Feb'!AL147,'Mar'!AL147,'Apr'!AL147,'May'!AL147,'Jun'!AL147,'Jul'!AL147,'Aug'!AL147,'Sep'!AL147,'Oct'!AL147,'Nov'!AL147,'Dec'!AL147)) | I42: =IF($B42="","",CHOOSE(MonthIdx,'Jan'!AM147,'Feb'!AM147,'Mar'!AM147,'Apr'!AM147,'May'!AM147,'Jun'!AM147,'Jul'!AM147,'Aug'!AM147,'Sep'!AM147,'Oct'!AM147,'Nov'!AM147,'Dec'!AM147))
A43: =IF(Roster!$B$37="","",Roster!$B$37) | B43: =IF(Roster!$C$37="","",Roster!$C$37) | C43: =IF(Roster!$C$37="","",Roster!$F$37&"") | D43: =IF(Roster!$C$37="","",Roster!$G$37&"") | E43: =IF($B43="","",CHOOSE(MonthIdx,'Jan'!AI151,'Feb'!AI151,'Mar'!AI151,'Apr'!AI151,'May'!AI151,'Jun'!AI151,'Jul'!AI151,'Aug'!AI151,'Sep'!AI151,'Oct'!AI151,'Nov'!AI151,'Dec'!AI151)) | F43: =IF($B43="","",CHOOSE(MonthIdx,'Jan'!AJ151,'Feb'!AJ151,'Mar'!AJ151,'Apr'!AJ151,'May'!AJ151,'Jun'!AJ151,'Jul'!AJ151,'Aug'!AJ151,'Sep'!AJ151,'Oct'!AJ151,'Nov'!AJ151,'Dec'!AJ151)) | G43: =IF($B43="","",CHOOSE(MonthIdx,'Jan'!AK151,'Feb'!AK151,'Mar'!AK151,'Apr'!AK151,'May'!AK151,'Jun'!AK151,'Jul'!AK151,'Aug'!AK151,'Sep'!AK151,'Oct'!AK151,'Nov'!AK151,'Dec'!AK151)) | H43: =IF($B43="","",CHOOSE(MonthIdx,'Jan'!AL151,'Feb'!AL151,'Mar'!AL151,'Apr'!AL151,'May'!AL151,'Jun'!AL151,'Jul'!AL151,'Aug'!AL151,'Sep'!AL151,'Oct'!AL151,'Nov'!AL151,'Dec'!AL151)) | I43: =IF($B43="","",CHOOSE(MonthIdx,'Jan'!AM151,'Feb'!AM151,'Mar'!AM151,'Apr'!AM151,'May'!AM151,'Jun'!AM151,'Jul'!AM151,'Aug'!AM151,'Sep'!AM151,'Oct'!AM151,'Nov'!AM151,'Dec'!AM151))
...

Sheet Guide
A1: LODESTAR FLIGHT & OPS PLANNER: HOW IT WORKS
A2: Offline, macro-free. Desktop Excel 2010 or later.
A4: ONE FILE PER DEPARTMENT
A5: Each department keeps its own copy of this workbook, with its own roster, flight programme and SDO days. The department name is on the Dashboard (cell G5).
A6: To see other departments, open the planner dashboard (the .html file), open your own Excel, then click 'Add other departments' and pick their Excel files. Each one shows as a read-only tab, and the SDO Plan tab combines everyone's SDO days.
A7: Duty days (BDO = Base Duty Officer, SDO = Squadron Duty Orderly) come from the Duty Planner's Duty Roster file. In the dashboard, open your own file, Add other departments and pick the Duty Roster, then on the Duty Planner tab click 'Copy my duty days from the Duty Roster' and Save to Excel.
A8: New department: copy an empty file, change the Department name on the Dashboard, and fill in its roster.
A10: SHEETS
A11: Dashboard: pick a year and month to see KPI cards, crew totals, the activity legend and the year overview. 'Open planner' jumps to that month.
A12: Jan to Dec: the planning matrix. Each crew member has AM, PM and NIGHT rows. Click a day cell and pick an activity from the dropdown.
A13: BDO Plan and SDO Plan: year calendars of your department's BDO and SDO days, copied from the Duty Roster. Each month tab shows them in the pink DUTY DAYS row and the table on the right lists the dates.
A14: DUTY DAYS row (month tabs): green when someone in your department has that duty planned (activity BDO or SDO), red when nobody does.
... A40: New year: in the dashboard Ops Room, Master Planner menu > Start new year. It archives this year's files and moves every file to the next year (crew, activities, currency dates and open down-chits carry over).

Sheet Daily View
A1: DAILY OPS VIEW | SUP 2
A2: Type a date to see who is on what. Shows today by default.
A4: DATE
A5: =TODAY() | C5: =IF(NOT(AND(A5>=DATE(PlanYear,1,1),A5<=DATE(PlanYear+1,1,31))),"Date is outside planning year "&PlanYear&" and January "&(PlanYear+1),"")
A7: FLIGHTS | C7: FLYING HRS | D7: SDO ON DUTY | E7: ON LEAVE | F7: AVAILABLE CREW | G7: DUTY DAY
A8: =IF(NOT(AND($A$5>=DATE(PlanYear,1,1),$A$5<=DATE(PlanYear+1,1,31))),"",INDEX({ref},1,DAY($A$5))) | C8: =IF(NOT(AND($A$5>=DATE(PlanYear,1,1),$A$5<=DATE(PlanYear+1,1,31))),"",INDEX({ref},1,DAY($A$5))) | D8: =IF(NOT(AND($A$5>=DATE(PlanYear,1,1),$A$5<=DATE(PlanYear+1,1,31))),"",INDEX({ref},1,DAY($A$5))) | E8: =IF(NOT(AND($A$5>=DATE(PlanYear,1,1),$A$5<=DATE(PlanYear+1,1,31))),"",INDEX({ref},1,DAY($A$5))) | F8: =IF(NOT(AND($A$5>=DATE(PlanYear,1,1),$A$5<=DATE(PlanYear+1,1,31))),"",INDEX({ref},1,DAY($A$5))) | G8: =IF(NOT(AND($A$5>=DATE(PlanYear,1,1),$A$5<=DATE(PlanYear+1,1,31))),"",IF(INDEX({sdoref},1,DAY($A$5))="","No",INDEX({sdoref},1,DAY($A$5))))
A10: Callsign | B10: Crew Member | C10: Role | D10: AM | E10: PM | F10: NIGHT | G10: WD
A11: =IF(Roster!$B$6="","",Roster!$B$6) | B11: =IF(Roster!$C$6="","",Roster!$C$6) | C11: =IF(Roster!$C$6="","",Roster!$F$6&IF(OR(Roster!$G$6="SANS",Roster!$G$6="NSMEN")," | "&Roster!$G$6,"")) | D11: =IF(OR($B11="",NOT(AND($A$5>=DATE(PlanYear,1,1),$A$5<=DATE(PlanYear+1,1,31)))),"",INDEX(CHOOSE(IF(YEAR($A$5)>PlanYear,13,MONTH($A$5)),'Jan'!$D$27:$AH$266,'Feb'!$D$27:$AH$266,'Mar'!$D$27:$AH$266,'Apr'!$D$27:$AH$266,'May'!$D$27:$AH$266,'Jun'!$D$27:$AH$266,'Jul'!$D$27:$AH$266,'Aug'!$D$27:$AH$266,'Sep'!$D$27:$AH$266,'Oct'!$D$27:$AH$266,'Nov'!$D$27:$AH$266,'Dec'!$D$27:$AH$266,'Jan (next year)'!$D$27:$AH$266),1,DAY($A$5))&"") | E11: =IF(OR($B11="",NOT(AND($A$5>=DATE(PlanYear,1,1),$A$5<=DATE(PlanYear+1,1,31)))),"",INDEX(CHOOSE(IF(YEAR($A$5)>PlanYear,13,MONTH($A$5)),'Jan'!$D$27:$AH$266,'Feb'!$D$27:$AH$266,'Mar'!$D$27:$AH$266,'Apr'!$D$27:$AH$266,'May'!$D$27:$AH$266,'Jun'!$D$27:$AH$266,'Jul'!$D$27:$AH$266,'Aug'!$D$27:$AH$266,'Sep'!$D$27:$AH$266,'Oct'!$D$27:$AH$266,'Nov'!$D$27:$AH$266,'Dec'!$D$27:$AH$266,'Jan (next year)'!$D$27:$AH$266),2,DAY($A$5))&"") | F11: =IF(OR($B11="",NOT(AND($A$5>=DATE(PlanYear,1,1),$A$5<=DATE(PlanYear+1,1,31)))),"",INDEX(CHOOSE(IF(YEAR($A$5)>PlanYear,13,MONTH($A$5)),'Jan'!$D$27:$AH$266,'Feb'!$D$27:$AH$266,'Mar'!$D$27:$AH$266,'Apr'!$D$27:$AH$266,'May'!$D$27:$AH$266,'Jun'!$D$27:$AH$266,'Jul'!$D$27:$AH$266,'Aug'!$D$27:$AH$266,'Sep'!$D$27:$AH$266,'Oct'!$D$27:$AH$266,'Nov'!$D$27:$AH$266,'Dec'!$D$27:$AH$266,'Jan (next year)'!$D$27:$AH$266),3,DAY($A$5))&"") | G11: =IF(OR($B11="",NOT(AND($A$5>=DATE(PlanYear,1,1),$A$5<=DATE(PlanYear+1,1,31)))),"",INDEX(CHOOSE(IF(YEAR($A$5)>PlanYear,13,MONTH($A$5)),'Jan'!$D$27:$AH$266,'Feb'!$D$27:$AH$266,'Mar'!$D$27:$AH$266,'Apr'!$D$27:$AH$266,'May'!$D$27:$AH$266,'Jun'!$D$27:$AH$266,'Jul'!$D$27:$AH$266,'Aug'!$D$27:$AH$266,'Sep'!$D$27:$AH$266,'Oct'!$D$27:$AH$266,'Nov'!$D$27:$AH$266,'Dec'!$D$27:$AH$266,'Jan (next year)'!$D$27:$AH$266),4,DAY($A$5))&"")
A12: =IF(Roster!$B$7="","",Roster!$B$7) | B12: =IF(Roster!$C$7="","",Roster!$C$7) | C12: =IF(Roster!$C$7="","",Roster!$F$7&IF(OR(Roster!$G$7="SANS",Roster!$G$7="NSMEN")," | "&Roster!$G$7,"")) | D12: =IF(OR($B12="",NOT(AND($A$5>=DATE(PlanYear,1,1),$A$5<=DATE(PlanYear+1,1,31)))),"",INDEX(CHOOSE(IF(YEAR($A$5)>PlanYear,13,MONTH($A$5)),'Jan'!$D$27:$AH$266,'Feb'!$D$27:$AH$266,'Mar'!$D$27:$AH$266,'Apr'!$D$27:$AH$266,'May'!$D$27:$AH$266,'Jun'!$D$27:$AH$266,'Jul'!$D$27:$AH$266,'Aug'!$D$27:$AH$266,'Sep'!$D$27:$AH$266,'Oct'!$D$27:$AH$266,'Nov'!$D$27:$AH$266,'Dec'!$D$27:$AH$266,'Jan (next year)'!$D$27:$AH$266),5,DAY($A$5))&"") | E12: =IF(OR($B12="",NOT(AND($A$5>=DATE(PlanYear,1,1),$A$5<=DATE(PlanYear+1,1,31)))),"",INDEX(CHOOSE(IF(YEAR($A$5)>PlanYear,13,MONTH($A$5)),'Jan'!$D$27:$AH$266,'Feb'!$D$27:$AH$266,'Mar'!$D$27:$AH$266,'Apr'!$D$27:$AH$266,'May'!$D$27:$AH$266,'Jun'!$D$27:$AH$266,'Jul'!$D$27:$AH$266,'Aug'!$D$27:$AH$266,'Sep'!$D$27:$AH$266,'Oct'!$D$27:$AH$266,'Nov'!$D$27:$AH$266,'Dec'!$D$27:$AH$266,'Jan (next year)'!$D$27:$AH$266),6,DAY($A$5))&"") | F12: =IF(OR($B12="",NOT(AND($A$5>=DATE(PlanYear,1,1),$A$5<=DATE(PlanYear+1,1,31)))),"",INDEX(CHOOSE(IF(YEAR($A$5)>PlanYear,13,MONTH($A$5)),'Jan'!$D$27:$AH$266,'Feb'!$D$27:$AH$266,'Mar'!$D$27:$AH$266,'Apr'!$D$27:$AH$266,'May'!$D$27:$AH$266,'Jun'!$D$27:$AH$266,'Jul'!$D$27:$AH$266,'Aug'!$D$27:$AH$266,'Sep'!$D$27:$AH$266,'Oct'!$D$27:$AH$266,'Nov'!$D$27:$AH$266,'Dec'!$D$27:$AH$266,'Jan (next year)'!$D$27:$AH$266),7,DAY($A$5))&"") | G12: =IF(OR($B12="",NOT(AND($A$5>=DATE(PlanYear,1,1),$A$5<=DATE(PlanYear+1,1,31)))),"",INDEX(CHOOSE(IF(YEAR($A$5)>PlanYear,13,MONTH($A$5)),'Jan'!$D$27:$AH$266,'Feb'!$D$27:$AH$266,'Mar'!$D$27:$AH$266,'Apr'!$D$27:$AH$266,'May'!$D$27:$AH$266,'Jun'!$D$27:$AH$266,'Jul'!$D$27:$AH$266,'Aug'!$D$27:$AH$266,'Sep'!$D$27:$AH$266,'Oct'!$D$27:$AH$266,'Nov'!$D$27:$AH$266,'Dec'!$D$27:$AH$266,'Jan (next year)'!$D$27:$AH$266),8,DAY($A$5))&"")
A13: =IF(Roster!$B$8="","",Roster!$B$8) | B13: =IF(Roster!$C$8="","",Roster!$C$8) | C13: =IF(Roster!$C$8="","",Roster!$F$8&IF(OR(Roster!$G$8="SANS",Roster!$G$8="NSMEN")," | "&Roster!$G$8,"")) | D13: =IF(OR($B13="",NOT(AND($A$5>=DATE(PlanYear,1,1),$A$5<=DATE(PlanYear+1,1,31)))),"",INDEX(CHOOSE(IF(YEAR($A$5)>PlanYear,13,MONTH($A$5)),'Jan'!$D$27:$AH$266,'Feb'!$D$27:$AH$266,'Mar'!$D$27:$AH$266,'Apr'!$D$27:$AH$266,'May'!$D$27:$AH$266,'Jun'!$D$27:$AH$266,'Jul'!$D$27:$AH$266,'Aug'!$D$27:$AH$266,'Sep'!$D$27:$AH$266,'Oct'!$D$27:$AH$266,'Nov'!$D$27:$AH$266,'Dec'!$D$27:$AH$266,'Jan (next year)'!$D$27:$AH$266),9,DAY($A$5))&"") | E13: =IF(OR($B13="",NOT(AND($A$5>=DATE(PlanYear,1,1),$A$5<=DATE(PlanYear+1,1,31)))),"",INDEX(CHOOSE(IF(YEAR($A$5)>PlanYear,13,MONTH($A$5)),'Jan'!$D$27:$AH$266,'Feb'!$D$27:$AH$266,'Mar'!$D$27:$AH$266,'Apr'!$D$27:$AH$266,'May'!$D$27:$AH$266,'Jun'!$D$27:$AH$266,'Jul'!$D$27:$AH$266,'Aug'!$D$27:$AH$266,'Sep'!$D$27:$AH$266,'Oct'!$D$27:$AH$266,'Nov'!$D$27:$AH$266,'Dec'!$D$27:$AH$266,'Jan (next year)'!$D$27:$AH$266),10,DAY($A$5))&"") | F13: =IF(OR($B13="",NOT(AND($A$5>=DATE(PlanYear,1,1),$A$5<=DATE(PlanYear+1,1,31)))),"",INDEX(CHOOSE(IF(YEAR($A$5)>PlanYear,13,MONTH($A$5)),'Jan'!$D$27:$AH$266,'Feb'!$D$27:$AH$266,'Mar'!$D$27:$AH$266,'Apr'!$D$27:$AH$266,'May'!$D$27:$AH$266,'Jun'!$D$27:$AH$266,'Jul'!$D$27:$AH$266,'Aug'!$D$27:$AH$266,'Sep'!$D$27:$AH$266,'Oct'!$D$27:$AH$266,'Nov'!$D$27:$AH$266,'Dec'!$D$27:$AH$266,'Jan (next year)'!$D$27:$AH$266),11,DAY($A$5))&"") | G13: =IF(OR($B13="",NOT(AND($A$5>=DATE(PlanYear,1,1),$A$5<=DATE(PlanYear+1,1,31)))),"",INDEX(CHOOSE(IF(YEAR($A$5)>PlanYear,13,MONTH($A$5)),'Jan'!$D$27:$AH$266,'Feb'!$D$27:$AH$266,'Mar'!$D$27:$AH$266,'Apr'!$D$27:$AH$266,'May'!$D$27:$AH$266,'Jun'!$D$27:$AH$266,'Jul'!$D$27:$AH$266,'Aug'!$D$27:$AH$266,'Sep'!$D$27:$AH$266,'Oct'!$D$27:$AH$266,'Nov'!$D$27:$AH$266,'Dec'!$D$27:$AH$266,'Jan (next year)'!$D$27:$AH$266),12,DAY($A$5))&"")
A14: =IF(Roster!$B$9="","",Roster!$B$9) | B14: =IF(Roster!$C$9="","",Roster!$C$9) | C14: =IF(Roster!$C$9="","",Roster!$F$9&IF(OR(Roster!$G$9="SANS",Roster!$G$9="NSMEN")," | "&Roster!$G$9,"")) | D14: =IF(OR($B14="",NOT(AND($A$5>=DATE(PlanYear,1,1),$A$5<=DATE(PlanYear+1,1,31)))),"",INDEX(CHOOSE(IF(YEAR($A$5)>PlanYear,13,MONTH($A$5)),'Jan'!$D$27:$AH$266,'Feb'!$D$27:$AH$266,'Mar'!$D$27:$AH$266,'Apr'!$D$27:$AH$266,'May'!$D$27:$AH$266,'Jun'!$D$27:$AH$266,'Jul'!$D$27:$AH$266,'Aug'!$D$27:$AH$266,'Sep'!$D$27:$AH$266,'Oct'!$D$27:$AH$266,'Nov'!$D$27:$AH$266,'Dec'!$D$27:$AH$266,'Jan (next year)'!$D$27:$AH$266),13,DAY($A$5))&"") | E14: =IF(OR($B14="",NOT(AND($A$5>=DATE(PlanYear,1,1),$A$5<=DATE(PlanYear+1,1,31)))),"",INDEX(CHOOSE(IF(YEAR($A$5)>PlanYear,13,MONTH($A$5)),'Jan'!$D$27:$AH$266,'Feb'!$D$27:$AH$266,'Mar'!$D$27:$AH$266,'Apr'!$D$27:$AH$266,'May'!$D$27:$AH$266,'Jun'!$D$27:$AH$266,'Jul'!$D$27:$AH$266,'Aug'!$D$27:$AH$266,'Sep'!$D$27:$AH$266,'Oct'!$D$27:$AH$266,'Nov'!$D$27:$AH$266,'Dec'!$D$27:$AH$266,'Jan (next year)'!$D$27:$AH$266),14,DAY($A$5))&"") | F14: =IF(OR($B14="",NOT(AND($A$5>=DATE(PlanYear,1,1),$A$5<=DATE(PlanYear+1,1,31)))),"",INDEX(CHOOSE(IF(YEAR($A$5)>PlanYear,13,MONTH($A$5)),'Jan'!$D$27:$AH$266,'Feb'!$D$27:$AH$266,'Mar'!$D$27:$AH$266,'Apr'!$D$27:$AH$266,'May'!$D$27:$AH$266,'Jun'!$D$27:$AH$266,'Jul'!$D$27:$AH$266,'Aug'!$D$27:$AH$266,'Sep'!$D$27:$AH$266,'Oct'!$D$27:$AH$266,'Nov'!$D$27:$AH$266,'Dec'!$D$27:$AH$266,'Jan (next year)'!$D$27:$AH$266),15,DAY($A$5))&"") | G14: =IF(OR($B14="",NOT(AND($A$5>=DATE(PlanYear,1,1),$A$5<=DATE(PlanYear+1,1,31)))),"",INDEX(CHOOSE(IF(YEAR($A$5)>PlanYear,13,MONTH($A$5)),'Jan'!$D$27:$AH$266,'Feb'!$D$27:$AH$266,'Mar'!$D$27:$AH$266,'Apr'!$D$27:$AH$266,'May'!$D$27:$AH$266,'Jun'!$D$27:$AH$266,'Jul'!$D$27:$AH$266,'Aug'!$D$27:$AH$266,'Sep'!$D$27:$AH$266,'Oct'!$D$27:$AH$266,'Nov'!$D$27:$AH$266,'Dec'!$D$27:$AH$266,'Jan (next year)'!$D$27:$AH$266),16,DAY($A$5))&"")
A15: =IF(Roster!$B$10="","",Roster!$B$10) | B15: =IF(Roster!$C$10="","",Roster!$C$10) | C15: =IF(Roster!$C$10="","",Roster!$F$10&IF(OR(Roster!$G$10="SANS",Roster!$G$10="NSMEN")," | "&Roster!$G$10,"")) | D15: =IF(OR($B15="",NOT(AND($A$5>=DATE(PlanYear,1,1),$A$5<=DATE(PlanYear+1,1,31)))),"",INDEX(CHOOSE(IF(YEAR($A$5)>PlanYear,13,MONTH($A$5)),'Jan'!$D$27:$AH$266,'Feb'!$D$27:$AH$266,'Mar'!$D$27:$AH$266,'Apr'!$D$27:$AH$266,'May'!$D$27:$AH$266,'Jun'!$D$27:$AH$266,'Jul'!$D$27:$AH$266,'Aug'!$D$27:$AH$266,'Sep'!$D$27:$AH$266,'Oct'!$D$27:$AH$266,'Nov'!$D$27:$AH$266,'Dec'!$D$27:$AH$266,'Jan (next year)'!$D$27:$AH$266),17,DAY($A$5))&"") | E15: =IF(OR($B15="",NOT(AND($A$5>=DATE(PlanYear,1,1),$A$5<=DATE(PlanYear+1,1,31)))),"",INDEX(CHOOSE(IF(YEAR($A$5)>PlanYear,13,MONTH($A$5)),'Jan'!$D$27:$AH$266,'Feb'!$D$27:$AH$266,'Mar'!$D$27:$AH$266,'Apr'!$D$27:$AH$266,'May'!$D$27:$AH$266,'Jun'!$D$27:$AH$266,'Jul'!$D$27:$AH$266,'Aug'!$D$27:$AH$266,'Sep'!$D$27:$AH$266,'Oct'!$D$27:$AH$266,'Nov'!$D$27:$AH$266,'Dec'!$D$27:$AH$266,'Jan (next year)'!$D$27:$AH$266),18,DAY($A$5))&"") | F15: =IF(OR($B15="",NOT(AND($A$5>=DATE(PlanYear,1,1),$A$5<=DATE(PlanYear+1,1,31)))),"",INDEX(CHOOSE(IF(YEAR($A$5)>PlanYear,13,MONTH($A$5)),'Jan'!$D$27:$AH$266,'Feb'!$D$27:$AH$266,'Mar'!$D$27:$AH$266,'Apr'!$D$27:$AH$266,'May'!$D$27:$AH$266,'Jun'!$D$27:$AH$266,'Jul'!$D$27:$AH$266,'Aug'!$D$27:$AH$266,'Sep'!$D$27:$AH$266,'Oct'!$D$27:$AH$266,'Nov'!$D$27:$AH$266,'Dec'!$D$27:$AH$266,'Jan (next year)'!$D$27:$AH$266),19,DAY($A$5))&"") | G15: =IF(OR($B15="",NOT(AND($A$5>=DATE(PlanYear,1,1),$A$5<=DATE(PlanYear+1,1,31)))),"",INDEX(CHOOSE(IF(YEAR($A$5)>PlanYear,13,MONTH($A$5)),'Jan'!$D$27:$AH$266,'Feb'!$D$27:$AH$266,'Mar'!$D$27:$AH$266,'Apr'!$D$27:$AH$266,'May'!$D$27:$AH$266,'Jun'!$D$27:$AH$266,'Jul'!$D$27:$AH$266,'Aug'!$D$27:$AH$266,'Sep'!$D$27:$AH$266,'Oct'!$D$27:$AH$266,'Nov'!$D$27:$AH$266,'Dec'!$D$27:$AH$266,'Jan (next year)'!$D$27:$AH$266),20,DAY($A$5))&"")
A16: =IF(Roster!$B$11="","",Roster!$B$11) | B16: =IF(Roster!$C$11="","",Roster!$C$11) | C16: =IF(Roster!$C$11="","",Roster!$F$11&IF(OR(Roster!$G$11="SANS",Roster!$G$11="NSMEN")," | "&Roster!$G$11,"")) | D16: =IF(OR($B16="",NOT(AND($A$5>=DATE(PlanYear,1,1),$A$5<=DATE(PlanYear+1,1,31)))),"",INDEX(CHOOSE(IF(YEAR($A$5)>PlanYear,13,MONTH($A$5)),'Jan'!$D$27:$AH$266,'Feb'!$D$27:$AH$266,'Mar'!$D$27:$AH$266,'Apr'!$D$27:$AH$266,'May'!$D$27:$AH$266,'Jun'!$D$27:$AH$266,'Jul'!$D$27:$AH$266,'Aug'!$D$27:$AH$266,'Sep'!$D$27:$AH$266,'Oct'!$D$27:$AH$266,'Nov'!$D$27:$AH$266,'Dec'!$D$27:$AH$266,'Jan (next year)'!$D$27:$AH$266),21,DAY($A$5))&"") | E16: =IF(OR($B16="",NOT(AND($A$5>=DATE(PlanYear,1,1),$A$5<=DATE(PlanYear+1,1,31)))),"",INDEX(CHOOSE(IF(YEAR($A$5)>PlanYear,13,MONTH($A$5)),'Jan'!$D$27:$AH$266,'Feb'!$D$27:$AH$266,'Mar'!$D$27:$AH$266,'Apr'!$D$27:$AH$266,'May'!$D$27:$AH$266,'Jun'!$D$27:$AH$266,'Jul'!$D$27:$AH$266,'Aug'!$D$27:$AH$266,'Sep'!$D$27:$AH$266,'Oct'!$D$27:$AH$266,'Nov'!$D$27:$AH$266,'Dec'!$D$27:$AH$266,'Jan (next year)'!$D$27:$AH$266),22,DAY($A$5))&"") | F16: =IF(OR($B16="",NOT(AND($A$5>=DATE(PlanYear,1,1),$A$5<=DATE(PlanYear+1,1,31)))),"",INDEX(CHOOSE(IF(YEAR($A$5)>PlanYear,13,MONTH($A$5)),'Jan'!$D$27:$AH$266,'Feb'!$D$27:$AH$266,'Mar'!$D$27:$AH$266,'Apr'!$D$27:$AH$266,'May'!$D$27:$AH$266,'Jun'!$D$27:$AH$266,'Jul'!$D$27:$AH$266,'Aug'!$D$27:$AH$266,'Sep'!$D$27:$AH$266,'Oct'!$D$27:$AH$266,'Nov'!$D$27:$AH$266,'Dec'!$D$27:$AH$266,'Jan (next year)'!$D$27:$AH$266),23,DAY($A$5))&"") | G16: =IF(OR($B16="",NOT(AND($A$5>=DATE(PlanYear,1,1),$A$5<=DATE(PlanYear+1,1,31)))),"",INDEX(CHOOSE(IF(YEAR($A$5)>PlanYear,13,MONTH($A$5)),'Jan'!$D$27:$AH$266,'Feb'!$D$27:$AH$266,'Mar'!$D$27:$AH$266,'Apr'!$D$27:$AH$266,'May'!$D$27:$AH$266,'Jun'!$D$27:$AH$266,'Jul'!$D$27:$AH$266,'Aug'!$D$27:$AH$266,'Sep'!$D$27:$AH$266,'Oct'!$D$27:$AH$266,'Nov'!$D$27:$AH$266,'Dec'!$D$27:$AH$266,'Jan (next year)'!$D$27:$AH$266),24,DAY($A$5))&"")
A17: =IF(Roster!$B$12="","",Roster!$B$12) | B17: =IF(Roster!$C$12="","",Roster!$C$12) | C17: =IF(Roster!$C$12="","",Roster!$F$12&IF(OR(Roster!$G$12="SANS",Roster!$G$12="NSMEN")," | "&Roster!$G$12,"")) | D17: =IF(OR($B17="",NOT(AND($A$5>=DATE(PlanYear,1,1),$A$5<=DATE(PlanYear+1,1,31)))),"",INDEX(CHOOSE(IF(YEAR($A$5)>PlanYear,13,MONTH($A$5)),'Jan'!$D$27:$AH$266,'Feb'!$D$27:$AH$266,'Mar'!$D$27:$AH$266,'Apr'!$D$27:$AH$266,'May'!$D$27:$AH$266,'Jun'!$D$27:$AH$266,'Jul'!$D$27:$AH$266,'Aug'!$D$27:$AH$266,'Sep'!$D$27:$AH$266,'Oct'!$D$27:$AH$266,'Nov'!$D$27:$AH$266,'Dec'!$D$27:$AH$266,'Jan (next year)'!$D$27:$AH$266),25,DAY($A$5))&"") | E17: =IF(OR($B17="",NOT(AND($A$5>=DATE(PlanYear,1,1),$A$5<=DATE(PlanYear+1,1,31)))),"",INDEX(CHOOSE(IF(YEAR($A$5)>PlanYear,13,MONTH($A$5)),'Jan'!$D$27:$AH$266,'Feb'!$D$27:$AH$266,'Mar'!$D$27:$AH$266,'Apr'!$D$27:$AH$266,'May'!$D$27:$AH$266,'Jun'!$D$27:$AH$266,'Jul'!$D$27:$AH$266,'Aug'!$D$27:$AH$266,'Sep'!$D$27:$AH$266,'Oct'!$D$27:$AH$266,'Nov'!$D$27:$AH$266,'Dec'!$D$27:$AH$266,'Jan (next year)'!$D$27:$AH$266),26,DAY($A$5))&"") | F17: =IF(OR($B17="",NOT(AND($A$5>=DATE(PlanYear,1,1),$A$5<=DATE(PlanYear+1,1,31)))),"",INDEX(CHOOSE(IF(YEAR($A$5)>PlanYear,13,MONTH($A$5)),'Jan'!$D$27:$AH$266,'Feb'!$D$27:$AH$266,'Mar'!$D$27:$AH$266,'Apr'!$D$27:$AH$266,'May'!$D$27:$AH$266,'Jun'!$D$27:$AH$266,'Jul'!$D$27:$AH$266,'Aug'!$D$27:$AH$266,'Sep'!$D$27:$AH$266,'Oct'!$D$27:$AH$266,'Nov'!$D$27:$AH$266,'Dec'!$D$27:$AH$266,'Jan (next year)'!$D$27:$AH$266),27,DAY($A$5))&"") | G17: =IF(OR($B17="",NOT(AND($A$5>=DATE(PlanYear,1,1),$A$5<=DATE(PlanYear+1,1,31)))),"",INDEX(CHOOSE(IF(YEAR($A$5)>PlanYear,13,MONTH($A$5)),'Jan'!$D$27:$AH$266,'Feb'!$D$27:$AH$266,'Mar'!$D$27:$AH$266,'Apr'!$D$27:$AH$266,'May'!$D$27:$AH$266,'Jun'!$D$27:$AH$266,'Jul'!$D$27:$AH$266,'Aug'!$D$27:$AH$266,'Sep'!$D$27:$AH$266,'Oct'!$D$27:$AH$266,'Nov'!$D$27:$AH$266,'Dec'!$D$27:$AH$266,'Jan (next year)'!$D$27:$AH$266),28,DAY($A$5))&"")
A18: =IF(Roster!$B$13="","",Roster!$B$13) | B18: =IF(Roster!$C$13="","",Roster!$C$13) | C18: =IF(Roster!$C$13="","",Roster!$F$13&IF(OR(Roster!$G$13="SANS",Roster!$G$13="NSMEN")," | "&Roster!$G$13,"")) | D18: =IF(OR($B18="",NOT(AND($A$5>=DATE(PlanYear,1,1),$A$5<=DATE(PlanYear+1,1,31)))),"",INDEX(CHOOSE(IF(YEAR($A$5)>PlanYear,13,MONTH($A$5)),'Jan'!$D$27:$AH$266,'Feb'!$D$27:$AH$266,'Mar'!$D$27:$AH$266,'Apr'!$D$27:$AH$266,'May'!$D$27:$AH$266,'Jun'!$D$27:$AH$266,'Jul'!$D$27:$AH$266,'Aug'!$D$27:$AH$266,'Sep'!$D$27:$AH$266,'Oct'!$D$27:$AH$266,'Nov'!$D$27:$AH$266,'Dec'!$D$27:$AH$266,'Jan (next year)'!$D$27:$AH$266),29,DAY($A$5))&"") | E18: =IF(OR($B18="",NOT(AND($A$5>=DATE(PlanYear,1,1),$A$5<=DATE(PlanYear+1,1,31)))),"",INDEX(CHOOSE(IF(YEAR($A$5)>PlanYear,13,MONTH($A$5)),'Jan'!$D$27:$AH$266,'Feb'!$D$27:$AH$266,'Mar'!$D$27:$AH$266,'Apr'!$D$27:$AH$266,'May'!$D$27:$AH$266,'Jun'!$D$27:$AH$266,'Jul'!$D$27:$AH$266,'Aug'!$D$27:$AH$266,'Sep'!$D$27:$AH$266,'Oct'!$D$27:$AH$266,'Nov'!$D$27:$AH$266,'Dec'!$D$27:$AH$266,'Jan (next year)'!$D$27:$AH$266),30,DAY($A$5))&"") | F18: =IF(OR($B18="",NOT(AND($A$5>=DATE(PlanYear,1,1),$A$5<=DATE(PlanYear+1,1,31)))),"",INDEX(CHOOSE(IF(YEAR($A$5)>PlanYear,13,MONTH($A$5)),'Jan'!$D$27:$AH$266,'Feb'!$D$27:$AH$266,'Mar'!$D$27:$AH$266,'Apr'!$D$27:$AH$266,'May'!$D$27:$AH$266,'Jun'!$D$27:$AH$266,'Jul'!$D$27:$AH$266,'Aug'!$D$27:$AH$266,'Sep'!$D$27:$AH$266,'Oct'!$D$27:$AH$266,'Nov'!$D$27:$AH$266,'Dec'!$D$27:$AH$266,'Jan (next year)'!$D$27:$AH$266),31,DAY($A$5))&"") | G18: =IF(OR($B18="",NOT(AND($A$5>=DATE(PlanYear,1,1),$A$5<=DATE(PlanYear+1,1,31)))),"",INDEX(CHOOSE(IF(YEAR($A$5)>PlanYear,13,MONTH($A$5)),'Jan'!$D$27:$AH$266,'Feb'!$D$27:$AH$266,'Mar'!$D$27:$AH$266,'Apr'!$D$27:$AH$266,'May'!$D$27:$AH$266,'Jun'!$D$27:$AH$266,'Jul'!$D$27:$AH$266,'Aug'!$D$27:$AH$266,'Sep'!$D$27:$AH$266,'Oct'!$D$27:$AH$266,'Nov'!$D$27:$AH$266,'Dec'!$D$27:$AH$266,'Jan (next year)'!$D$27:$AH$266),32,DAY($A$5))&"")
