Workbook
Name PlanYear: Dashboard!$A$5
Name GrList: OFFSET('Flight Codes'!$I$6,0,0,MAX(1,COUNTA('Flight Codes'!$I$6:$I$25)),1)
Name FlCodes: OFFSET('Flight Codes'!$A$6,0,0,MAX(1,COUNTA('Flight Codes'!$A$6:$A$45)),1)
Name CodeTable: 'Flight Codes'!$A$6:$E$45
Name DayStatusList: OFFSET('Flight Codes'!$G$6,0,0,MAX(1,COUNTA('Flight Codes'!$G$6:$G$17)),1)
Name FlDate: Flights!$A$6:$A$1005
Name FlShift: Flights!$B$6:$B$1005
Name FlCode: Flights!$C$6:$C$1005
Name FlTime: Flights!$D$6:$D$1005
Name FlKey: Flights!$I$6:$I$1005
Name FlOrder: Flights!$J$6:$J$1005
Name FlSorties: Flights!$G$6:$G$1005
Name FlCount: Flights!$K$6:$K$1005
Name FlHrs: Flights!$L$6:$L$1005
Name DayStat: 'Day Status'!$C$6:$C$402
Name GrDate: 'Ground Programme'!$A$6:$A$505
Name GrAct: 'Ground Programme'!$C$6:$C$505

Sheet Dashboard
A1: MASTER PLANNER
A2: The master list of planned flights for every department. | Z2: LODESTAR master layout 2
A4: YEAR | G4: FILE
A5: 2026 | G5: Master Planner
A7: Month | B7: Planned sorties | C7: Flights | D7: Planned hrs
A8: January | B8: ='Jan'!E3 | C8: ='Jan'!I3 | D8: ='Jan'!L3 | F8: HOW IT WORKS
A9: February | B9: ='Feb'!E3 | C9: ='Feb'!I3 | D9: ='Feb'!L3 | F9: 1. Flights sheet: the master list, one flight per row (date, AM / PM / NIGHT, flight code, time, comment). Any number of flights per shift.
A10: March | B10: ='Mar'!E3 | C10: ='Mar'!I3 | D10: ='Mar'!L3 | F10: 2. Easiest is the Master Planning tab in the planner dashboard: + Add flight under a shift, x to remove one.
A11: April | B11: ='Apr'!E3 | C11: ='Apr'!I3 | D11: ='Apr'!L3 | F11: 3. Crew comes from the flight code (Flight Codes sheet, column E: P Pilot, L Loadmaster, T TACCO, S1 SUP 1, S2 SUP 2; blank = everyone).
A12: May | B12: ='May'!E3 | C12: ='May'!I3 | D12: ='May'!L3 | F12: Type a crew on a flight only when it differs from its code. Departments only get the flights that need them.
A13: June | B13: ='Jun'!E3 | C13: ='Jun'!I3 | D13: ='Jun'!L3 | F13: 4. No flying on a day: pick a reason on the Day Status sheet (or in the dashboard). The day turns grey and departments see NO FLY.
A14: July | B14: ='Jul'!E3 | C14: ='Jul'!I3 | D14: ='Jul'!L3 | F14: 5. Jan to Dec tabs (and Jan (next year), for planning January while still in December): a calendar view of the lists, with each day's sorties. View only.
A15: August | B15: ='Aug'!E3 | C15: ='Aug'!I3 | D15: ='Aug'!L3 | F15: 6. Departments take their flights from here: in the planner dashboard, open your department file with the Master Planner and click 'Copy flights from the Master Planner'.
A16: September | B16: ='Sep'!E3 | C16: ='Sep'!I3 | D16: ='Sep'!L3
A17: October | B17: ='Oct'!E3 | C17: ='Oct'!I3 | D17: ='Oct'!L3
A18: November | B18: ='Nov'!E3 | C18: ='Nov'!I3 | D18: ='Nov'!L3
A19: December | B19: ='Dec'!E3 | C19: ='Dec'!I3 | D19: ='Dec'!L3
A20: Total | B20: =SUM(B8:B19) | C20: =SUM(C8:C19) | D20: =SUM(D8:D19)
A21: Jan (next year) | B21: ='Jan (next year)'!E3 | C21: ='Jan (next year)'!I3 | D21: ='Jan (next year)'!L3

Sheet Flights
A1: FLIGHTS
A2: The master list: one flight per row, any number per shift. Add flights in the empty rows (or with + Add flight in the planner dashboard). Crew blank = the code's crew.
A3: Sort or filter as you like. To remove a flight, clear its row. Grey columns fill in by themselves.
A5: Date | B5: Shift | C5: Flight code | D5: Time | E5: Crew (only if different) | F5: Comment | G5: Sorties | H5: Crew used | I5: Key | J5: Order | K5: Counts | L5: Hrs
A6: 46296 | B6: AM | C6: 2xFLT-2.0 | D6: 0830-1030 | F6: Formation lead VIPER | G6: =IF(C6="","",IFERROR(VLOOKUP(C6,CodeTable,3,0),1)) | H6: =IF(C6="","",IF(E6<>"",E6,IF(IFERROR(VLOOKUP(C6,CodeTable,5,0)&"","")="","All",VLOOKUP(C6,CodeTable,5,0)&""))) | I6: =IF(OR(A6="",C6=""),"",A6&"|"&B6&"|"&(COUNTIFS(FlDate,A6,FlShift,B6,FlCode,"<>",FlOrder,"<"&J6)+COUNTIFS(A$6:A6,A6,B$6:B6,B6,C$6:C6,"<>",J$6:J6,J6))) | J6: =IF(C6="","",IF(D6="","zz","t"&D6)) | K6: =IF(OR(A6="",C6=""),"",IF(IFERROR(INDEX(DayStat,A6-DATE(PlanYear,1,1)+1)&"","")<>"",0,1)) | L6: =IF(K6="","",K6*IFERROR(VLOOKUP(C6,CodeTable,4,0),0))
A7: 46296 | B7: AM | C7: FLT-1.5 | D7: 0900-1030 | G7: =IF(C7="","",IFERROR(VLOOKUP(C7,CodeTable,3,0),1)) | H7: =IF(C7="","",IF(E7<>"",E7,IF(IFERROR(VLOOKUP(C7,CodeTable,5,0)&"","")="","All",VLOOKUP(C7,CodeTable,5,0)&""))) | I7: =IF(OR(A7="",C7=""),"",A7&"|"&B7&"|"&(COUNTIFS(FlDate,A7,FlShift,B7,FlCode,"<>",FlOrder,"<"&J7)+COUNTIFS(A$6:A7,A7,B$6:B7,B7,C$6:C7,"<>",J$6:J7,J7))) | J7: =IF(C7="","",IF(D7="","zz","t"&D7)) | K7: =IF(OR(A7="",C7=""),"",IF(IFERROR(INDEX(DayStat,A7-DATE(PlanYear,1,1)+1)&"","")<>"",0,1)) | L7: =IF(K7="","",K7*IFERROR(VLOOKUP(C7,CodeTable,4,0),0))
A8: 46296 | B8: PM | C8: FLT-2.0 | D8: 1400-1600 | G8: =IF(C8="","",IFERROR(VLOOKUP(C8,CodeTable,3,0),1)) | H8: =IF(C8="","",IF(E8<>"",E8,IF(IFERROR(VLOOKUP(C8,CodeTable,5,0)&"","")="","All",VLOOKUP(C8,CodeTable,5,0)&""))) | I8: =IF(OR(A8="",C8=""),"",A8&"|"&B8&"|"&(COUNTIFS(FlDate,A8,FlShift,B8,FlCode,"<>",FlOrder,"<"&J8)+COUNTIFS(A$6:A8,A8,B$6:B8,B8,C$6:C8,"<>",J$6:J8,J8))) | J8: =IF(C8="","",IF(D8="","zz","t"&D8)) | K8: =IF(OR(A8="",C8=""),"",IF(IFERROR(INDEX(DayStat,A8-DATE(PlanYear,1,1)+1)&"","")<>"",0,1)) | L8: =IF(K8="","",K8*IFERROR(VLOOKUP(C8,CodeTable,4,0),0))
A9: 46296 | B9: PM | C9: FLT-1.5 | D9: 1530-1700 | G9: =IF(C9="","",IFERROR(VLOOKUP(C9,CodeTable,3,0),1)) | H9: =IF(C9="","",IF(E9<>"",E9,IF(IFERROR(VLOOKUP(C9,CodeTable,5,0)&"","")="","All",VLOOKUP(C9,CodeTable,5,0)&""))) | I9: =IF(OR(A9="",C9=""),"",A9&"|"&B9&"|"&(COUNTIFS(FlDate,A9,FlShift,B9,FlCode,"<>",FlOrder,"<"&J9)+COUNTIFS(A$6:A9,A9,B$6:B9,B9,C$6:C9,"<>",J$6:J9,J9))) | J9: =IF(C9="","",IF(D9="","zz","t"&D9)) | K9: =IF(OR(A9="",C9=""),"",IF(IFERROR(INDEX(DayStat,A9-DATE(PlanYear,1,1)+1)&"","")<>"",0,1)) | L9: =IF(K9="","",K9*IFERROR(VLOOKUP(C9,CodeTable,4,0),0))
A10: 46296 | B10: PM | C10: FLT-2.0 | D10: 1600-1800 | F10: Ferry back | G10: =IF(C10="","",IFERROR(VLOOKUP(C10,CodeTable,3,0),1)) | H10: =IF(C10="","",IF(E10<>"",E10,IF(IFERROR(VLOOKUP(C10,CodeTable,5,0)&"","")="","All",VLOOKUP(C10,CodeTable,5,0)&""))) | I10: =IF(OR(A10="",C10=""),"",A10&"|"&B10&"|"&(COUNTIFS(FlDate,A10,FlShift,B10,FlCode,"<>",FlOrder,"<"&J10)+COUNTIFS(A$6:A10,A10,B$6:B10,B10,C$6:C10,"<>",J$6:J10,J10))) | J10: =IF(C10="","",IF(D10="","zz","t"&D10)) | K10: =IF(OR(A10="",C10=""),"",IF(IFERROR(INDEX(DayStat,A10-DATE(PlanYear,1,1)+1)&"","")<>"",0,1)) | L10: =IF(K10="","",K10*IFERROR(VLOOKUP(C10,CodeTable,4,0),0))
A11: 46297 | B11: AM | C11: FLT-1.5 | D11: 0800-0930 | G11: =IF(C11="","",IFERROR(VLOOKUP(C11,CodeTable,3,0),1)) | H11: =IF(C11="","",IF(E11<>"",E11,IF(IFERROR(VLOOKUP(C11,CodeTable,5,0)&"","")="","All",VLOOKUP(C11,CodeTable,5,0)&""))) | I11: =IF(OR(A11="",C11=""),"",A11&"|"&B11&"|"&(COUNTIFS(FlDate,A11,FlShift,B11,FlCode,"<>",FlOrder,"<"&J11)+COUNTIFS(A$6:A11,A11,B$6:B11,B11,C$6:C11,"<>",J$6:J11,J11))) | J11: =IF(C11="","",IF(D11="","zz","t"&D11)) | K11: =IF(OR(A11="",C11=""),"",IF(IFERROR(INDEX(DayStat,A11-DATE(PlanYear,1,1)+1)&"","")<>"",0,1)) | L11: =IF(K11="","",K11*IFERROR(VLOOKUP(C11,CodeTable,4,0),0))
A12: 46297 | B12: AM | C12: FLT-2.0 | D12: 1000-1200 | G12: =IF(C12="","",IFERROR(VLOOKUP(C12,CodeTable,3,0),1)) | H12: =IF(C12="","",IF(E12<>"",E12,IF(IFERROR(VLOOKUP(C12,CodeTable,5,0)&"","")="","All",VLOOKUP(C12,CodeTable,5,0)&""))) | I12: =IF(OR(A12="",C12=""),"",A12&"|"&B12&"|"&(COUNTIFS(FlDate,A12,FlShift,B12,FlCode,"<>",FlOrder,"<"&J12)+COUNTIFS(A$6:A12,A12,B$6:B12,B12,C$6:C12,"<>",J$6:J12,J12))) | J12: =IF(C12="","",IF(D12="","zz","t"&D12)) | K12: =IF(OR(A12="",C12=""),"",IF(IFERROR(INDEX(DayStat,A12-DATE(PlanYear,1,1)+1)&"","")<>"",0,1)) | L12: =IF(K12="","",K12*IFERROR(VLOOKUP(C12,CodeTable,4,0),0))
A13: 46297 | B13: PM | C13: FLT-2.0 | D13: 1330 | G13: =IF(C13="","",IFERROR(VLOOKUP(C13,CodeTable,3,0),1)) | H13: =IF(C13="","",IF(E13<>"",E13,IF(IFERROR(VLOOKUP(C13,CodeTable,5,0)&"","")="","All",VLOOKUP(C13,CodeTable,5,0)&""))) | I13: =IF(OR(A13="",C13=""),"",A13&"|"&B13&"|"&(COUNTIFS(FlDate,A13,FlShift,B13,FlCode,"<>",FlOrder,"<"&J13)+COUNTIFS(A$6:A13,A13,B$6:B13,B13,C$6:C13,"<>",J$6:J13,J13))) | J13: =IF(C13="","",IF(D13="","zz","t"&D13)) | K13: =IF(OR(A13="",C13=""),"",IF(IFERROR(INDEX(DayStat,A13-DATE(PlanYear,1,1)+1)&"","")<>"",0,1)) | L13: =IF(K13="","",K13*IFERROR(VLOOKUP(C13,CodeTable,4,0),0))
A14: 46297 | B14: NIGHT | C14: NVG-2.0 | D14: 2000-2200 | G14: =IF(C14="","",IFERROR(VLOOKUP(C14,CodeTable,3,0),1)) | H14: =IF(C14="","",IF(E14<>"",E14,IF(IFERROR(VLOOKUP(C14,CodeTable,5,0)&"","")="","All",VLOOKUP(C14,CodeTable,5,0)&""))) | I14: =IF(OR(A14="",C14=""),"",A14&"|"&B14&"|"&(COUNTIFS(FlDate,A14,FlShift,B14,FlCode,"<>",FlOrder,"<"&J14)+COUNTIFS(A$6:A14,A14,B$6:B14,B14,C$6:C14,"<>",J$6:J14,J14))) | J14: =IF(C14="","",IF(D14="","zz","t"&D14)) | K14: =IF(OR(A14="",C14=""),"",IF(IFERROR(INDEX(DayStat,A14-DATE(PlanYear,1,1)+1)&"","")<>"",0,1)) | L14: =IF(K14="","",K14*IFERROR(VLOOKUP(C14,CodeTable,4,0),0))
A15: 46300 | B15: AM | C15: FLT-2.0 | D15: 0830 | G15: =IF(C15="","",IFERROR(VLOOKUP(C15,CodeTable,3,0),1)) | H15: =IF(C15="","",IF(E15<>"",E15,IF(IFERROR(VLOOKUP(C15,CodeTable,5,0)&"","")="","All",VLOOKUP(C15,CodeTable,5,0)&""))) | I15: =IF(OR(A15="",C15=""),"",A15&"|"&B15&"|"&(COUNTIFS(FlDate,A15,FlShift,B15,FlCode,"<>",FlOrder,"<"&J15)+COUNTIFS(A$6:A15,A15,B$6:B15,B15,C$6:C15,"<>",J$6:J15,J15))) | J15: =IF(C15="","",IF(D15="","zz","t"&D15)) | K15: =IF(OR(A15="",C15=""),"",IF(IFERROR(INDEX(DayStat,A15-DATE(PlanYear,1,1)+1)&"","")<>"",0,1)) | L15: =IF(K15="","",K15*IFERROR(VLOOKUP(C15,CodeTable,4,0),0))
A16: 46300 | B16: AM | C16: FLT-1.5 | D16: TBC | F16: Wx dependent | G16: =IF(C16="","",IFERROR(VLOOKUP(C16,CodeTable,3,0),1)) | H16: =IF(C16="","",IF(E16<>"",E16,IF(IFERROR(VLOOKUP(C16,CodeTable,5,0)&"","")="","All",VLOOKUP(C16,CodeTable,5,0)&""))) | I16: =IF(OR(A16="",C16=""),"",A16&"|"&B16&"|"&(COUNTIFS(FlDate,A16,FlShift,B16,FlCode,"<>",FlOrder,"<"&J16)+COUNTIFS(A$6:A16,A16,B$6:B16,B16,C$6:C16,"<>",J$6:J16,J16))) | J16: =IF(C16="","",IF(D16="","zz","t"&D16)) | K16: =IF(OR(A16="",C16=""),"",IF(IFERROR(INDEX(DayStat,A16-DATE(PlanYear,1,1)+1)&"","")<>"",0,1)) | L16: =IF(K16="","",K16*IFERROR(VLOOKUP(C16,CodeTable,4,0),0))
A17: 46300 | B17: NIGHT | C17: NVG-2.0 | D17: 1930-2130 | G17: =IF(C17="","",IFERROR(VLOOKUP(C17,CodeTable,3,0),1)) | H17: =IF(C17="","",IF(E17<>"",E17,IF(IFERROR(VLOOKUP(C17,CodeTable,5,0)&"","")="","All",VLOOKUP(C17,CodeTable,5,0)&""))) | I17: =IF(OR(A17="",C17=""),"",A17&"|"&B17&"|"&(COUNTIFS(FlDate,A17,FlShift,B17,FlCode,"<>",FlOrder,"<"&J17)+COUNTIFS(A$6:A17,A17,B$6:B17,B17,C$6:C17,"<>",J$6:J17,J17))) | J17: =IF(C17="","",IF(D17="","zz","t"&D17)) | K17: =IF(OR(A17="",C17=""),"",IF(IFERROR(INDEX(DayStat,A17-DATE(PlanYear,1,1)+1)&"","")<>"",0,1)) | L17: =IF(K17="","",K17*IFERROR(VLOOKUP(C17,CodeTable,4,0),0))
A18: 46301 | B18: PM | C18: FLT-3.0 | D18: 1300-1600 | E18: P L | G18: =IF(C18="","",IFERROR(VLOOKUP(C18,CodeTable,3,0),1)) | H18: =IF(C18="","",IF(E18<>"",E18,IF(IFERROR(VLOOKUP(C18,CodeTable,5,0)&"","")="","All",VLOOKUP(C18,CodeTable,5,0)&""))) | I18: =IF(OR(A18="",C18=""),"",A18&"|"&B18&"|"&(COUNTIFS(FlDate,A18,FlShift,B18,FlCode,"<>",FlOrder,"<"&J18)+COUNTIFS(A$6:A18,A18,B$6:B18,B18,C$6:C18,"<>",J$6:J18,J18))) | J18: =IF(C18="","",IF(D18="","zz","t"&D18)) | K18: =IF(OR(A18="",C18=""),"",IF(IFERROR(INDEX(DayStat,A18-DATE(PlanYear,1,1)+1)&"","")<>"",0,1)) | L18: =IF(K18="","",K18*IFERROR(VLOOKUP(C18,CodeTable,4,0),0))
A19: 46302 | B19: AM | C19: FLT-2.0 | D19: 0830-1030 | F19: Need 2nd crew | G19: =IF(C19="","",IFERROR(VLOOKUP(C19,CodeTable,3,0),1)) | H19: =IF(C19="","",IF(E19<>"",E19,IF(IFERROR(VLOOKUP(C19,CodeTable,5,0)&"","")="","All",VLOOKUP(C19,CodeTable,5,0)&""))) | I19: =IF(OR(A19="",C19=""),"",A19&"|"&B19&"|"&(COUNTIFS(FlDate,A19,FlShift,B19,FlCode,"<>",FlOrder,"<"&J19)+COUNTIFS(A$6:A19,A19,B$6:B19,B19,C$6:C19,"<>",J$6:J19,J19))) | J19: =IF(C19="","",IF(D19="","zz","t"&D19)) | K19: =IF(OR(A19="",C19=""),"",IF(IFERROR(INDEX(DayStat,A19-DATE(PlanYear,1,1)+1)&"","")<>"",0,1)) | L19: =IF(K19="","",K19*IFERROR(VLOOKUP(C19,CodeTable,4,0),0))
A20: 46302 | B20: AM | C20: FLT-1.5 | D20: 1100 | G20: =IF(C20="","",IFERROR(VLOOKUP(C20,CodeTable,3,0),1)) | H20: =IF(C20="","",IF(E20<>"",E20,IF(IFERROR(VLOOKUP(C20,CodeTable,5,0)&"","")="","All",VLOOKUP(C20,CodeTable,5,0)&""))) | I20: =IF(OR(A20="",C20=""),"",A20&"|"&B20&"|"&(COUNTIFS(FlDate,A20,FlShift,B20,FlCode,"<>",FlOrder,"<"&J20)+COUNTIFS(A$6:A20,A20,B$6:B20,B20,C$6:C20,"<>",J$6:J20,J20))) | J20: =IF(C20="","",IF(D20="","zz","t"&D20)) | K20: =IF(OR(A20="",C20=""),"",IF(IFERROR(INDEX(DayStat,A20-DATE(PlanYear,1,1)+1)&"","")<>"",0,1)) | L20: =IF(K20="","",K20*IFERROR(VLOOKUP(C20,CodeTable,4,0),0))
A21: 46303 | B21: AM | C21: FLT-2.0 | D21: 0900-1100 | E21: P T | F21: Exercise | G21: =IF(C21="","",IFERROR(VLOOKUP(C21,CodeTable,3,0),1)) | H21: =IF(C21="","",IF(E21<>"",E21,IF(IFERROR(VLOOKUP(C21,CodeTable,5,0)&"","")="","All",VLOOKUP(C21,CodeTable,5,0)&""))) | I21: =IF(OR(A21="",C21=""),"",A21&"|"&B21&"|"&(COUNTIFS(FlDate,A21,FlShift,B21,FlCode,"<>",FlOrder,"<"&J21)+COUNTIFS(A$6:A21,A21,B$6:B21,B21,C$6:C21,"<>",J$6:J21,J21))) | J21: =IF(C21="","",IF(D21="","zz","t"&D21)) | K21: =IF(OR(A21="",C21=""),"",IF(IFERROR(INDEX(DayStat,A21-DATE(PlanYear,1,1)+1)&"","")<>"",0,1)) | L21: =IF(K21="","",K21*IFERROR(VLOOKUP(C21,CodeTable,4,0),0))
A22: 46307 | B22: AM | C22: FLT-2.0 | D22: 0830-1030 | G22: =IF(C22="","",IFERROR(VLOOKUP(C22,CodeTable,3,0),1)) | H22: =IF(C22="","",IF(E22<>"",E22,IF(IFERROR(VLOOKUP(C22,CodeTable,5,0)&"","")="","All",VLOOKUP(C22,CodeTable,5,0)&""))) | I22: =IF(OR(A22="",C22=""),"",A22&"|"&B22&"|"&(COUNTIFS(FlDate,A22,FlShift,B22,FlCode,"<>",FlOrder,"<"&J22)+COUNTIFS(A$6:A22,A22,B$6:B22,B22,C$6:C22,"<>",J$6:J22,J22))) | J22: =IF(C22="","",IF(D22="","zz","t"&D22)) | K22: =IF(OR(A22="",C22=""),"",IF(IFERROR(INDEX(DayStat,A22-DATE(PlanYear,1,1)+1)&"","")<>"",0,1)) | L22: =IF(K22="","",K22*IFERROR(VLOOKUP(C22,CodeTable,4,0),0))
A23: 46307 | B23: PM | C23: FLT-1.5 | D23: 1400-1530 | G23: =IF(C23="","",IFERROR(VLOOKUP(C23,CodeTable,3,0),1)) | H23: =IF(C23="","",IF(E23<>"",E23,IF(IFERROR(VLOOKUP(C23,CodeTable,5,0)&"","")="","All",VLOOKUP(C23,CodeTable,5,0)&""))) | I23: =IF(OR(A23="",C23=""),"",A23&"|"&B23&"|"&(COUNTIFS(FlDate,A23,FlShift,B23,FlCode,"<>",FlOrder,"<"&J23)+COUNTIFS(A$6:A23,A23,B$6:B23,B23,C$6:C23,"<>",J$6:J23,J23))) | J23: =IF(C23="","",IF(D23="","zz","t"&D23)) | K23: =IF(OR(A23="",C23=""),"",IF(IFERROR(INDEX(DayStat,A23-DATE(PlanYear,1,1)+1)&"","")<>"",0,1)) | L23: =IF(K23="","",K23*IFERROR(VLOOKUP(C23,CodeTable,4,0),0))
A24: 46308 | B24: NIGHT | C24: NVG-2.0 | D24: 2000-2200 | E24: P S2 | G24: =IF(C24="","",IFERROR(VLOOKUP(C24,CodeTable,3,0),1)) | H24: =IF(C24="","",IF(E24<>"",E24,IF(IFERROR(VLOOKUP(C24,CodeTable,5,0)&"","")="","All",VLOOKUP(C24,CodeTable,5,0)&""))) | I24: =IF(OR(A24="",C24=""),"",A24&"|"&B24&"|"&(COUNTIFS(FlDate,A24,FlShift,B24,FlCode,"<>",FlOrder,"<"&J24)+COUNTIFS(A$6:A24,A24,B$6:B24,B24,C$6:C24,"<>",J$6:J24,J24))) | J24: =IF(C24="","",IF(D24="","zz","t"&D24)) | K24: =IF(OR(A24="",C24=""),"",IF(IFERROR(INDEX(DayStat,A24-DATE(PlanYear,1,1)+1)&"","")<>"",0,1)) | L24: =IF(K24="","",K24*IFERROR(VLOOKUP(C24,CodeTable,4,0),0))
A25: 46309 | B25: AM | C25: 2xFLT-1.5 | D25: 0800-1100 | F25: Check rides | G25: =IF(C25="","",IFERROR(VLOOKUP(C25,CodeTable,3,0),1)) | H25: =IF(C25="","",IF(E25<>"",E25,IF(IFERROR(VLOOKUP(C25,CodeTable,5,0)&"","")="","All",VLOOKUP(C25,CodeTable,5,0)&""))) | I25: =IF(OR(A25="",C25=""),"",A25&"|"&B25&"|"&(COUNTIFS(FlDate,A25,FlShift,B25,FlCode,"<>",FlOrder,"<"&J25)+COUNTIFS(A$6:A25,A25,B$6:B25,B25,C$6:C25,"<>",J$6:J25,J25))) | J25: =IF(C25="","",IF(D25="","zz","t"&D25)) | K25: =IF(OR(A25="",C25=""),"",IF(IFERROR(INDEX(DayStat,A25-DATE(PlanYear,1,1)+1)&"","")<>"",0,1)) | L25: =IF(K25="","",K25*IFERROR(VLOOKUP(C25,CodeTable,4,0),0))
A26: 46310 | B26: PM | C26: MSN-3.0 | D26: 1300-1600 | F26: Long range | G26: =IF(C26="","",IFERROR(VLOOKUP(C26,CodeTable,3,0),1)) | H26: =IF(C26="","",IF(E26<>"",E26,IF(IFERROR(VLOOKUP(C26,CodeTable,5,0)&"","")="","All",VLOOKUP(C26,CodeTable,5,0)&""))) | I26: =IF(OR(A26="",C26=""),"",A26&"|"&B26&"|"&(COUNTIFS(FlDate,A26,FlShift,B26,FlCode,"<>",FlOrder,"<"&J26)+COUNTIFS(A$6:A26,A26,B$6:B26,B26,C$6:C26,"<>",J$6:J26,J26))) | J26: =IF(C26="","",IF(D26="","zz","t"&D26)) | K26: =IF(OR(A26="",C26=""),"",IF(IFERROR(INDEX(DayStat,A26-DATE(PlanYear,1,1)+1)&"","")<>"",0,1)) | L26: =IF(K26="","",K26*IFERROR(VLOOKUP(C26,CodeTable,4,0),0))
A27: 46315 | B27: AM | C27: PLT-TRG | D27: 0900-1030 | G27: =IF(C27="","",IFERROR(VLOOKUP(C27,CodeTable,3,0),1)) | H27: =IF(C27="","",IF(E27<>"",E27,IF(IFERROR(VLOOKUP(C27,CodeTable,5,0)&"","")="","All",VLOOKUP(C27,CodeTable,5,0)&""))) | I27: =IF(OR(A27="",C27=""),"",A27&"|"&B27&"|"&(COUNTIFS(FlDate,A27,FlShift,B27,FlCode,"<>",FlOrder,"<"&J27)+COUNTIFS(A$6:A27,A27,B$6:B27,B27,C$6:C27,"<>",J$6:J27,J27))) | J27: =IF(C27="","",IF(D27="","zz","t"&D27)) | K27: =IF(OR(A27="",C27=""),"",IF(IFERROR(INDEX(DayStat,A27-DATE(PlanYear,1,1)+1)&"","")<>"",0,1)) | L27: =IF(K27="","",K27*IFERROR(VLOOKUP(C27,CodeTable,4,0),0))
A28: 46316 | B28: AM | C28: FLT-2.0 | D28: 0830-1030 | G28: =IF(C28="","",IFERROR(VLOOKUP(C28,CodeTable,3,0),1)) | H28: =IF(C28="","",IF(E28<>"",E28,IF(IFERROR(VLOOKUP(C28,CodeTable,5,0)&"","")="","All",VLOOKUP(C28,CodeTable,5,0)&""))) | I28: =IF(OR(A28="",C28=""),"",A28&"|"&B28&"|"&(COUNTIFS(FlDate,A28,FlShift,B28,FlCode,"<>",FlOrder,"<"&J28)+COUNTIFS(A$6:A28,A28,B$6:B28,B28,C$6:C28,"<>",J$6:J28,J28))) | J28: =IF(C28="","",IF(D28="","zz","t"&D28)) | K28: =IF(OR(A28="",C28=""),"",IF(IFERROR(INDEX(DayStat,A28-DATE(PlanYear,1,1)+1)&"","")<>"",0,1)) | L28: =IF(K28="","",K28*IFERROR(VLOOKUP(C28,CodeTable,4,0),0))
A29: 46316 | B29: AM | C29: FLT-1.5 | D29: 1000-1130 | G29: =IF(C29="","",IFERROR(VLOOKUP(C29,CodeTable,3,0),1)) | H29: =IF(C29="","",IF(E29<>"",E29,IF(IFERROR(VLOOKUP(C29,CodeTable,5,0)&"","")="","All",VLOOKUP(C29,CodeTable,5,0)&""))) | I29: =IF(OR(A29="",C29=""),"",A29&"|"&B29&"|"&(COUNTIFS(FlDate,A29,FlShift,B29,FlCode,"<>",FlOrder,"<"&J29)+COUNTIFS(A$6:A29,A29,B$6:B29,B29,C$6:C29,"<>",J$6:J29,J29))) | J29: =IF(C29="","",IF(D29="","zz","t"&D29)) | K29: =IF(OR(A29="",C29=""),"",IF(IFERROR(INDEX(DayStat,A29-DATE(PlanYear,1,1)+1)&"","")<>"",0,1)) | L29: =IF(K29="","",K29*IFERROR(VLOOKUP(C29,CodeTable,4,0),0))
A30: 46316 | B30: PM | C30: MSN-3.0 | D30: 1300-1600 | F30: Long range | G30: =IF(C30="","",IFERROR(VLOOKUP(C30,CodeTable,3,0),1)) | H30: =IF(C30="","",IF(E30<>"",E30,IF(IFERROR(VLOOKUP(C30,CodeTable,5,0)&"","")="","All",VLOOKUP(C30,CodeTable,5,0)&""))) | I30: =IF(OR(A30="",C30=""),"",A30&"|"&B30&"|"&(COUNTIFS(FlDate,A30,FlShift,B30,FlCode,"<>",FlOrder,"<"&J30)+COUNTIFS(A$6:A30,A30,B$6:B30,B30,C$6:C30,"<>",J$6:J30,J30))) | J30: =IF(C30="","",IF(D30="","zz","t"&D30)) | K30: =IF(OR(A30="",C30=""),"",IF(IFERROR(INDEX(DayStat,A30-DATE(PlanYear,1,1)+1)&"","")<>"",0,1)) | L30: =IF(K30="","",K30*IFERROR(VLOOKUP(C30,CodeTable,4,0),0))
A31: 46317 | B31: AM | C31: FLT-3.0 | D31: 0800-1100 | G31: =IF(C31="","",IFERROR(VLOOKUP(C31,CodeTable,3,0),1)) | H31: =IF(C31="","",IF(E31<>"",E31,IF(IFERROR(VLOOKUP(C31,CodeTable,5,0)&"","")="","All",VLOOKUP(C31,CodeTable,5,0)&""))) | I31: =IF(OR(A31="",C31=""),"",A31&"|"&B31&"|"&(COUNTIFS(FlDate,A31,FlShift,B31,FlCode,"<>",FlOrder,"<"&J31)+COUNTIFS(A$6:A31,A31,B$6:B31,B31,C$6:C31,"<>",J$6:J31,J31))) | J31: =IF(C31="","",IF(D31="","zz","t"&D31)) | K31: =IF(OR(A31="",C31=""),"",IF(IFERROR(INDEX(DayStat,A31-DATE(PlanYear,1,1)+1)&"","")<>"",0,1)) | L31: =IF(K31="","",K31*IFERROR(VLOOKUP(C31,CodeTable,4,0),0))
A32: 46317 | B32: NIGHT | C32: NVG-2.0 | D32: 2000-2200 | G32: =IF(C32="","",IFERROR(VLOOKUP(C32,CodeTable,3,0),1)) | H32: =IF(C32="","",IF(E32<>"",E32,IF(IFERROR(VLOOKUP(C32,CodeTable,5,0)&"","")="","All",VLOOKUP(C32,CodeTable,5,0)&""))) | I32: =IF(OR(A32="",C32=""),"",A32&"|"&B32&"|"&(COUNTIFS(FlDate,A32,FlShift,B32,FlCode,"<>",FlOrder,"<"&J32)+COUNTIFS(A$6:A32,A32,B$6:B32,B32,C$6:C32,"<>",J$6:J32,J32))) | J32: =IF(C32="","",IF(D32="","zz","t"&D32)) | K32: =IF(OR(A32="",C32=""),"",IF(IFERROR(INDEX(DayStat,A32-DATE(PlanYear,1,1)+1)&"","")<>"",0,1)) | L32: =IF(K32="","",K32*IFERROR(VLOOKUP(C32,CodeTable,4,0),0))
A33: 46318 | B33: AM | C33: FLT-2.0 | D33: 0830-1030 | G33: =IF(C33="","",IFERROR(VLOOKUP(C33,CodeTable,3,0),1)) | H33: =IF(C33="","",IF(E33<>"",E33,IF(IFERROR(VLOOKUP(C33,CodeTable,5,0)&"","")="","All",VLOOKUP(C33,CodeTable,5,0)&""))) | I33: =IF(OR(A33="",C33=""),"",A33&"|"&B33&"|"&(COUNTIFS(FlDate,A33,FlShift,B33,FlCode,"<>",FlOrder,"<"&J33)+COUNTIFS(A$6:A33,A33,B$6:B33,B33,C$6:C33,"<>",J$6:J33,J33))) | J33: =IF(C33="","",IF(D33="","zz","t"&D33)) | K33: =IF(OR(A33="",C33=""),"",IF(IFERROR(INDEX(DayStat,A33-DATE(PlanYear,1,1)+1)&"","")<>"",0,1)) | L33: =IF(K33="","",K33*IFERROR(VLOOKUP(C33,CodeTable,4,0),0))
A34: 46318 | B34: AM | C34: FLT-1.5 | D34: 1000-1130 | G34: =IF(C34="","",IFERROR(VLOOKUP(C34,CodeTable,3,0),1)) | H34: =IF(C34="","",IF(E34<>"",E34,IF(IFERROR(VLOOKUP(C34,CodeTable,5,0)&"","")="","All",VLOOKUP(C34,CodeTable,5,0)&""))) | I34: =IF(OR(A34="",C34=""),"",A34&"|"&B34&"|"&(COUNTIFS(FlDate,A34,FlShift,B34,FlCode,"<>",FlOrder,"<"&J34)+COUNTIFS(A$6:A34,A34,B$6:B34,B34,C$6:C34,"<>",J$6:J34,J34))) | J34: =IF(C34="","",IF(D34="","zz","t"&D34)) | K34: =IF(OR(A34="",C34=""),"",IF(IFERROR(INDEX(DayStat,A34-DATE(PlanYear,1,1)+1)&"","")<>"",0,1)) | L34: =IF(K34="","",K34*IFERROR(VLOOKUP(C34,CodeTable,4,0),0))
A35: 46318 | B35: PM | C35: FLT-1.5 | D35: 1430-1600 | G35: =IF(C35="","",IFERROR(VLOOKUP(C35,CodeTable,3,0),1)) | H35: =IF(C35="","",IF(E35<>"",E35,IF(IFERROR(VLOOKUP(C35,CodeTable,5,0)&"","")="","All",VLOOKUP(C35,CodeTable,5,0)&""))) | I35: =IF(OR(A35="",C35=""),"",A35&"|"&B35&"|"&(COUNTIFS(FlDate,A35,FlShift,B35,FlCode,"<>",FlOrder,"<"&J35)+COUNTIFS(A$6:A35,A35,B$6:B35,B35,C$6:C35,"<>",J$6:J35,J35))) | J35: =IF(C35="","",IF(D35="","zz","t"&D35)) | K35: =IF(OR(A35="",C35=""),"",IF(IFERROR(INDEX(DayStat,A35-DATE(PlanYear,1,1)+1)&"","")<>"",0,1)) | L35: =IF(K35="","",K35*IFERROR(VLOOKUP(C35,CodeTable,4,0),0))
A36: 46321 | B36: AM | C36: FLT-2.0 | D36: 0830-1030 | G36: =IF(C36="","",IFERROR(VLOOKUP(C36,CodeTable,3,0),1)) | H36: =IF(C36="","",IF(E36<>"",E36,IF(IFERROR(VLOOKUP(C36,CodeTable,5,0)&"","")="","All",VLOOKUP(C36,CodeTable,5,0)&""))) | I36: =IF(OR(A36="",C36=""),"",A36&"|"&B36&"|"&(COUNTIFS(FlDate,A36,FlShift,B36,FlCode,"<>",FlOrder,"<"&J36)+COUNTIFS(A$6:A36,A36,B$6:B36,B36,C$6:C36,"<>",J$6:J36,J36))) | J36: =IF(C36="","",IF(D36="","zz","t"&D36)) | K36: =IF(OR(A36="",C36=""),"",IF(IFERROR(INDEX(DayStat,A36-DATE(PlanYear,1,1)+1)&"","")<>"",0,1)) | L36: =IF(K36="","",K36*IFERROR(VLOOKUP(C36,CodeTable,4,0),0))
A37: 46321 | B37: AM | C37: FLT-1.5 | D37: 1000-1130 | G37: =IF(C37="","",IFERROR(VLOOKUP(C37,CodeTable,3,0),1)) | H37: =IF(C37="","",IF(E37<>"",E37,IF(IFERROR(VLOOKUP(C37,CodeTable,5,0)&"","")="","All",VLOOKUP(C37,CodeTable,5,0)&""))) | I37: =IF(OR(A37="",C37=""),"",A37&"|"&B37&"|"&(COUNTIFS(FlDate,A37,FlShift,B37,FlCode,"<>",FlOrder,"<"&J37)+COUNTIFS(A$6:A37,A37,B$6:B37,B37,C$6:C37,"<>",J$6:J37,J37))) | J37: =IF(C37="","",IF(D37="","zz","t"&D37)) | K37: =IF(OR(A37="",C37=""),"",IF(IFERROR(INDEX(DayStat,A37-DATE(PlanYear,1,1)+1)&"","")<>"",0,1)) | L37: =IF(K37="","",K37*IFERROR(VLOOKUP(C37,CodeTable,4,0),0))
A38: 46321 | B38: PM | C38: MSN-3.0 | D38: 1300-1600 | F38: Long range | G38: =IF(C38="","",IFERROR(VLOOKUP(C38,CodeTable,3,0),1)) | H38: =IF(C38="","",IF(E38<>"",E38,IF(IFERROR(VLOOKUP(C38,CodeTable,5,0)&"","")="","All",VLOOKUP(C38,CodeTable,5,0)&""))) | I38: =IF(OR(A38="",C38=""),"",A38&"|"&B38&"|"&(COUNTIFS(FlDate,A38,FlShift,B38,FlCode,"<>",FlOrder,"<"&J38)+COUNTIFS(A$6:A38,A38,B$6:B38,B38,C$6:C38,"<>",J$6:J38,J38))) | J38: =IF(C38="","",IF(D38="","zz","t"&D38)) | K38: =IF(OR(A38="",C38=""),"",IF(IFERROR(INDEX(DayStat,A38-DATE(PlanYear,1,1)+1)&"","")<>"",0,1)) | L38: =IF(K38="","",K38*IFERROR(VLOOKUP(C38,CodeTable,4,0),0))
A39: 46322 | B39: AM | C39: FLT-2.0 | D39: 0830-1030 | G39: =IF(C39="","",IFERROR(VLOOKUP(C39,CodeTable,3,0),1)) | H39: =IF(C39="","",IF(E39<>"",E39,IF(IFERROR(VLOOKUP(C39,CodeTable,5,0)&"","")="","All",VLOOKUP(C39,CodeTable,5,0)&""))) | I39: =IF(OR(A39="",C39=""),"",A39&"|"&B39&"|"&(COUNTIFS(FlDate,A39,FlShift,B39,FlCode,"<>",FlOrder,"<"&J39)+COUNTIFS(A$6:A39,A39,B$6:B39,B39,C$6:C39,"<>",J$6:J39,J39))) | J39: =IF(C39="","",IF(D39="","zz","t"&D39)) | K39: =IF(OR(A39="",C39=""),"",IF(IFERROR(INDEX(DayStat,A39-DATE(PlanYear,1,1)+1)&"","")<>"",0,1)) | L39: =IF(K39="","",K39*IFERROR(VLOOKUP(C39,CodeTable,4,0),0))
A40: 46322 | B40: AM | C40: FLT-1.5 | D40: 1000-1130 | G40: =IF(C40="","",IFERROR(VLOOKUP(C40,CodeTable,3,0),1)) | H40: =IF(C40="","",IF(E40<>"",E40,IF(IFERROR(VLOOKUP(C40,CodeTable,5,0)&"","")="","All",VLOOKUP(C40,CodeTable,5,0)&""))) | I40: =IF(OR(A40="",C40=""),"",A40&"|"&B40&"|"&(COUNTIFS(FlDate,A40,FlShift,B40,FlCode,"<>",FlOrder,"<"&J40)+COUNTIFS(A$6:A40,A40,B$6:B40,B40,C$6:C40,"<>",J$6:J40,J40))) | J40: =IF(C40="","",IF(D40="","zz","t"&D40)) | K40: =IF(OR(A40="",C40=""),"",IF(IFERROR(INDEX(DayStat,A40-DATE(PlanYear,1,1)+1)&"","")<>"",0,1)) | L40: =IF(K40="","",K40*IFERROR(VLOOKUP(C40,CodeTable,4,0),0))
A41: 46322 | B41: NIGHT | C41: NVG-2.0 | D41: 2000-2200 | G41: =IF(C41="","",IFERROR(VLOOKUP(C41,CodeTable,3,0),1)) | H41: =IF(C41="","",IF(E41<>"",E41,IF(IFERROR(VLOOKUP(C41,CodeTable,5,0)&"","")="","All",VLOOKUP(C41,CodeTable,5,0)&""))) | I41: =IF(OR(A41="",C41=""),"",A41&"|"&B41&"|"&(COUNTIFS(FlDate,A41,FlShift,B41,FlCode,"<>",FlOrder,"<"&J41)+COUNTIFS(A$6:A41,A41,B$6:B41,B41,C$6:C41,"<>",J$6:J41,J41))) | J41: =IF(C41="","",IF(D41="","zz","t"&D41)) | K41: =IF(OR(A41="",C41=""),"",IF(IFERROR(INDEX(DayStat,A41-DATE(PlanYear,1,1)+1)&"","")<>"",0,1)) | L41: =IF(K41="","",K41*IFERROR(VLOOKUP(C41,CodeTable,4,0),0))
...

Sheet Day Status
A1: DAY STATUS
A2: Leave blank for a flying day. Pick a reason (No Flying, Stand-down, Maintenance ...) for a day with no flying: it greys out on the calendar and departments see NO FLY.
A5: Date | B5: Day | C5: Status
A6: =IF(DATE(PlanYear,1,1)+0<=DATE(PlanYear+1,1,31),DATE(PlanYear,1,1)+0,"") | B6: =IF(A6="","",TEXT(A6,"ddd"))
A7: =IF(DATE(PlanYear,1,1)+1<=DATE(PlanYear+1,1,31),DATE(PlanYear,1,1)+1,"") | B7: =IF(A7="","",TEXT(A7,"ddd"))
A8: =IF(DATE(PlanYear,1,1)+2<=DATE(PlanYear+1,1,31),DATE(PlanYear,1,1)+2,"") | B8: =IF(A8="","",TEXT(A8,"ddd"))
A9: =IF(DATE(PlanYear,1,1)+3<=DATE(PlanYear+1,1,31),DATE(PlanYear,1,1)+3,"") | B9: =IF(A9="","",TEXT(A9,"ddd"))
A10: =IF(DATE(PlanYear,1,1)+4<=DATE(PlanYear+1,1,31),DATE(PlanYear,1,1)+4,"") | B10: =IF(A10="","",TEXT(A10,"ddd"))
A11: =IF(DATE(PlanYear,1,1)+5<=DATE(PlanYear+1,1,31),DATE(PlanYear,1,1)+5,"") | B11: =IF(A11="","",TEXT(A11,"ddd"))
A12: =IF(DATE(PlanYear,1,1)+6<=DATE(PlanYear+1,1,31),DATE(PlanYear,1,1)+6,"") | B12: =IF(A12="","",TEXT(A12,"ddd"))
A13: =IF(DATE(PlanYear,1,1)+7<=DATE(PlanYear+1,1,31),DATE(PlanYear,1,1)+7,"") | B13: =IF(A13="","",TEXT(A13,"ddd"))
A14: =IF(DATE(PlanYear,1,1)+8<=DATE(PlanYear+1,1,31),DATE(PlanYear,1,1)+8,"") | B14: =IF(A14="","",TEXT(A14,"ddd"))
A15: =IF(DATE(PlanYear,1,1)+9<=DATE(PlanYear+1,1,31),DATE(PlanYear,1,1)+9,"") | B15: =IF(A15="","",TEXT(A15,"ddd"))
A16: =IF(DATE(PlanYear,1,1)+10<=DATE(PlanYear+1,1,31),DATE(PlanYear,1,1)+10,"") | B16: =IF(A16="","",TEXT(A16,"ddd"))
A17: =IF(DATE(PlanYear,1,1)+11<=DATE(PlanYear+1,1,31),DATE(PlanYear,1,1)+11,"") | B17: =IF(A17="","",TEXT(A17,"ddd"))
A18: =IF(DATE(PlanYear,1,1)+12<=DATE(PlanYear+1,1,31),DATE(PlanYear,1,1)+12,"") | B18: =IF(A18="","",TEXT(A18,"ddd"))
A19: =IF(DATE(PlanYear,1,1)+13<=DATE(PlanYear+1,1,31),DATE(PlanYear,1,1)+13,"") | B19: =IF(A19="","",TEXT(A19,"ddd"))
A20: =IF(DATE(PlanYear,1,1)+14<=DATE(PlanYear+1,1,31),DATE(PlanYear,1,1)+14,"") | B20: =IF(A20="","",TEXT(A20,"ddd"))
A21: =IF(DATE(PlanYear,1,1)+15<=DATE(PlanYear+1,1,31),DATE(PlanYear,1,1)+15,"") | B21: =IF(A21="","",TEXT(A21,"ddd"))
A22: =IF(DATE(PlanYear,1,1)+16<=DATE(PlanYear+1,1,31),DATE(PlanYear,1,1)+16,"") | B22: =IF(A22="","",TEXT(A22,"ddd"))
A23: =IF(DATE(PlanYear,1,1)+17<=DATE(PlanYear+1,1,31),DATE(PlanYear,1,1)+17,"") | B23: =IF(A23="","",TEXT(A23,"ddd"))
A24: =IF(DATE(PlanYear,1,1)+18<=DATE(PlanYear+1,1,31),DATE(PlanYear,1,1)+18,"") | B24: =IF(A24="","",TEXT(A24,"ddd"))
A25: =IF(DATE(PlanYear,1,1)+19<=DATE(PlanYear+1,1,31),DATE(PlanYear,1,1)+19,"") | B25: =IF(A25="","",TEXT(A25,"ddd"))
A26: =IF(DATE(PlanYear,1,1)+20<=DATE(PlanYear+1,1,31),DATE(PlanYear,1,1)+20,"") | B26: =IF(A26="","",TEXT(A26,"ddd"))
A27: =IF(DATE(PlanYear,1,1)+21<=DATE(PlanYear+1,1,31),DATE(PlanYear,1,1)+21,"") | B27: =IF(A27="","",TEXT(A27,"ddd"))
A28: =IF(DATE(PlanYear,1,1)+22<=DATE(PlanYear+1,1,31),DATE(PlanYear,1,1)+22,"") | B28: =IF(A28="","",TEXT(A28,"ddd"))
A29: =IF(DATE(PlanYear,1,1)+23<=DATE(PlanYear+1,1,31),DATE(PlanYear,1,1)+23,"") | B29: =IF(A29="","",TEXT(A29,"ddd"))
A30: =IF(DATE(PlanYear,1,1)+24<=DATE(PlanYear+1,1,31),DATE(PlanYear,1,1)+24,"") | B30: =IF(A30="","",TEXT(A30,"ddd"))
A31: =IF(DATE(PlanYear,1,1)+25<=DATE(PlanYear+1,1,31),DATE(PlanYear,1,1)+25,"") | B31: =IF(A31="","",TEXT(A31,"ddd"))
A32: =IF(DATE(PlanYear,1,1)+26<=DATE(PlanYear+1,1,31),DATE(PlanYear,1,1)+26,"") | B32: =IF(A32="","",TEXT(A32,"ddd"))
A33: =IF(DATE(PlanYear,1,1)+27<=DATE(PlanYear+1,1,31),DATE(PlanYear,1,1)+27,"") | B33: =IF(A33="","",TEXT(A33,"ddd"))
A34: =IF(DATE(PlanYear,1,1)+28<=DATE(PlanYear+1,1,31),DATE(PlanYear,1,1)+28,"") | B34: =IF(A34="","",TEXT(A34,"ddd"))
A35: =IF(DATE(PlanYear,1,1)+29<=DATE(PlanYear+1,1,31),DATE(PlanYear,1,1)+29,"") | B35: =IF(A35="","",TEXT(A35,"ddd"))
A36: =IF(DATE(PlanYear,1,1)+30<=DATE(PlanYear+1,1,31),DATE(PlanYear,1,1)+30,"") | B36: =IF(A36="","",TEXT(A36,"ddd"))
A37: =IF(DATE(PlanYear,1,1)+31<=DATE(PlanYear+1,1,31),DATE(PlanYear,1,1)+31,"") | B37: =IF(A37="","",TEXT(A37,"ddd"))
A38: =IF(DATE(PlanYear,1,1)+32<=DATE(PlanYear+1,1,31),DATE(PlanYear,1,1)+32,"") | B38: =IF(A38="","",TEXT(A38,"ddd"))
A39: =IF(DATE(PlanYear,1,1)+33<=DATE(PlanYear+1,1,31),DATE(PlanYear,1,1)+33,"") | B39: =IF(A39="","",TEXT(A39,"ddd"))
A40: =IF(DATE(PlanYear,1,1)+34<=DATE(PlanYear+1,1,31),DATE(PlanYear,1,1)+34,"") | B40: =IF(A40="","",TEXT(A40,"ddd"))
A41: =IF(DATE(PlanYear,1,1)+35<=DATE(PlanYear+1,1,31),DATE(PlanYear,1,1)+35,"") | B41: =IF(A41="","",TEXT(A41,"ddd"))
A42: =IF(DATE(PlanYear,1,1)+36<=DATE(PlanYear+1,1,31),DATE(PlanYear,1,1)+36,"") | B42: =IF(A42="","",TEXT(A42,"ddd"))
...

Sheet Ground Programme
A1: GROUND PROGRAMME
A2: Ground events for the office: lectures, briefs, sim, meetings. One per row, any number per day. Crew blank = everyone; or tags P L T S1 S2.
A5: Date | B5: Time | C5: Activity | D5: Crew (blank = all) | E5: Comment
A6: 46296 | B6: 0730-0800 | C6: Safety Brief | E6: Monthly safety brief
A7: 46302 | B7: 1400-1600 | C7: CRM Lecture | D7: S1 S2
A8: 46304 | B8: 0900-1200 | C8: Ground School | E8: While the aircraft are in maintenance
A9: 46309 | B9: 1500 | C9: Sqn Meeting
A10: 46317 | B10: 1400-1600 | C10: CRM Lecture | D10: P T
A11: 46323 | B11: 1500 | C11: Sqn Meeting
A12: 46328 | B12: 0730-0800 | C12: Safety Brief | E12: Monthly safety brief
A13: 46337 | B13: 0900-1200 | C13: Ground School | D13: L S1 S2 | E13: Sonobuoy refresher
A14: 46344 | B14: 1500 | C14: Sqn Meeting
A15: 46352 | B15: 1400-1600 | C15: CRM Lecture

Sheet Requests
A1: REQUESTS FROM DEPARTMENTS
A2: Answered in the dashboard (Master Planning, Requests inbox). Done or Declined with a reply; the department sees it.
A5: Dept | B5: Request ID | C5: Status | D5: Reply | E5: Answered on | F5: Request
A6: SUP 2 | B6: S2-SAMPLE2 | C6: Declined | D6: Range is booked 0800-1000, keep 0830 | E6: 46297 | F6: Raised Thu, 1 Oct: Can Friday's AM flight start 0900 instead? Ground school runs late

Sheet Flight Codes
A1: FLIGHT CODES
A2: The flights programme: every flight code the squadron uses. Departments copy this list into their Activities sheet in the planner dashboard. Crew = the departments that fly this code (blank = every department). Mission Type is used by the currency rules.
H4: e.g. EIS, MAS Tact
A5: Code | B5: Description | C5: Sorties | D5: Flight Hrs | E5: Crew | F5: Mission Type | G5: Day status (no flying) | H5: Syllabus tag | I5: Ground programme
A6: FLT-1.5 | B6: Routine Sortie (1.5h) | C6: 1 | D6: 1.5 | F6: GEN | G6: No Flying | I6: Ground School
A7: FLT-2.0 | B7: Standard Sortie (2.0h) | C7: 1 | D7: 2 | F7: GEN | G7: Stand-down | I7: Safety Brief
A8: FLT-3.0 | B8: Extended Mission (3.0h) | C8: 1 | D8: 3 | F8: GEN | G8: Maintenance | I8: CRM Lecture
A9: NVG-2.0 | B9: Night Flying Sortie (2.0h) | C9: 1 | D9: 2 | F9: NIGHT | G9: Public Holiday | I9: Sim Training
A10: 2xFLT-1.5 | B10: Two routine sorties in one shift | C10: 2 | D10: 3 | F10: GEN | I10: Sqn Meeting
A11: 2xFLT-2.0 | B11: Two standard sorties in one shift | C11: 2 | D11: 4 | F11: GEN | I11: Admin Day
A12: MSN-3.0 | B12: Mission sortie: Pilot, TACCO, SUP 2 (3.0h) | C12: 1 | D12: 3 | E12: P T S2 | F12: MSN | I12: Fitness / IPPT
A13: PLT-TRG | B13: Pilot training sortie (1.5h) | C13: 1 | D13: 1.5 | E13: P | F13: TRG | I13: Medical
A14: EIS | B14: EIS training sortie (2.0h) | C14: 1 | D14: 2 | E14: S2 | F14: TRG | H14: EIS
A15: MAS TRG | B15: MAS tactical training (3.0h) | C15: 1 | D15: 3 | E15: S2 | F15: TRG | H15: MAS Tact
G19: Add your own reasons in the empty rows.
I26: The ground programme list (any text is allowed too).

Sheet Jan
A1: ="MASTER PLANNER | JANUARY "&(PlanYear+0)
A2: View only: built from the Flights and Day Status sheets. Shows up to 3 flights per shift; more show as '+n more'. Plan on the Flights sheet or in the planner dashboard.
B3: Planned sorties this month | E3: =N(D5)+N(G5)+N(J5)+N(M5)+N(P5)+N(S5)+N(V5)+N(D16)+N(G16)+N(J16)+N(M16)+N(P16)+N(S16)+N(V16)+N(D27)+N(G27)+N(J27)+N(M27)+N(P27)+N(S27)+N(V27)+N(D38)+N(G38)+N(J38)+N(M38)+N(P38)+N(S38)+N(V38)+N(D49)+N(G49)+N(J49)+N(M49)+N(P49)+N(S49)+N(V49)+N(D60)+N(G60)+N(J60)+N(M60)+N(P60)+N(S60)+N(V60) | G3: Flights | I3: =SUMIFS(FlCount,FlDate,">="&DATE(PlanYear,1,1),FlDate,"<="&EOMONTH(DATE(PlanYear,1,1),0)) | J3: Planned flying hrs | L3: =SUMIFS(FlHrs,FlDate,">="&DATE(PlanYear,1,1),FlDate,"<="&EOMONTH(DATE(PlanYear,1,1),0)) | N3: To add, change or remove a flight: use the Flights sheet, or the Master Planning tab in the planner dashboard.
B4: MON | E4: TUE | H4: WED | K4: THU | N4: FRI | Q4: SAT | T4: SUN
B5: =IF(MONTH(DATE(PlanYear,1,1)-WEEKDAY(DATE(PlanYear,1,1),3)+0)=1,DATE(PlanYear,1,1)-WEEKDAY(DATE(PlanYear,1,1),3)+0,"") | D5: =IF($B$5="","",IF(IFERROR(INDEX(DayStat,$B$5-DATE(PlanYear,1,1)+1)&"","")<>"",0,SUMIFS(FlSorties,FlDate,$B$5))) | E5: =IF(MONTH(DATE(PlanYear,1,1)-WEEKDAY(DATE(PlanYear,1,1),3)+1)=1,DATE(PlanYear,1,1)-WEEKDAY(DATE(PlanYear,1,1),3)+1,"") | G5: =IF($E$5="","",IF(IFERROR(INDEX(DayStat,$E$5-DATE(PlanYear,1,1)+1)&"","")<>"",0,SUMIFS(FlSorties,FlDate,$E$5))) | H5: =IF(MONTH(DATE(PlanYear,1,1)-WEEKDAY(DATE(PlanYear,1,1),3)+2)=1,DATE(PlanYear,1,1)-WEEKDAY(DATE(PlanYear,1,1),3)+2,"") | J5: =IF($H$5="","",IF(IFERROR(INDEX(DayStat,$H$5-DATE(PlanYear,1,1)+1)&"","")<>"",0,SUMIFS(FlSorties,FlDate,$H$5))) | K5: =IF(MONTH(DATE(PlanYear,1,1)-WEEKDAY(DATE(PlanYear,1,1),3)+3)=1,DATE(PlanYear,1,1)-WEEKDAY(DATE(PlanYear,1,1),3)+3,"") | M5: =IF($K$5="","",IF(IFERROR(INDEX(DayStat,$K$5-DATE(PlanYear,1,1)+1)&"","")<>"",0,SUMIFS(FlSorties,FlDate,$K$5))) | N5: =IF(MONTH(DATE(PlanYear,1,1)-WEEKDAY(DATE(PlanYear,1,1),3)+4)=1,DATE(PlanYear,1,1)-WEEKDAY(DATE(PlanYear,1,1),3)+4,"") | P5: =IF($N$5="","",IF(IFERROR(INDEX(DayStat,$N$5-DATE(PlanYear,1,1)+1)&"","")<>"",0,SUMIFS(FlSorties,FlDate,$N$5))) | Q5: =IF(MONTH(DATE(PlanYear,1,1)-WEEKDAY(DATE(PlanYear,1,1),3)+5)=1,DATE(PlanYear,1,1)-WEEKDAY(DATE(PlanYear,1,1),3)+5,"") | S5: =IF($Q$5="","",IF(IFERROR(INDEX(DayStat,$Q$5-DATE(PlanYear,1,1)+1)&"","")<>"",0,SUMIFS(FlSorties,FlDate,$Q$5))) | T5: =IF(MONTH(DATE(PlanYear,1,1)-WEEKDAY(DATE(PlanYear,1,1),3)+6)=1,DATE(PlanYear,1,1)-WEEKDAY(DATE(PlanYear,1,1),3)+6,"") | V5: =IF($T$5="","",IF(IFERROR(INDEX(DayStat,$T$5-DATE(PlanYear,1,1)+1)&"","")<>"",0,SUMIFS(FlSorties,FlDate,$T$5)))
B6: =IF($B$5="","",IF(IFERROR(INDEX(DayStat,$B$5-DATE(PlanYear,1,1)+1)&"","")<>"",IFERROR(INDEX(DayStat,$B$5-DATE(PlanYear,1,1)+1)&"",""),IF(COUNTIF(GrDate,$B$5)=0,"","GND: "&INDEX(GrAct,MATCH($B$5,GrDate,0))&IF(COUNTIF(GrDate,$B$5)>1," +"&(COUNTIF(GrDate,$B$5)-1)&" more","")))) | E6: =IF($E$5="","",IF(IFERROR(INDEX(DayStat,$E$5-DATE(PlanYear,1,1)+1)&"","")<>"",IFERROR(INDEX(DayStat,$E$5-DATE(PlanYear,1,1)+1)&"",""),IF(COUNTIF(GrDate,$E$5)=0,"","GND: "&INDEX(GrAct,MATCH($E$5,GrDate,0))&IF(COUNTIF(GrDate,$E$5)>1," +"&(COUNTIF(GrDate,$E$5)-1)&" more","")))) | H6: =IF($H$5="","",IF(IFERROR(INDEX(DayStat,$H$5-DATE(PlanYear,1,1)+1)&"","")<>"",IFERROR(INDEX(DayStat,$H$5-DATE(PlanYear,1,1)+1)&"",""),IF(COUNTIF(GrDate,$H$5)=0,"","GND: "&INDEX(GrAct,MATCH($H$5,GrDate,0))&IF(COUNTIF(GrDate,$H$5)>1," +"&(COUNTIF(GrDate,$H$5)-1)&" more","")))) | K6: =IF($K$5="","",IF(IFERROR(INDEX(DayStat,$K$5-DATE(PlanYear,1,1)+1)&"","")<>"",IFERROR(INDEX(DayStat,$K$5-DATE(PlanYear,1,1)+1)&"",""),IF(COUNTIF(GrDate,$K$5)=0,"","GND: "&INDEX(GrAct,MATCH($K$5,GrDate,0))&IF(COUNTIF(GrDate,$K$5)>1," +"&(COUNTIF(GrDate,$K$5)-1)&" more","")))) | N6: =IF($N$5="","",IF(IFERROR(INDEX(DayStat,$N$5-DATE(PlanYear,1,1)+1)&"","")<>"",IFERROR(INDEX(DayStat,$N$5-DATE(PlanYear,1,1)+1)&"",""),IF(COUNTIF(GrDate,$N$5)=0,"","GND: "&INDEX(GrAct,MATCH($N$5,GrDate,0))&IF(COUNTIF(GrDate,$N$5)>1," +"&(COUNTIF(GrDate,$N$5)-1)&" more","")))) | Q6: =IF($Q$5="","",IF(IFERROR(INDEX(DayStat,$Q$5-DATE(PlanYear,1,1)+1)&"","")<>"",IFERROR(INDEX(DayStat,$Q$5-DATE(PlanYear,1,1)+1)&"",""),IF(COUNTIF(GrDate,$Q$5)=0,"","GND: "&INDEX(GrAct,MATCH($Q$5,GrDate,0))&IF(COUNTIF(GrDate,$Q$5)>1," +"&(COUNTIF(GrDate,$Q$5)-1)&" more","")))) | T6: =IF($T$5="","",IF(IFERROR(INDEX(DayStat,$T$5-DATE(PlanYear,1,1)+1)&"","")<>"",IFERROR(INDEX(DayStat,$T$5-DATE(PlanYear,1,1)+1)&"",""),IF(COUNTIF(GrDate,$T$5)=0,"","GND: "&INDEX(GrAct,MATCH($T$5,GrDate,0))&IF(COUNTIF(GrDate,$T$5)>1," +"&(COUNTIF(GrDate,$T$5)-1)&" more",""))))
B7: =IF($B$5="","","AM"&IF(COUNTIFS(FlDate,$B$5,FlShift,"AM",FlCode,"<>")>3,CHAR(10)&"+"&(COUNTIFS(FlDate,$B$5,FlShift,"AM",FlCode,"<>")-3)&" more","")) | C7: =IF($B$5="","",IFERROR(INDEX(FlCode,MATCH($B$5&"|AM|1",FlKey,0)),"")) | D7: =IF($B$5="","",IFERROR(INDEX(FlTime,MATCH($B$5&"|AM|1",FlKey,0))&"","")) | E7: =IF($E$5="","","AM"&IF(COUNTIFS(FlDate,$E$5,FlShift,"AM",FlCode,"<>")>3,CHAR(10)&"+"&(COUNTIFS(FlDate,$E$5,FlShift,"AM",FlCode,"<>")-3)&" more","")) | F7: =IF($E$5="","",IFERROR(INDEX(FlCode,MATCH($E$5&"|AM|1",FlKey,0)),"")) | G7: =IF($E$5="","",IFERROR(INDEX(FlTime,MATCH($E$5&"|AM|1",FlKey,0))&"","")) | H7: =IF($H$5="","","AM"&IF(COUNTIFS(FlDate,$H$5,FlShift,"AM",FlCode,"<>")>3,CHAR(10)&"+"&(COUNTIFS(FlDate,$H$5,FlShift,"AM",FlCode,"<>")-3)&" more","")) | I7: =IF($H$5="","",IFERROR(INDEX(FlCode,MATCH($H$5&"|AM|1",FlKey,0)),"")) | J7: =IF($H$5="","",IFERROR(INDEX(FlTime,MATCH($H$5&"|AM|1",FlKey,0))&"","")) | K7: =IF($K$5="","","AM"&IF(COUNTIFS(FlDate,$K$5,FlShift,"AM",FlCode,"<>")>3,CHAR(10)&"+"&(COUNTIFS(FlDate,$K$5,FlShift,"AM",FlCode,"<>")-3)&" more","")) | L7: =IF($K$5="","",IFERROR(INDEX(FlCode,MATCH($K$5&"|AM|1",FlKey,0)),"")) | M7: =IF($K$5="","",IFERROR(INDEX(FlTime,MATCH($K$5&"|AM|1",FlKey,0))&"","")) | N7: =IF($N$5="","","AM"&IF(COUNTIFS(FlDate,$N$5,FlShift,"AM",FlCode,"<>")>3,CHAR(10)&"+"&(COUNTIFS(FlDate,$N$5,FlShift,"AM",FlCode,"<>")-3)&" more","")) | O7: =IF($N$5="","",IFERROR(INDEX(FlCode,MATCH($N$5&"|AM|1",FlKey,0)),"")) | P7: =IF($N$5="","",IFERROR(INDEX(FlTime,MATCH($N$5&"|AM|1",FlKey,0))&"","")) | Q7: =IF($Q$5="","","AM"&IF(COUNTIFS(FlDate,$Q$5,FlShift,"AM",FlCode,"<>")>3,CHAR(10)&"+"&(COUNTIFS(FlDate,$Q$5,FlShift,"AM",FlCode,"<>")-3)&" more","")) | R7: =IF($Q$5="","",IFERROR(INDEX(FlCode,MATCH($Q$5&"|AM|1",FlKey,0)),"")) | S7: =IF($Q$5="","",IFERROR(INDEX(FlTime,MATCH($Q$5&"|AM|1",FlKey,0))&"","")) | T7: =IF($T$5="","","AM"&IF(COUNTIFS(FlDate,$T$5,FlShift,"AM",FlCode,"<>")>3,CHAR(10)&"+"&(COUNTIFS(FlDate,$T$5,FlShift,"AM",FlCode,"<>")-3)&" more","")) | U7: =IF($T$5="","",IFERROR(INDEX(FlCode,MATCH($T$5&"|AM|1",FlKey,0)),"")) | V7: =IF($T$5="","",IFERROR(INDEX(FlTime,MATCH($T$5&"|AM|1",FlKey,0))&"",""))
C8: =IF($B$5="","",IFERROR(INDEX(FlCode,MATCH($B$5&"|AM|2",FlKey,0)),"")) | D8: =IF($B$5="","",IFERROR(INDEX(FlTime,MATCH($B$5&"|AM|2",FlKey,0))&"","")) | F8: =IF($E$5="","",IFERROR(INDEX(FlCode,MATCH($E$5&"|AM|2",FlKey,0)),"")) | G8: =IF($E$5="","",IFERROR(INDEX(FlTime,MATCH($E$5&"|AM|2",FlKey,0))&"","")) | I8: =IF($H$5="","",IFERROR(INDEX(FlCode,MATCH($H$5&"|AM|2",FlKey,0)),"")) | J8: =IF($H$5="","",IFERROR(INDEX(FlTime,MATCH($H$5&"|AM|2",FlKey,0))&"","")) | L8: =IF($K$5="","",IFERROR(INDEX(FlCode,MATCH($K$5&"|AM|2",FlKey,0)),"")) | M8: =IF($K$5="","",IFERROR(INDEX(FlTime,MATCH($K$5&"|AM|2",FlKey,0))&"","")) | O8: =IF($N$5="","",IFERROR(INDEX(FlCode,MATCH($N$5&"|AM|2",FlKey,0)),"")) | P8: =IF($N$5="","",IFERROR(INDEX(FlTime,MATCH($N$5&"|AM|2",FlKey,0))&"","")) | R8: =IF($Q$5="","",IFERROR(INDEX(FlCode,MATCH($Q$5&"|AM|2",FlKey,0)),"")) | S8: =IF($Q$5="","",IFERROR(INDEX(FlTime,MATCH($Q$5&"|AM|2",FlKey,0))&"","")) | U8: =IF($T$5="","",IFERROR(INDEX(FlCode,MATCH($T$5&"|AM|2",FlKey,0)),"")) | V8: =IF($T$5="","",IFERROR(INDEX(FlTime,MATCH($T$5&"|AM|2",FlKey,0))&"",""))
C9: =IF($B$5="","",IFERROR(INDEX(FlCode,MATCH($B$5&"|AM|3",FlKey,0)),"")) | D9: =IF($B$5="","",IFERROR(INDEX(FlTime,MATCH($B$5&"|AM|3",FlKey,0))&"","")) | F9: =IF($E$5="","",IFERROR(INDEX(FlCode,MATCH($E$5&"|AM|3",FlKey,0)),"")) | G9: =IF($E$5="","",IFERROR(INDEX(FlTime,MATCH($E$5&"|AM|3",FlKey,0))&"","")) | I9: =IF($H$5="","",IFERROR(INDEX(FlCode,MATCH($H$5&"|AM|3",FlKey,0)),"")) | J9: =IF($H$5="","",IFERROR(INDEX(FlTime,MATCH($H$5&"|AM|3",FlKey,0))&"","")) | L9: =IF($K$5="","",IFERROR(INDEX(FlCode,MATCH($K$5&"|AM|3",FlKey,0)),"")) | M9: =IF($K$5="","",IFERROR(INDEX(FlTime,MATCH($K$5&"|AM|3",FlKey,0))&"","")) | O9: =IF($N$5="","",IFERROR(INDEX(FlCode,MATCH($N$5&"|AM|3",FlKey,0)),"")) | P9: =IF($N$5="","",IFERROR(INDEX(FlTime,MATCH($N$5&"|AM|3",FlKey,0))&"","")) | R9: =IF($Q$5="","",IFERROR(INDEX(FlCode,MATCH($Q$5&"|AM|3",FlKey,0)),"")) | S9: =IF($Q$5="","",IFERROR(INDEX(FlTime,MATCH($Q$5&"|AM|3",FlKey,0))&"","")) | U9: =IF($T$5="","",IFERROR(INDEX(FlCode,MATCH($T$5&"|AM|3",FlKey,0)),"")) | V9: =IF($T$5="","",IFERROR(INDEX(FlTime,MATCH($T$5&"|AM|3",FlKey,0))&"",""))
B10: =IF($B$5="","","PM"&IF(COUNTIFS(FlDate,$B$5,FlShift,"PM",FlCode,"<>")>3,CHAR(10)&"+"&(COUNTIFS(FlDate,$B$5,FlShift,"PM",FlCode,"<>")-3)&" more","")) | C10: =IF($B$5="","",IFERROR(INDEX(FlCode,MATCH($B$5&"|PM|1",FlKey,0)),"")) | D10: =IF($B$5="","",IFERROR(INDEX(FlTime,MATCH($B$5&"|PM|1",FlKey,0))&"","")) | E10: =IF($E$5="","","PM"&IF(COUNTIFS(FlDate,$E$5,FlShift,"PM",FlCode,"<>")>3,CHAR(10)&"+"&(COUNTIFS(FlDate,$E$5,FlShift,"PM",FlCode,"<>")-3)&" more","")) | F10: =IF($E$5="","",IFERROR(INDEX(FlCode,MATCH($E$5&"|PM|1",FlKey,0)),"")) | G10: =IF($E$5="","",IFERROR(INDEX(FlTime,MATCH($E$5&"|PM|1",FlKey,0))&"","")) | H10: =IF($H$5="","","PM"&IF(COUNTIFS(FlDate,$H$5,FlShift,"PM",FlCode,"<>")>3,CHAR(10)&"+"&(COUNTIFS(FlDate,$H$5,FlShift,"PM",FlCode,"<>")-3)&" more","")) | I10: =IF($H$5="","",IFERROR(INDEX(FlCode,MATCH($H$5&"|PM|1",FlKey,0)),"")) | J10: =IF($H$5="","",IFERROR(INDEX(FlTime,MATCH($H$5&"|PM|1",FlKey,0))&"","")) | K10: =IF($K$5="","","PM"&IF(COUNTIFS(FlDate,$K$5,FlShift,"PM",FlCode,"<>")>3,CHAR(10)&"+"&(COUNTIFS(FlDate,$K$5,FlShift,"PM",FlCode,"<>")-3)&" more","")) | L10: =IF($K$5="","",IFERROR(INDEX(FlCode,MATCH($K$5&"|PM|1",FlKey,0)),"")) | M10: =IF($K$5="","",IFERROR(INDEX(FlTime,MATCH($K$5&"|PM|1",FlKey,0))&"","")) | N10: =IF($N$5="","","PM"&IF(COUNTIFS(FlDate,$N$5,FlShift,"PM",FlCode,"<>")>3,CHAR(10)&"+"&(COUNTIFS(FlDate,$N$5,FlShift,"PM",FlCode,"<>")-3)&" more","")) | O10: =IF($N$5="","",IFERROR(INDEX(FlCode,MATCH($N$5&"|PM|1",FlKey,0)),"")) | P10: =IF($N$5="","",IFERROR(INDEX(FlTime,MATCH($N$5&"|PM|1",FlKey,0))&"","")) | Q10: =IF($Q$5="","","PM"&IF(COUNTIFS(FlDate,$Q$5,FlShift,"PM",FlCode,"<>")>3,CHAR(10)&"+"&(COUNTIFS(FlDate,$Q$5,FlShift,"PM",FlCode,"<>")-3)&" more","")) | R10: =IF($Q$5="","",IFERROR(INDEX(FlCode,MATCH($Q$5&"|PM|1",FlKey,0)),"")) | S10: =IF($Q$5="","",IFERROR(INDEX(FlTime,MATCH($Q$5&"|PM|1",FlKey,0))&"","")) | T10: =IF($T$5="","","PM"&IF(COUNTIFS(FlDate,$T$5,FlShift,"PM",FlCode,"<>")>3,CHAR(10)&"+"&(COUNTIFS(FlDate,$T$5,FlShift,"PM",FlCode,"<>")-3)&" more","")) | U10: =IF($T$5="","",IFERROR(INDEX(FlCode,MATCH($T$5&"|PM|1",FlKey,0)),"")) | V10: =IF($T$5="","",IFERROR(INDEX(FlTime,MATCH($T$5&"|PM|1",FlKey,0))&"",""))
C11: =IF($B$5="","",IFERROR(INDEX(FlCode,MATCH($B$5&"|PM|2",FlKey,0)),"")) | D11: =IF($B$5="","",IFERROR(INDEX(FlTime,MATCH($B$5&"|PM|2",FlKey,0))&"","")) | F11: =IF($E$5="","",IFERROR(INDEX(FlCode,MATCH($E$5&"|PM|2",FlKey,0)),"")) | G11: =IF($E$5="","",IFERROR(INDEX(FlTime,MATCH($E$5&"|PM|2",FlKey,0))&"","")) | I11: =IF($H$5="","",IFERROR(INDEX(FlCode,MATCH($H$5&"|PM|2",FlKey,0)),"")) | J11: =IF($H$5="","",IFERROR(INDEX(FlTime,MATCH($H$5&"|PM|2",FlKey,0))&"","")) | L11: =IF($K$5="","",IFERROR(INDEX(FlCode,MATCH($K$5&"|PM|2",FlKey,0)),"")) | M11: =IF($K$5="","",IFERROR(INDEX(FlTime,MATCH($K$5&"|PM|2",FlKey,0))&"","")) | O11: =IF($N$5="","",IFERROR(INDEX(FlCode,MATCH($N$5&"|PM|2",FlKey,0)),"")) | P11: =IF($N$5="","",IFERROR(INDEX(FlTime,MATCH($N$5&"|PM|2",FlKey,0))&"","")) | R11: =IF($Q$5="","",IFERROR(INDEX(FlCode,MATCH($Q$5&"|PM|2",FlKey,0)),"")) | S11: =IF($Q$5="","",IFERROR(INDEX(FlTime,MATCH($Q$5&"|PM|2",FlKey,0))&"","")) | U11: =IF($T$5="","",IFERROR(INDEX(FlCode,MATCH($T$5&"|PM|2",FlKey,0)),"")) | V11: =IF($T$5="","",IFERROR(INDEX(FlTime,MATCH($T$5&"|PM|2",FlKey,0))&"",""))
C12: =IF($B$5="","",IFERROR(INDEX(FlCode,MATCH($B$5&"|PM|3",FlKey,0)),"")) | D12: =IF($B$5="","",IFERROR(INDEX(FlTime,MATCH($B$5&"|PM|3",FlKey,0))&"","")) | F12: =IF($E$5="","",IFERROR(INDEX(FlCode,MATCH($E$5&"|PM|3",FlKey,0)),"")) | G12: =IF($E$5="","",IFERROR(INDEX(FlTime,MATCH($E$5&"|PM|3",FlKey,0))&"","")) | I12: =IF($H$5="","",IFERROR(INDEX(FlCode,MATCH($H$5&"|PM|3",FlKey,0)),"")) | J12: =IF($H$5="","",IFERROR(INDEX(FlTime,MATCH($H$5&"|PM|3",FlKey,0))&"","")) | L12: =IF($K$5="","",IFERROR(INDEX(FlCode,MATCH($K$5&"|PM|3",FlKey,0)),"")) | M12: =IF($K$5="","",IFERROR(INDEX(FlTime,MATCH($K$5&"|PM|3",FlKey,0))&"","")) | O12: =IF($N$5="","",IFERROR(INDEX(FlCode,MATCH($N$5&"|PM|3",FlKey,0)),"")) | P12: =IF($N$5="","",IFERROR(INDEX(FlTime,MATCH($N$5&"|PM|3",FlKey,0))&"","")) | R12: =IF($Q$5="","",IFERROR(INDEX(FlCode,MATCH($Q$5&"|PM|3",FlKey,0)),"")) | S12: =IF($Q$5="","",IFERROR(INDEX(FlTime,MATCH($Q$5&"|PM|3",FlKey,0))&"","")) | U12: =IF($T$5="","",IFERROR(INDEX(FlCode,MATCH($T$5&"|PM|3",FlKey,0)),"")) | V12: =IF($T$5="","",IFERROR(INDEX(FlTime,MATCH($T$5&"|PM|3",FlKey,0))&"",""))
B13: =IF($B$5="","","NIGHT"&IF(COUNTIFS(FlDate,$B$5,FlShift,"NIGHT",FlCode,"<>")>3,CHAR(10)&"+"&(COUNTIFS(FlDate,$B$5,FlShift,"NIGHT",FlCode,"<>")-3)&" more","")) | C13: =IF($B$5="","",IFERROR(INDEX(FlCode,MATCH($B$5&"|NIGHT|1",FlKey,0)),"")) | D13: =IF($B$5="","",IFERROR(INDEX(FlTime,MATCH($B$5&"|NIGHT|1",FlKey,0))&"","")) | E13: =IF($E$5="","","NIGHT"&IF(COUNTIFS(FlDate,$E$5,FlShift,"NIGHT",FlCode,"<>")>3,CHAR(10)&"+"&(COUNTIFS(FlDate,$E$5,FlShift,"NIGHT",FlCode,"<>")-3)&" more","")) | F13: =IF($E$5="","",IFERROR(INDEX(FlCode,MATCH($E$5&"|NIGHT|1",FlKey,0)),"")) | G13: =IF($E$5="","",IFERROR(INDEX(FlTime,MATCH($E$5&"|NIGHT|1",FlKey,0))&"","")) | H13: =IF($H$5="","","NIGHT"&IF(COUNTIFS(FlDate,$H$5,FlShift,"NIGHT",FlCode,"<>")>3,CHAR(10)&"+"&(COUNTIFS(FlDate,$H$5,FlShift,"NIGHT",FlCode,"<>")-3)&" more","")) | I13: =IF($H$5="","",IFERROR(INDEX(FlCode,MATCH($H$5&"|NIGHT|1",FlKey,0)),"")) | J13: =IF($H$5="","",IFERROR(INDEX(FlTime,MATCH($H$5&"|NIGHT|1",FlKey,0))&"","")) | K13: =IF($K$5="","","NIGHT"&IF(COUNTIFS(FlDate,$K$5,FlShift,"NIGHT",FlCode,"<>")>3,CHAR(10)&"+"&(COUNTIFS(FlDate,$K$5,FlShift,"NIGHT",FlCode,"<>")-3)&" more","")) | L13: =IF($K$5="","",IFERROR(INDEX(FlCode,MATCH($K$5&"|NIGHT|1",FlKey,0)),"")) | M13: =IF($K$5="","",IFERROR(INDEX(FlTime,MATCH($K$5&"|NIGHT|1",FlKey,0))&"","")) | N13: =IF($N$5="","","NIGHT"&IF(COUNTIFS(FlDate,$N$5,FlShift,"NIGHT",FlCode,"<>")>3,CHAR(10)&"+"&(COUNTIFS(FlDate,$N$5,FlShift,"NIGHT",FlCode,"<>")-3)&" more","")) | O13: =IF($N$5="","",IFERROR(INDEX(FlCode,MATCH($N$5&"|NIGHT|1",FlKey,0)),"")) | P13: =IF($N$5="","",IFERROR(INDEX(FlTime,MATCH($N$5&"|NIGHT|1",FlKey,0))&"","")) | Q13: =IF($Q$5="","","NIGHT"&IF(COUNTIFS(FlDate,$Q$5,FlShift,"NIGHT",FlCode,"<>")>3,CHAR(10)&"+"&(COUNTIFS(FlDate,$Q$5,FlShift,"NIGHT",FlCode,"<>")-3)&" more","")) | R13: =IF($Q$5="","",IFERROR(INDEX(FlCode,MATCH($Q$5&"|NIGHT|1",FlKey,0)),"")) | S13: =IF($Q$5="","",IFERROR(INDEX(FlTime,MATCH($Q$5&"|NIGHT|1",FlKey,0))&"","")) | T13: =IF($T$5="","","NIGHT"&IF(COUNTIFS(FlDate,$T$5,FlShift,"NIGHT",FlCode,"<>")>3,CHAR(10)&"+"&(COUNTIFS(FlDate,$T$5,FlShift,"NIGHT",FlCode,"<>")-3)&" more","")) | U13: =IF($T$5="","",IFERROR(INDEX(FlCode,MATCH($T$5&"|NIGHT|1",FlKey,0)),"")) | V13: =IF($T$5="","",IFERROR(INDEX(FlTime,MATCH($T$5&"|NIGHT|1",FlKey,0))&"",""))
C14: =IF($B$5="","",IFERROR(INDEX(FlCode,MATCH($B$5&"|NIGHT|2",FlKey,0)),"")) | D14: =IF($B$5="","",IFERROR(INDEX(FlTime,MATCH($B$5&"|NIGHT|2",FlKey,0))&"","")) | F14: =IF($E$5="","",IFERROR(INDEX(FlCode,MATCH($E$5&"|NIGHT|2",FlKey,0)),"")) | G14: =IF($E$5="","",IFERROR(INDEX(FlTime,MATCH($E$5&"|NIGHT|2",FlKey,0))&"","")) | I14: =IF($H$5="","",IFERROR(INDEX(FlCode,MATCH($H$5&"|NIGHT|2",FlKey,0)),"")) | J14: =IF($H$5="","",IFERROR(INDEX(FlTime,MATCH($H$5&"|NIGHT|2",FlKey,0))&"","")) | L14: =IF($K$5="","",IFERROR(INDEX(FlCode,MATCH($K$5&"|NIGHT|2",FlKey,0)),"")) | M14: =IF($K$5="","",IFERROR(INDEX(FlTime,MATCH($K$5&"|NIGHT|2",FlKey,0))&"","")) | O14: =IF($N$5="","",IFERROR(INDEX(FlCode,MATCH($N$5&"|NIGHT|2",FlKey,0)),"")) | P14: =IF($N$5="","",IFERROR(INDEX(FlTime,MATCH($N$5&"|NIGHT|2",FlKey,0))&"","")) | R14: =IF($Q$5="","",IFERROR(INDEX(FlCode,MATCH($Q$5&"|NIGHT|2",FlKey,0)),"")) | S14: =IF($Q$5="","",IFERROR(INDEX(FlTime,MATCH($Q$5&"|NIGHT|2",FlKey,0))&"","")) | U14: =IF($T$5="","",IFERROR(INDEX(FlCode,MATCH($T$5&"|NIGHT|2",FlKey,0)),"")) | V14: =IF($T$5="","",IFERROR(INDEX(FlTime,MATCH($T$5&"|NIGHT|2",FlKey,0))&"",""))
C15: =IF($B$5="","",IFERROR(INDEX(FlCode,MATCH($B$5&"|NIGHT|3",FlKey,0)),"")) | D15: =IF($B$5="","",IFERROR(INDEX(FlTime,MATCH($B$5&"|NIGHT|3",FlKey,0))&"","")) | F15: =IF($E$5="","",IFERROR(INDEX(FlCode,MATCH($E$5&"|NIGHT|3",FlKey,0)),"")) | G15: =IF($E$5="","",IFERROR(INDEX(FlTime,MATCH($E$5&"|NIGHT|3",FlKey,0))&"","")) | I15: =IF($H$5="","",IFERROR(INDEX(FlCode,MATCH($H$5&"|NIGHT|3",FlKey,0)),"")) | J15: =IF($H$5="","",IFERROR(INDEX(FlTime,MATCH($H$5&"|NIGHT|3",FlKey,0))&"","")) | L15: =IF($K$5="","",IFERROR(INDEX(FlCode,MATCH($K$5&"|NIGHT|3",FlKey,0)),"")) | M15: =IF($K$5="","",IFERROR(INDEX(FlTime,MATCH($K$5&"|NIGHT|3",FlKey,0))&"","")) | O15: =IF($N$5="","",IFERROR(INDEX(FlCode,MATCH($N$5&"|NIGHT|3",FlKey,0)),"")) | P15: =IF($N$5="","",IFERROR(INDEX(FlTime,MATCH($N$5&"|NIGHT|3",FlKey,0))&"","")) | R15: =IF($Q$5="","",IFERROR(INDEX(FlCode,MATCH($Q$5&"|NIGHT|3",FlKey,0)),"")) | S15: =IF($Q$5="","",IFERROR(INDEX(FlTime,MATCH($Q$5&"|NIGHT|3",FlKey,0))&"","")) | U15: =IF($T$5="","",IFERROR(INDEX(FlCode,MATCH($T$5&"|NIGHT|3",FlKey,0)),"")) | V15: =IF($T$5="","",IFERROR(INDEX(FlTime,MATCH($T$5&"|NIGHT|3",FlKey,0))&"",""))
B16: =IF(MONTH(DATE(PlanYear,1,1)-WEEKDAY(DATE(PlanYear,1,1),3)+7)=1,DATE(PlanYear,1,1)-WEEKDAY(DATE(PlanYear,1,1),3)+7,"") | D16: =IF($B$16="","",IF(IFERROR(INDEX(DayStat,$B$16-DATE(PlanYear,1,1)+1)&"","")<>"",0,SUMIFS(FlSorties,FlDate,$B$16))) | E16: =IF(MONTH(DATE(PlanYear,1,1)-WEEKDAY(DATE(PlanYear,1,1),3)+8)=1,DATE(PlanYear,1,1)-WEEKDAY(DATE(PlanYear,1,1),3)+8,"") | G16: =IF($E$16="","",IF(IFERROR(INDEX(DayStat,$E$16-DATE(PlanYear,1,1)+1)&"","")<>"",0,SUMIFS(FlSorties,FlDate,$E$16))) | H16: =IF(MONTH(DATE(PlanYear,1,1)-WEEKDAY(DATE(PlanYear,1,1),3)+9)=1,DATE(PlanYear,1,1)-WEEKDAY(DATE(PlanYear,1,1),3)+9,"") | J16: =IF($H$16="","",IF(IFERROR(INDEX(DayStat,$H$16-DATE(PlanYear,1,1)+1)&"","")<>"",0,SUMIFS(FlSorties,FlDate,$H$16))) | K16: =IF(MONTH(DATE(PlanYear,1,1)-WEEKDAY(DATE(PlanYear,1,1),3)+10)=1,DATE(PlanYear,1,1)-WEEKDAY(DATE(PlanYear,1,1),3)+10,"") | M16: =IF($K$16="","",IF(IFERROR(INDEX(DayStat,$K$16-DATE(PlanYear,1,1)+1)&"","")<>"",0,SUMIFS(FlSorties,FlDate,$K$16))) | N16: =IF(MONTH(DATE(PlanYear,1,1)-WEEKDAY(DATE(PlanYear,1,1),3)+11)=1,DATE(PlanYear,1,1)-WEEKDAY(DATE(PlanYear,1,1),3)+11,"") | P16: =IF($N$16="","",IF(IFERROR(INDEX(DayStat,$N$16-DATE(PlanYear,1,1)+1)&"","")<>"",0,SUMIFS(FlSorties,FlDate,$N$16))) | Q16: =IF(MONTH(DATE(PlanYear,1,1)-WEEKDAY(DATE(PlanYear,1,1),3)+12)=1,DATE(PlanYear,1,1)-WEEKDAY(DATE(PlanYear,1,1),3)+12,"") | S16: =IF($Q$16="","",IF(IFERROR(INDEX(DayStat,$Q$16-DATE(PlanYear,1,1)+1)&"","")<>"",0,SUMIFS(FlSorties,FlDate,$Q$16))) | T16: =IF(MONTH(DATE(PlanYear,1,1)-WEEKDAY(DATE(PlanYear,1,1),3)+13)=1,DATE(PlanYear,1,1)-WEEKDAY(DATE(PlanYear,1,1),3)+13,"") | V16: =IF($T$16="","",IF(IFERROR(INDEX(DayStat,$T$16-DATE(PlanYear,1,1)+1)&"","")<>"",0,SUMIFS(FlSorties,FlDate,$T$16)))
B17: =IF($B$16="","",IF(IFERROR(INDEX(DayStat,$B$16-DATE(PlanYear,1,1)+1)&"","")<>"",IFERROR(INDEX(DayStat,$B$16-DATE(PlanYear,1,1)+1)&"",""),IF(COUNTIF(GrDate,$B$16)=0,"","GND: "&INDEX(GrAct,MATCH($B$16,GrDate,0))&IF(COUNTIF(GrDate,$B$16)>1," +"&(COUNTIF(GrDate,$B$16)-1)&" more","")))) | E17: =IF($E$16="","",IF(IFERROR(INDEX(DayStat,$E$16-DATE(PlanYear,1,1)+1)&"","")<>"",IFERROR(INDEX(DayStat,$E$16-DATE(PlanYear,1,1)+1)&"",""),IF(COUNTIF(GrDate,$E$16)=0,"","GND: "&INDEX(GrAct,MATCH($E$16,GrDate,0))&IF(COUNTIF(GrDate,$E$16)>1," +"&(COUNTIF(GrDate,$E$16)-1)&" more","")))) | H17: =IF($H$16="","",IF(IFERROR(INDEX(DayStat,$H$16-DATE(PlanYear,1,1)+1)&"","")<>"",IFERROR(INDEX(DayStat,$H$16-DATE(PlanYear,1,1)+1)&"",""),IF(COUNTIF(GrDate,$H$16)=0,"","GND: "&INDEX(GrAct,MATCH($H$16,GrDate,0))&IF(COUNTIF(GrDate,$H$16)>1," +"&(COUNTIF(GrDate,$H$16)-1)&" more","")))) | K17: =IF($K$16="","",IF(IFERROR(INDEX(DayStat,$K$16-DATE(PlanYear,1,1)+1)&"","")<>"",IFERROR(INDEX(DayStat,$K$16-DATE(PlanYear,1,1)+1)&"",""),IF(COUNTIF(GrDate,$K$16)=0,"","GND: "&INDEX(GrAct,MATCH($K$16,GrDate,0))&IF(COUNTIF(GrDate,$K$16)>1," +"&(COUNTIF(GrDate,$K$16)-1)&" more","")))) | N17: =IF($N$16="","",IF(IFERROR(INDEX(DayStat,$N$16-DATE(PlanYear,1,1)+1)&"","")<>"",IFERROR(INDEX(DayStat,$N$16-DATE(PlanYear,1,1)+1)&"",""),IF(COUNTIF(GrDate,$N$16)=0,"","GND: "&INDEX(GrAct,MATCH($N$16,GrDate,0))&IF(COUNTIF(GrDate,$N$16)>1," +"&(COUNTIF(GrDate,$N$16)-1)&" more","")))) | Q17: =IF($Q$16="","",IF(IFERROR(INDEX(DayStat,$Q$16-DATE(PlanYear,1,1)+1)&"","")<>"",IFERROR(INDEX(DayStat,$Q$16-DATE(PlanYear,1,1)+1)&"",""),IF(COUNTIF(GrDate,$Q$16)=0,"","GND: "&INDEX(GrAct,MATCH($Q$16,GrDate,0))&IF(COUNTIF(GrDate,$Q$16)>1," +"&(COUNTIF(GrDate,$Q$16)-1)&" more","")))) | T17: =IF($T$16="","",IF(IFERROR(INDEX(DayStat,$T$16-DATE(PlanYear,1,1)+1)&"","")<>"",IFERROR(INDEX(DayStat,$T$16-DATE(PlanYear,1,1)+1)&"",""),IF(COUNTIF(GrDate,$T$16)=0,"","GND: "&INDEX(GrAct,MATCH($T$16,GrDate,0))&IF(COUNTIF(GrDate,$T$16)>1," +"&(COUNTIF(GrDate,$T$16)-1)&" more",""))))
B18: =IF($B$16="","","AM"&IF(COUNTIFS(FlDate,$B$16,FlShift,"AM",FlCode,"<>")>3,CHAR(10)&"+"&(COUNTIFS(FlDate,$B$16,FlShift,"AM",FlCode,"<>")-3)&" more","")) | C18: =IF($B$16="","",IFERROR(INDEX(FlCode,MATCH($B$16&"|AM|1",FlKey,0)),"")) | D18: =IF($B$16="","",IFERROR(INDEX(FlTime,MATCH($B$16&"|AM|1",FlKey,0))&"","")) | E18: =IF($E$16="","","AM"&IF(COUNTIFS(FlDate,$E$16,FlShift,"AM",FlCode,"<>")>3,CHAR(10)&"+"&(COUNTIFS(FlDate,$E$16,FlShift,"AM",FlCode,"<>")-3)&" more","")) | F18: =IF($E$16="","",IFERROR(INDEX(FlCode,MATCH($E$16&"|AM|1",FlKey,0)),"")) | G18: =IF($E$16="","",IFERROR(INDEX(FlTime,MATCH($E$16&"|AM|1",FlKey,0))&"","")) | H18: =IF($H$16="","","AM"&IF(COUNTIFS(FlDate,$H$16,FlShift,"AM",FlCode,"<>")>3,CHAR(10)&"+"&(COUNTIFS(FlDate,$H$16,FlShift,"AM",FlCode,"<>")-3)&" more","")) | I18: =IF($H$16="","",IFERROR(INDEX(FlCode,MATCH($H$16&"|AM|1",FlKey,0)),"")) | J18: =IF($H$16="","",IFERROR(INDEX(FlTime,MATCH($H$16&"|AM|1",FlKey,0))&"","")) | K18: =IF($K$16="","","AM"&IF(COUNTIFS(FlDate,$K$16,FlShift,"AM",FlCode,"<>")>3,CHAR(10)&"+"&(COUNTIFS(FlDate,$K$16,FlShift,"AM",FlCode,"<>")-3)&" more","")) | L18: =IF($K$16="","",IFERROR(INDEX(FlCode,MATCH($K$16&"|AM|1",FlKey,0)),"")) | M18: =IF($K$16="","",IFERROR(INDEX(FlTime,MATCH($K$16&"|AM|1",FlKey,0))&"","")) | N18: =IF($N$16="","","AM"&IF(COUNTIFS(FlDate,$N$16,FlShift,"AM",FlCode,"<>")>3,CHAR(10)&"+"&(COUNTIFS(FlDate,$N$16,FlShift,"AM",FlCode,"<>")-3)&" more","")) | O18: =IF($N$16="","",IFERROR(INDEX(FlCode,MATCH($N$16&"|AM|1",FlKey,0)),"")) | P18: =IF($N$16="","",IFERROR(INDEX(FlTime,MATCH($N$16&"|AM|1",FlKey,0))&"","")) | Q18: =IF($Q$16="","","AM"&IF(COUNTIFS(FlDate,$Q$16,FlShift,"AM",FlCode,"<>")>3,CHAR(10)&"+"&(COUNTIFS(FlDate,$Q$16,FlShift,"AM",FlCode,"<>")-3)&" more","")) | R18: =IF($Q$16="","",IFERROR(INDEX(FlCode,MATCH($Q$16&"|AM|1",FlKey,0)),"")) | S18: =IF($Q$16="","",IFERROR(INDEX(FlTime,MATCH($Q$16&"|AM|1",FlKey,0))&"","")) | T18: =IF($T$16="","","AM"&IF(COUNTIFS(FlDate,$T$16,FlShift,"AM",FlCode,"<>")>3,CHAR(10)&"+"&(COUNTIFS(FlDate,$T$16,FlShift,"AM",FlCode,"<>")-3)&" more","")) | U18: =IF($T$16="","",IFERROR(INDEX(FlCode,MATCH($T$16&"|AM|1",FlKey,0)),"")) | V18: =IF($T$16="","",IFERROR(INDEX(FlTime,MATCH($T$16&"|AM|1",FlKey,0))&"",""))
C19: =IF($B$16="","",IFERROR(INDEX(FlCode,MATCH($B$16&"|AM|2",FlKey,0)),"")) | D19: =IF($B$16="","",IFERROR(INDEX(FlTime,MATCH($B$16&"|AM|2",FlKey,0))&"","")) | F19: =IF($E$16="","",IFERROR(INDEX(FlCode,MATCH($E$16&"|AM|2",FlKey,0)),"")) | G19: =IF($E$16="","",IFERROR(INDEX(FlTime,MATCH($E$16&"|AM|2",FlKey,0))&"","")) | I19: =IF($H$16="","",IFERROR(INDEX(FlCode,MATCH($H$16&"|AM|2",FlKey,0)),"")) | J19: =IF($H$16="","",IFERROR(INDEX(FlTime,MATCH($H$16&"|AM|2",FlKey,0))&"","")) | L19: =IF($K$16="","",IFERROR(INDEX(FlCode,MATCH($K$16&"|AM|2",FlKey,0)),"")) | M19: =IF($K$16="","",IFERROR(INDEX(FlTime,MATCH($K$16&"|AM|2",FlKey,0))&"","")) | O19: =IF($N$16="","",IFERROR(INDEX(FlCode,MATCH($N$16&"|AM|2",FlKey,0)),"")) | P19: =IF($N$16="","",IFERROR(INDEX(FlTime,MATCH($N$16&"|AM|2",FlKey,0))&"","")) | R19: =IF($Q$16="","",IFERROR(INDEX(FlCode,MATCH($Q$16&"|AM|2",FlKey,0)),"")) | S19: =IF($Q$16="","",IFERROR(INDEX(FlTime,MATCH($Q$16&"|AM|2",FlKey,0))&"","")) | U19: =IF($T$16="","",IFERROR(INDEX(FlCode,MATCH($T$16&"|AM|2",FlKey,0)),"")) | V19: =IF($T$16="","",IFERROR(INDEX(FlTime,MATCH($T$16&"|AM|2",FlKey,0))&"",""))
C20: =IF($B$16="","",IFERROR(INDEX(FlCode,MATCH($B$16&"|AM|3",FlKey,0)),"")) | D20: =IF($B$16="","",IFERROR(INDEX(FlTime,MATCH($B$16&"|AM|3",FlKey,0))&"","")) | F20: =IF($E$16="","",IFERROR(INDEX(FlCode,MATCH($E$16&"|AM|3",FlKey,0)),"")) | G20: =IF($E$16="","",IFERROR(INDEX(FlTime,MATCH($E$16&"|AM|3",FlKey,0))&"","")) | I20: =IF($H$16="","",IFERROR(INDEX(FlCode,MATCH($H$16&"|AM|3",FlKey,0)),"")) | J20: =IF($H$16="","",IFERROR(INDEX(FlTime,MATCH($H$16&"|AM|3",FlKey,0))&"","")) | L20: =IF($K$16="","",IFERROR(INDEX(FlCode,MATCH($K$16&"|AM|3",FlKey,0)),"")) | M20: =IF($K$16="","",IFERROR(INDEX(FlTime,MATCH($K$16&"|AM|3",FlKey,0))&"","")) | O20: =IF($N$16="","",IFERROR(INDEX(FlCode,MATCH($N$16&"|AM|3",FlKey,0)),"")) | P20: =IF($N$16="","",IFERROR(INDEX(FlTime,MATCH($N$16&"|AM|3",FlKey,0))&"","")) | R20: =IF($Q$16="","",IFERROR(INDEX(FlCode,MATCH($Q$16&"|AM|3",FlKey,0)),"")) | S20: =IF($Q$16="","",IFERROR(INDEX(FlTime,MATCH($Q$16&"|AM|3",FlKey,0))&"","")) | U20: =IF($T$16="","",IFERROR(INDEX(FlCode,MATCH($T$16&"|AM|3",FlKey,0)),"")) | V20: =IF($T$16="","",IFERROR(INDEX(FlTime,MATCH($T$16&"|AM|3",FlKey,0))&"",""))
